Workbook

Sheet DropdownLIST
A1: HEADS
A2: MCGS | B2: IMO Manager
A3: BPB | B3: Operations & Maintenance SectionHead
A4: LFCP | B4: Engineering Section Head
A5: VEP | B5: Finance Section Head
A6: VMM | B6: Senior Accounting Processor A
A7: MME | B7: Administrative Section Head
A10: SECTION | G10: ENG'G | H10: OMS | I10: ADMIN | J10: FINANCE | K10: BAC | L10: CATNES | M10: IMO
A11: ENG'G | G11: BILLING | H11: CERTIFICATIONS | I11: APPLICANTS | J11: CERTIFICATIONS | K11: CERTIFICATIONS | L11: BILLING | M11: CERTIFICATIONS
A12: OMS | G12: CERTIFICATIONS | H12: COMMUNICATION LETTER | I12: AUTHORITY TO RENDER OVERTIME SERVICES | J12: CHEQUES/JEV | K12: COMMUNICATION LETTER | L12: CERTIFICATIONS | M12: COMMUNICATION LETTER
A13: ADMIN | G13: COMMUNICATION LETTER | H13: GATE PASS, RIS, TRIP TICKET, TRANSPO REQ | I13: CERTIFICATIONS | J13: COMMUNICATION LETTER | K13: LOCATOR SLIP | L13: COMMUNICATION LETTER | M13: LOCATOR SLIP
A14: FINANCE | G14: CONTRACT TIME ADJUSTMENT | H14: INSPECTION REPORT | I14: COMMUNICATION LETTER | J14: LOCATOR SLIP | K14: MINUTES | L14: CONTRACT TIME ADJUSTMENT | M14: MINUTES
A15: BAC | G15: FIVC/FINAL INSPECTION REPORT | H15: LOCATOR SLIP | I15: LOCATOR SLIP | J15: MINUTES | K15: RESOLUTION | L15: FIVC/FINAL INSPECTION REPORT | M15: RESOLUTION
A16: CATNES | G16: FSDE | H16: MINUTES | I16: MINUTES | J16: PAYROLL | K16: TRANSMITTAL | L16: FSDE | M16: TRANSMITTAL
A17: IMO | G17: INSPECTION REPORT | H17: PROJECT PROPOSAL | I17: PAYROLL | J17: RESOLUTION | K17: TRAVEL ORDER/ITINERARY | L17: INSPECTION REPORT | M17: TRAVEL ORDER/ITINERARY
G18: LOCATOR SLIP | H18: RESOLUTION | I18: PURCHASE ORDER | J18: TRANSMITTAL | K18: POST QUALIFICATION EVALUATION | L18: LOCATOR SLIP
G19: MINUTES | H19: TRANSMITTAL | I19: RESOLUTION | J19: TRAVEL ORDER/ITINERARY | K19: VERIFICATION OF PERFORMANCE/TRACK RECORD | L19: MINUTES
G20: PLANS | H20: TRAVEL ORDER/ITINERARY | I20: TRANSMITTAL | L20: PLANS
G21: PROGRAM OF WORKS | I21: TRAVEL ORDER/ITINERARY | L21: PROGRAM OF WORKS
G22: RESOLUTION | I22: OTHER ADMIN CONCERNS | L22: RESOLUTION
G23: TRANSMITTAL | L23: TRANSMITTAL
G24: TRAVEL ORDER/ITINERARY | L24: TRAVEL ORDER/ITINERARY
G25: VARIATION ORDERS | L25: VARIATION ORDERS

Sheet 0102
A1: INCOMING DOCUMENTS TO THE OFFICE OF THE IMO MANAGER
A2: 45659
A3: =TEXT(A2,"DDDD") -> Thursday
A4: NOTE: | B4: IMO on leave, OIC: BPB until 11:30AM, OIC after 11:30 : LFCP
A5: NO. | C5: DOCUMENT | E5: SECTION | F5: TO | G5: REMARKS
A6: =A2 -> 45659 | B6: 1 | C6: ITINERARY: OMS-TO001 | E6: OMS | F6: BPB | G6: FOR SIGNATURE
A7: =A6 -> 45659 | B7: =B6+1 -> 2 | C7: 8th Supplemental (APP FY 2024) | E7: BAC | F7: MCGS | G7: FOR SIGNATURE
A8: =A7 -> 45659 | B8: =B7+1 -> 3 | C8: Personnel Locator Slip: 01/02/2025, NB Nash, Official, 10:00AM | E8: ENG'G | F8: BPB | G8: FOR SIGNATURE
A9: =A8 -> 45659 | B9: =B8+1 -> 4 | C9: TRAVEL ORDER: ENG-TO002 | E9: ENG'G | F9: LFCP | G9: FOR SIGNATURE
A10: =A9 -> 45659 | B10: =B9+1 -> 5 | C10: ITINERARY: OMS-TO002 | E10: OMS | F10: LFCP | G10: FOR SIGNATURE
A11: =A10 -> 45659 | B11: =B10+1 -> 6 | C11: FIVC & FINAL INSPECTION REPORT: (FOR SIGNATURE) Tagoytoy CIS (ALCARP-REPCIS-015-24INF) | E11: ENG'G | F11: MCGS | G11: FOR SIGNATURE
A12: =A11 -> 45659 | B12: =B11+1 -> 7 | C12: FINAL INSPECTION REPORT: (with Punchlist) ALIBUAG CIS (CAT-REPCIS-003-24INF) | E12: CATNES | F12: MME | G12: (Original Copy) Forwarded to Admin to be sent to Cat'nes
A13: =A12 -> 45659 | B13: =B12+1 -> 8 | C13: Currents Volume 57, No. 2 2023 (21 pcs) Gearing Up to Build Better More Irrigation Infrastructures | E13: IMO | F13: MCGS
A14: =A13 -> 45659 | B14: =B13+1 -> 9 | C14: Approved Feasibility Study Report: AROYAO PIP, CAGDARAO SIP, MACULIW CIP | E14: ENG'G | F14: LFCP | G14: Forwarded to Eng'g
A15: =A14 -> 45659 | B15: =B14+1 -> 10 | C15: Comments on the Submitted FSDE for the Modernization of Cabilogan-San Juan RIS | E15: ENG'G | F15: LFCP | G15: Forwarded to Eng'g
A16: =A15 -> 45659 | B16: =B15+1 -> 11 | C16: Transmittal to Region: SUBMISSION OF AUDIT COMPLIANCE PROGRESS REPORT (ACPR) RE: OPERATIONS PERFORMANCE AUDIT | E16: ENG'G | F16: LFCP | G16: FOR SIGNATURE
A17: =A16 -> 45659 | B17: =B16+1 -> 12 | C17: TRAVEL ORDER: OMS-TO006 | E17: OMS | F17: LFCP | G17: FOR SIGNATURE
A18: ***NOTHING FOLLOWS***
A20: Received, Recorded & Forwarded: | D20: Tracked Disseminated & Filed:
D22: (not yet recalled) | F22: (not yet recalled)
A23: COLEEN M. RASTRULLO | D23: ELLA N. RINGAD | F23: JESSICA V. PEÑAFLOR
A24: Engineering Assistant A | D24: Clerk Processor A | F24: Information Officer C

Sheet 0103
A1: INCOMING DOCUMENTS TO THE OFFICE OF THE IMO MANAGER
A2: 45660
A3: =TEXT(A2,"DDDD") -> Friday
A4: NOTE:
A5: NO. | C5: DOCUMENT | E5: SECTION | F5: TO | G5: REMARKS
A6: =A2 -> 45660 | B6: 1 | C6: Travel Order: ENG-TO003 | E6: ENG'G | F6: MCGS | G6: For Signature
A7: =A6 -> 45660 | B7: =B6+1 -> 2 | C7: Travel Order: ENG-TO004 | E7: ENG'G | F7: MCGS | G7: For Signature
A8: =A7 -> 45660 | B8: =B7+1 -> 3 | C8: Transmittal to Region: SIGNED FIVC & FINAL INSPECTION REPORT BY IMO MANAGER FOR TAGOYTOY CIS CONTRACT NO: ALCARP-REPCIS-015-24INF | E8: ENG'G | F8: MCGS | G8: For Signature
A9: =A8 -> 45660 | B9: =B8+1 -> 4 | C9: NOTICE OF MEETING INVITATION Sunwest Inc., 01/09/2025 (Thursday) at NIA ROV | E9: ENG'G | F9: MCGS | G9: For Signature
A10: =A9 -> 45660 | B10: =B9+1 -> 5 | C10: Office Memo: ADM001 s.2025: Various Directives and Reminders | E10: ADMIN | F10: MCGS | G10: For Signature
A11: =A10 -> 45660 | B11: =B10+1 -> 6 | C11: Transmittal to Region: Request for Extension/Creation of job Order Positions for the 1st Semester CY 2025 | E11: ADMIN | F11: MCGS | G11: For Signature
A12: =A11 -> 45660 | B12: =B11+1 -> 7 | C12: To Catanduanes: File Copy of 2nd & Final Billing of Alibuag CIS CAT-REPCIS-002-23 | E12: CATNES | F12: MCGS | G12: For Signature
A13: =A12 -> 45660 | B13: =B12+1 -> 8 | C13: Oas Community College Internship Program of BS inOffice Admin on February 17, 2025 | E13: ADMIN | F13: MCGS
A14: =A13 -> 45660 | B14: =B13+1 -> 9 | C14: APPLICANTS: Guadalupe, Ulyssis (Gate Keeper) Franco Satuid (Dam Operator) | E14: ADMIN | F14: MCGS
A15: =A14 -> 45660 | B15: =B14+1 -> 10 | C15: REQUEST FOR INSPECTION OF COA: Buhi CIS (CAT-REPCIS-001-23) Alibuag CIS (CAT-REPCIS-002-23) Quinartilan CIS (ALCARP-REPCIS-013-24INF) Bagong Abre CIS (AL-REPCIS-004-24INF) Cabilogan San Juan RIS (AL-RESNIS-009-24INF) MNOH Mahaba RIS (TAPSSIA) (AL-REPNIS-011-24INF) | E15: ENG'G | F15: MCGS | G15: For Signature
A16: =A15 -> 45660 | B16: =B15+1 -> 11 | C16: RIS: 001-2025 | E16: OMS | F16: MCGS | G16: For Signature
A17: ***NOTHING FOLLOWS***
A19: Received, Recorded & Forwarded: | D19: Tracked Disseminated & Filed:
D21: (not yet recalled) | F21: (not yet recalled)
A22: COLEEN M. RASTRULLO | D22: ELLA N. RINGAD | F22: JESSICA V. PEÑAFLOR
A23: Engineering Assistant A | D23: Clerk Processor A | F23: Information Officer C

Sheet 0106
A1: INCOMING DOCUMENTS TO THE OFFICE OF THE IMO MANAGER
A2: 45663
A3: =TEXT(A2,"DDDD") -> Monday
A4: NOTE:
A5: NO. | C5: DOCUMENT | D5: SECTION | E5: TO | F5: REMARKS
A6: =A2 -> 45663 | B6: 1 | C6: Personnel Locator Slip 01/06/2025, NBN, 9:00AM, Official | D6: ENG'G | E6: MCGS | F6: For signature
A7: =A6 -> 45663 | B7: =B6+1 -> 2 | C7: Wages (Oct. 1-15, 2024) MP Laynesa | D7: FINANCE | E7: MCGS | F7: For signature
A8: =A7 -> 45663 | B8: =B7+1 -> 3 | C8: Wages(Oct. 16-29, 2024) A. Guarin & 1 | D8: FINANCE | E8: MCGS | F8: For signature
A9: =A8 -> 45663 | B9: =B8+1 -> 4 | C9: Wages(Nov. 1-15, 2024) R.S Nacario | D9: FINANCE | E9: MCGS | F9: For signature
A10: =A9 -> 45663 | B10: =B9+1 -> 5 | C10: Wages(Nov. 16-30, 2024) R.R Warde | D10: FINANCE | E10: MCGS | F10: For signature
A11: =A10 -> 45663 | B11: =B10+1 -> 6 | C11: DRAFT Office Memo: ADM002 : 1st Written Warning ADM003 : Reiteration of the Office Memorandum AD010s.2024 ADM004: Use of Equipment Shed as Hangout Spot, Lounge and/of Kitchen Area | D11: ADMIN | E11: MCGS | F11: For signature
A12: =A11 -> 45663 | B12: =B11+1 -> 7 | C12: Travel Order: ENG-TO005, 006,007,008,009,010 | D12: ENG'G | E12: MCGS | F12: For signature
A13: =A12 -> 45663 | B13: =B12+1 -> 8 | C13: Trvale Order: OMS-TO009 | D13: OMS | E13: MCGS | F13: For signature
A14: =A13 -> 45663 | B14: =B13+1 -> 9 | C14: Personnel Locator Slip 01/06/2025, MAP POLIDARIO, 11:30AM, Official | D14: OMS | E14: MCGS | F14: For signature
A15: =A14 -> 45663 | B15: =B14+1 -> 10 | C15: ITINERARY: OMS-TO007 | D15: OMS | E15: MCGS | F15: For signature
A16: =A15 -> 45663 | B16: =B15+1 -> 11 | C16: ITINERARY: OMS-TO10 | D16: OMS | E16: MCGS | F16: For signature
A17: =A16 -> 45663 | B17: =B16+1 -> 12 | C17: INSPECTION REPORT: Inspection Report (Fallen Tree along MC of Cabilogan-San Juan RIS) (01/06/2025) | D17: OMS | E17: MCGS | F17: For signature
A18: =A17 -> 45663 | B18: =B17+1 -> 13 | C18: Competency Assessment Form of LFCP | D18: ENG'G | E18: MCGS | F18: For signature
... A24: =A23 -> 45663 | B24: =B23+1 -> 19 | C24: To Region: CY 2023 Project Cost Variances of Catanduanes 1. Libjo CIS (2.5M) 2. Dororian CIS (1.5M) 3. Cabuyoan CIS (2M) | D24: ENG'G | E24: MCGS | F24: For signature
A25: =A24 -> 45663 | B25: =B24+1 -> 20 | C25: GSIS: Delayed Remittances Payment for the month of November 2024 | D25: FINANCE | E25: MCGS
A26: =A25 -> 45663 | B26: =B25+1 -> 21 | C26: Notice of Resumption: October 22, 2023 Tilod CIS & Nagbarorong CIS CAT-RREIS-007-23INF | D26: CATNES | E26: MCGS
A27: =A26 -> 45663 | B27: =B26+1 -> 22 | C27: PCR: Repar/Rehab of Marambong CIS RREIS-CT-020-12 | D27: CATNES | E27: MCGS
A28: =A27 -> 45663 | B28: =B27+1 -> 23 | C28: TRAVEL ORDER: ENG-TO012 ITINERARY: ENG-TO013,014,015,016 | D28: ENG'G | E28: MCGS | F28: For signature
A29: =A28 -> 45663 | B29: =B28+1 -> 24 | C29: Office Memo: ADM002 : 1st Written Warning ADM003 : Reiteration of the Office Memorandum AD010s.2024 ADM004: Use of Equipment Shed as Hangout Spot, Lounge and/of Kitchen Area | D29: ADMIN | E29: MCGS | F29: For signature
A30: =A29 -> 45663 | B30: =B29+1 -> 25 | C30: Plantilla of Casual Appointments (JG 8 below) | D30: ADMIN | E30: MCGS | F30: For signature
A31: =A30 -> 45663 | B31: =B30+1 -> 26 | C31: ITINERARY: ENG-TO017,018 OMS-TO011,012,013,014 | D31: ENG'G | E31: MCGS | F31: For signature
A32: =A31 -> 45663 | B32: =B31+1 -> 27 | C32: Personnel Locator Slip 01/06/2025, MAP POLIDARIO, no time, Official | D32: OMS | E32: MCGS | F32: For signature
A33: =A32 -> 45663 | B33: =B32+1 -> 28 | C33: Gate Pass: 005,004,003,009,010,011-2025 RIS: 006,007,005,002,004-2025 Transpo Req: 001,003,004,005,002-2025 Trip Ticket: 001,002,003,004,005,006,007,008-2025 | D33: OMS | E33: MCGS | F33: For signature
A34: =A33 -> 45663 | B34: =B33+1 -> 29 | C34: Turn-Over Documents San Francisco RIS (Repair CIS CY 2022) 20M | D34: ENG'G | E34: MCGS | F34: For signature
A35: =A34 -> 45663 | B35: =B34+1 -> 30 | C35: Application for Leave V. Manlangit, AJ Delgado | D35: FINANCE | E35: MCGS | F35: For signature
A36: =A35 -> 45663 | B36: =B35+1 -> 31 | C36: Transmittal To COA *with attachments: Bank Reconcialiation Statement Fund 501 LFP & CARP-IC for November 2024 | D36: FINANCE | E36: MCGS | F36: For signature
A37: =A36 -> 45663 | B37: =B36+1 -> 32 | C37: Travel Order FIN-TO007 s.2024 | D37: FINANCE | E37: MCGS | F37: For signature
A38: =A37 -> 45663 | B38: =B37+1 -> 33 | C38: Reimbursement of MCG So for May-June 2024 | D38: FINANCE | E38: MCGS | F38: For signature
A39: =A38 -> 45663 | B39: =B38+1 -> 34 | C39: PAG-IBIG Calamity Loan Application Form AB Calpe | D39: ADMIN | E39: MCGS | F39: For signature
... A70: =A69 -> 45663 | B70: =B69+1 -> 65 | C70: RIS: 008-2025 | D70: OMS | E70: MCGS | F70: For signature
A71: ***NOTHING FOLLOWS***
A73: Received, Recorded & Forwarded: | D73: Tracked Disseminated & Filed:
A76: COLEEN M. RASTRULLO | D76: ELLA N. RINGAD | F76: JESSICA V. PEÑAFLOR
A77: Engineering Assistant A | D77: Clerk Processor A | F77: Information Officer C

Sheet 0107
A1: INCOMING DOCUMENTS TO THE OFFICE OF THE IMO MANAGER
A2: 45664
A3: =TEXT(A2,"DDDD") -> Tuesday
A4: NOTE:
A5: NO. | C5: DOCUMENT | F5: TO | G5: REMARKS
C6: SECTION | D6: TYPE
A7: =A2 -> 45664 | B7: 1 | C7: OMS | E7: Gate Pass: 019-2025 RIS: 009,010-2025 Trip Ticket: 010-2025 | F7: MCGS | G7: For Signature
A8: =A7 -> 45664 | B8: =B7+1 -> 2 | C8: OMS | E8: RIS: 011-2025 | F8: MCGS | G8: For Signature
A9: =A8 -> 45664 | B9: =B8+1 -> 3 | C9: OMS | E9: Letters to: Hon. Alfredo Garbin Jr. Hon. Jaime C. Villanueva re: Final Pre-Con on 01/10/2025 at Cagbacong Brgy. Session Hall, 9:30AM | F9: MCGS | G9: For Signature
A10: =A9 -> 45664 | B10: =B9+1 -> 4 | C10: OMS | E10: Itinerary: OMS-TO008 | F10: MCGS | G10: For Signature
A11: =A10 -> 45664 | B11: =B10+1 -> 5 | C11: OMS | E11: To Region: Turn-Over Documents 1. Ogsong RIS (REPNIS 2023) | F11: MCGS | G11: For Signature
A12: =A11 -> 45664 | B12: =B11+1 -> 6 | C12: OMS | E12: TRAVEL ORDER: OMS-TO016, 017,018 | F12: MCGS | G12: For Signature
A13: =A12 -> 45664 | B13: =B12+1 -> 7 | C13: OMS | E13: Personnel Locator Slip: 01/07/2025, 10:00AM, A Lopez, Official | F13: MCGS | G13: For Signature
A14: =A13 -> 45664 | B14: =B13+1 -> 8 | C14: OMS | E14: Travel Order: OMS-TO021 | F14: MCGS | G14: For Signature
A15: =A14 -> 45664 | B15: =B14+1 -> 9 | C15: OMS | E15: Gate Pass: 021-2025 Transpo Req: 011-2025 Travel Order: OMS-TO022 | F15: MCGS | G15: For Signature
A16: =A15 -> 45664 | B16: =B15+1 -> 10 | C16: FINANCE | E16: Cheques & JEV: NIA F-501 LFP - Php 3,587.19 Vilma M. Manlangit - Php 4,582.00 NIA F-501LFP - Php 52,362.02 Senen A. Balondo - Php 2,700.00 Jojo O. Paje - Php 3,150.00 Gratuity Pay: John Kenneth Paje & 2 | F16: MCGS | G16: For Signature
A17: =A16 -> 45664 | B17: =B16+1 -> 11 | E17: TRAVEL ORDER: ENG-TO026 ITINERARY OF TRAVEL: OMS-TO20 & OMS-TO19 | F17: MCGS | G17: For Signature
A18: =A17 -> 45664 | B18: =B17+1 -> 12 | C18: OMS | E18: Gate Pass: January 7, 2025 Karl Daniel Asanza, PE of Sunwest Inc. : 2 sets Mounting Structure & 2 other items thru Howo Boom Truck NFF-8761 | F18: MCGS | G18: For Signature
A19: =A18 -> 45664 | B19: =B18+1 -> 13 | C19: OMS | E19: IDS REGULAR MEETING (JAN. 06, 2024)-4 COPIES | F19: MCGS | G19: For Signature
A20: =A19 -> 45664 | B20: =B19+1 -> 14 | C20: OMS | E20: ITINERARY: OMS-TO024 | F20: MCGS | G20: For Signature
A21: =A20 -> 45664 | B21: =B20+1 -> 15 | C21: IMO | E21: Personnel Locator Slip: 01/07/2025, 1:30PM,EN Ringad, Personal | F21: MCGS | G21: For Signature
A22: =A21 -> 45664 | B22: =B21+1 -> 16 | C22: ENG'G | E22: LGU MALINAO (MAENRO) Letter Request for the Continuation of Irrigation Services Between Bariw and Balading | F22: MCGS
A23: =A22 -> 45664 | B23: =B22+1 -> 17 | C23: BAC | E23: NIA ROV: POST QUALIFICATION EVALUATION CISCO KVF Const & 8 Others | F23: MCGS
A24: =A23 -> 45664 | B24: =B23+1 -> 18 | C24: ADMIN | E24: OM No. 003 s.2025 Readoptation of MC No. 102 s.2024 in all Official Letters and Specific Reports/Forms Regionwide | F24: MCGS
A25: =A24 -> 45664 | B25: =B24+1 -> 19 | C25: BAC | E25: DPWH: VERIFICATION OF PERFORMANCE/TRACK RECORD Dated December 16,17,18,24, 2024 | F25: MCGS
A26: =A25 -> 45664 | B26: =B25+1 -> 20 | C26: BAC | E26: DPWH: VERIFICATION OF PERFORMANCE/TRACK RECORD Dated December 9 & 10, 2024 | F26: MCGS
A27: =A26 -> 45664 | B27: =B26+1 -> 21 | C27: OMS | E27: Gate Pass: 023,022-2025 Travel Order: ADM-TO001 | F27: MCGS | G27: For Signature
A28: =A27 -> 45664 | B28: =B27+1 -> 22 | C28: OMS | E28: Personnel Locator Slip: 01/07/2025, 2:00PM, Official, CL Lontac | F28: MCGS | G28: For Signature
A29: =A28 -> 45664 | B29: =B28+1 -> 23 | C29: OMS | E29: ITINERARY: OMS-TO025 | F29: MCGS | G29: For Signature
A30: =A29 -> 45664 | B30: =B29+1 -> 24 | C30: FINANCE | E30: Cheques w/ Attachments: Albay Electric Cooperative Inc. - Php 803.69 PLDT, Inc - Php 2,061.56 FICELCO - Php 6,394.25 NCIP Region V - Php 20,930.00 | F30: MCGS | G30: For Signature
A31: =A30 -> 45664 | B31: =B30+1 -> 25 | C31: FINANCE | E31: Cheques w/ Attachments: Carlito C. Pongpong - Php 2,000.00 Carlito C. Pongpong - Php 2,000.00 Carlito C. Pongpong - Php 2,000.00 Carlito C. Pongpong - Php 2,000.00 Elizabeth J. Jacob - Php 1,966.00 Jevielyn A. Dolz - Php 3,150.00 Marilou A. Robledo - Php 730.00 Bernardita P. Balingasa - Php 4,4370.00 | F31: MCGS | G31: For Signature
A32: =A31 -> 45664 | B32: =B31+1 -> 26 | C32: ENG'G | E32: 15% Mobilization Santicon SPIP (AL-EGPIPSOL-010-24INF) Grelips Construction and Development | F32: MCGS | G32: For Signature
A33: =A32 -> 45664 | B33: =B32+1 -> 27 | C33: ENG'G | E33: TRAVEL ORDER: ENG-TO027 | F33: MCGS | G33: For Signature
A34: =A33 -> 45664 | B34: =B33+1 -> 28 | C34: OMS | E34: ITINERARY: OMS-TO023, 026 | F34: MCGS | G34: For Signature
A35: =A34 -> 45664 | B35: =B34+1 -> 29 | C35: ENG'G | E35: Request for ICC: 1. Leo P. Carase, Lot No. 310 | F35: MCGS | G35: For Signature
A36: =A35 -> 45664 | B36: =B35+1 -> 30 | C36: ENG'G | E36: Request for ICC: 1. Graciano P. Dafta Sr., Lot No. 1221 2. Graciano P. Dagta Sr., Lot No. 1217 | F36: MCGS | G36: For Signature
A37: =A36 -> 45664 | B37: =B36+1 -> 31 | C37: OMS | E37: Travel Order: OMS-TO027 | F37: MCGS | G37: For Signature
A38: =A37 -> 45664 | B38: =B37+1 -> 32 | C38: ENG'G | E38: Travel Order: ENG-TO028 | F38: MCGS | G38: For Signature
... A45: =A44 -> 45664 | B45: =B44+1 -> 39 | C45: ENG'G | E45: Request for ICC: 1.Glicerio Colle Dolom m/ to Elene R. Dolom | F45: MCGS | G45: For Signature
A46: ***NOTHING FOLLOWS***
...

Sheet 0108
A1: INCOMING DOCUMENTS TO THE OFFICE OF THE IMO MANAGER
A2: 45665
A3: =TEXT(A2,"DDDD") -> Wednesday
A4: NOTE: | B4: Half-day work suspension due to intense rain
A5: NO. | C5: DOCUMENT | F5: TO | G5: REMARKS
C6: DOCUMENT | D6: SECTION | E6: TYPE
A7: =A2 -> 45665 | B7: 1 | C7: To Region: Plantilla of Casual Appointments for the Period of January 1, 2025 to December 31, 2025 Summary and Accomplished Competency Assessment Form CY 2024 | D7: ADMIN | F7: MCGS | G7: For Signature
A8: =A7 -> 45665 | B8: =B7+1 -> 2 | C8: Travel Order: ENG-TO032 | D8: ENG'G | F8: MCGS | G8: For Signature
A9: =A8 -> 45665 | B9: =B8+1 -> 3 | C9: Stronghold Insurance Company Inc. (Closed Envelope) for MCGS | D9: IMO | F9: MCGS
A10: =A9 -> 45665 | B10: =B9+1 -> 4 | C10: JEV & attachments: 1. NIA Region V Naga City COB for Bid Documents Income for 4th Quarter of CY 2024 2. 2nd & Final Billing of Mahaba RIS (MAZOIA) (AL-ISRNIS-007-24INF) | D10: FINANCE | F10: MCGS | G10: For Signature
A11: =A10 -> 45665 | B11: =B10+1 -> 5 | C11: 15% Mobilization LIBJO CIS (AL-EGPIPSOL-012-24INF) Kratos Development Corporation | D11: ENG'G | F11: MCGS | G11: For Signature
A12: =A11 -> 45665 | B12: =B11+1 -> 6 | C12: To COA: Bank Reconciliation Statement of Fund 501LFP & CARP-IC for October 2024 | D12: FINANCE | F12: MCGS | G12: For Signature
A13: =A12 -> 45665 | B13: =B12+1 -> 7 | C13: DTR & Attachments: VE Pitallano (11/1-15, 16-30/2024), (12/1-15/2024) | D13: ADMIN | F13: MCGS | G13: For Signature
A14: =A13 -> 45665 | B14: =B13+1 -> 8 | C14: Travel Order: ENG-TO033, 034 | D14: ENG'G | F14: MCGS | G14: For Signature
A15: =A14 -> 45665 | B15: =B14+1 -> 9 | C15: Gate Pass: 028,029-2025 RIS: 013,014-2025 Transpo Req: 017,018-2025 | D15: OMS | F15: MCGS | G15: For Signature
A16: =A15 -> 45665 | B16: =B15+1 -> 10 | C16: To COA: Summary Report of Actual Maintenance & Other Operating Expenses (MOOE) & Capital Outlay (CO) for Semester ended December 31, 2024 Report of Accountability for Accountable Forms for the month of October 2024 | D16: FINANCE | F16: MCGS | G16: For Signature
A17: =A16 -> 45665 | B17: =B16+1 -> 11 | C17: Check & attachments: Vilma M. Manlangit - Php 133,981.00 | D17: FINANCE | F17: MCGS | G17: For Signature
A18: =A17 -> 45665 | B18: =B17+1 -> 12 | C18: Check & attachments: Vilma M. Manlangit - Php 84,272.54 | D18: FINANCE | F18: MCGS | G18: For Signature
A19: =A18 -> 45665 | B19: =B18+1 -> 13 | C19: Travel Order: OMS-TO029,030 | D19: OMS | F19: MCGS | G19: For Signature
A20: =A19 -> 45665 | B20: =B19+1 -> 14 | C20: Letters to: Hon. Gerry Raphael Z. Jaucian Jr. Hon. Roy Marco re: Pre-Con for Alobo Gapo Inarado CIS EGPIP Fund on 01/10/2025 ,9:00AM at Inarado Brgy Hall, Daraga, albay | D20: OMS | F20: MCGS | G20: For Signature
A21: =A20 -> 45665 | B21: =B20+1 -> 15 | C21: To COA: Quarterly Financial Reports as of December 31, 2024 for Fund 501-LFP (2 separate documents w/ different attachments) | D21: FINANCE | F21: MCGS | G21: For Signature
... A31: =A30 -> 45665 | B31: =B30+1 -> 25 | C31: Gate pass: 032, 033, 031, 030-2025 RIS : 015-2025 Transpo Req. : 020, 026, 021, 022-2025 | D31: OMS | F31: MCGS | G31: For Signature
A32: ***NOTHING FOLLOWS***
A34: Received, Recorded, Tracked, Disseminated & Filed:
A37: COLEEN M. RASTRULLO | D37: ELLA N. RINGAD | G37: JESSICA V. PEÑAFLOR
A38: Engineering Assistant A | D38: Clerk Processor A | G38: Information Officer C

Sheet 0109
A1: INCOMING DOCUMENTS TO THE OFFICE OF THE IMO MANAGER
A2: 45666
A3: =TEXT(A2,"DDDD") -> Thursday
A4: NOTE: | B4: IMO at Regional Office. OIC: BPB
A5: NO. | C5: DOCUMENT | F5: TO | G5: REMARKS
C6: DOCUMENT | D6: SECTION | E6: TYPE
A7: =A2 -> 45666 | B7: 1 | C7: Travel Order: ENG-TO042,043 | D7: ENG'G | F7: BPB | G7: For Signature
A8: =A7 -> 45666 | B8: =B7+1 -> 2 | C8: Travel Order: ENG-TO044 | D8: ENG'G | F8: BPB | G8: For Signature
A9: =A8 -> 45666 | B9: =B8+1 -> 3 | C9: Gate Pass: 034-2025 RIS: 016-2025 Personnel Locator Slip: 01/09/25,8:30, Official, CL Lontac Travel Order: OMS-TO027, ENG-TO045 | D9: OMS | F9: BPB | G9: For Signature
A10: =A9 -> 45666 | B10: =B9+1 -> 4 | C10: Project Completion Report San Francisco RIS CY 2022 | D10: ENG'G | F10: MCGS | G10: For Signature
A11: =A10 -> 45666 | B11: =B10+1 -> 5 | C11: Travel Order: ENG-TO046 Gate Pass: 035-2025 RIS: 017-2025 | F11: BPB | G11: For Signature
A12: =A11 -> 45666 | B12: =B11+1 -> 6 | C12: Post Qualification Evaluation 1. Philworks Const. & Supply & 10 others | D12: BAC | F12: MCGS
A13: =A12 -> 45666 | B13: =B12+1 -> 7 | C13: ACIMO-5-501-2024-465-PS for CNA Php 1,515,000.00 & 3 others | D13: FINANCE | F13: MCGS
A14: =A13 -> 45666 | B14: =B13+1 -> 8 | C14: Travel Order: ENG-TO047, 048 | D14: ENG'G | F14: BPB | G14: For Signature
A15: =A14 -> 45666 | B15: =B14+1 -> 9 | C15: ITINERARY: OMS-TO031 | D15: OMS | F15: BPB | G15: For Signature
A16: =A15 -> 45666 | B16: =B15+1 -> 10 | C16: Project Completion Report Baniaga CIS, Bato, Catanduanes CY 2017 (RREIS-CT-025-17) | D16: ENG'G | F16: MCGS | G16: For Signature
A17: =A16 -> 45666 | B17: =B16+1 -> 11 | C17: Project Completion Report Marambong CIS, Pandan, Catanduanes CY 2012 (RREIS-CT-020-12) | D17: ENG'G | F17: MCGS | G17: For Signature
A18: =A17 -> 45666 | B18: =B17+1 -> 12 | C18: TEVS of: Jevielyn A Dolz - 3,150.00 Marilou A Robledo - 730.00 Cash Advance: Bernardita P. Balingasa - 29,760.00 Excess CA of JBC: NIA F-501LFP- 4,548.00 | D18: FINANCE | F18: MCGS | G18: For Signature
A19: =A18 -> 45666 | B19: =B18+1 -> 13 | C19: Wages (08/01/2024-12/31/2024) JK Paje & 1 AR Madrideo & 2 Wages: (11/16-30/2024) F. Dagumboy | D19: FINANCE | F19: MCGS | G19: For Signature
A20: =A19 -> 45666 | B20: =B19+1 -> 14 | C20: Cheque & Attachments: 2nd & Final Billing BUHI CIS (CAT-REPCIS-001-23) Hi-Tone Construction & Devt Corp. Php 520,040.85 | D20: ENG'G | F20: MCGS | G20: For Signature
A21: =A20 -> 45666 | B21: =B20+1 -> 15 | C21: Personnel Locator Slip: 01/09/2025, 2:00PM, Official, JA Amados | D21: OMS | F21: BPB | G21: For Signature
A22: =A21 -> 45666 | B22: =B21+1 -> 16 | C22: Personnel Locator Slip: 01/09/2025, 1:15PM, Official, A Lopez | D22: OMS | F22: BPB | G22: For Signature
A23: =A22 -> 45666 | B23: =B22+1 -> 17 | C23: Gate Pass: 036,,037,038,039-2025 RIS: 018,019,020-2025 Transpo Req: 024,023,025-2025 | D23: OMS | F23: BPB | G23: For Signature
A24: =A23 -> 45666 | B24: =B23+1 -> 18 | C24: Gate Pass: January 9, 2025 Karl Daniel Asanza, PE of Sunwest Inc. : 50pcs of 5 in Double Flange Steel Pipes & 1 other item thru Howo Boom Truck NFF-8761 | D24: OMS | F24: BPB | G24: For Signature
A25: =A24 -> 45666 | B25: =B24+1 -> 19 | C25: Gate Pass: January 9, 2025 Karl Daniel Asanza, PE of Sunwest Inc. : 30pcs of 5 in Double Flange Steel Pipes & 3 other items thru Howo Boom Truck NFF-8761 | D25: OMS | F25: BPB | G25: For Signature
... A35: =A34 -> 45666 | B35: =B34+1 -> 29 | C35: Travel Order: OMS-TO034,035 | D35: OMS | F35: BPB | G35: For Signature
A36: =A35 -> 45666 | B36: =B35+1 -> 30 | C36: Request to re-schedule conduct of Strategic Planning and Policy Formulation Training/Workshop in Banquerohan CIS from 12/12-13/2024 to 01/21-22/2025 | D36: OMS | F36: MCGS
A37: =A36 -> 45666 | B37: =B36+1 -> 31 | C37: SSS Remittance of K. Almiñana & 1 and A Calpe & 11 for November 2024 | D37: FINANCE | F37: MCGS | G37: For Signature
A38: =A37 -> 45666 | B38: =B37+1 -> 32 | C38: Payment to PLDT Inc for November & December 2024 (Albay) | D38: FINANCE | F38: MCGS | G38: For Signature
A39: =A38 -> 45666 | B39: =B38+1 -> 33 | C39: Fund Transfer Fund 501 CARP to F501-COB for VIG Disallowance for April-November 2024 | D39: FINANCE | F39: MCGS | G39: For Signature
A40: =A39 -> 45666 | B40: =B39+1 -> 34 | C40: Payment to Bureau of Treasury for Remittance of LD for December 2024 | D40: FINANCE | F40: MCGS | G40: For Signature
A41: =A40 -> 45666 | B41: =B40+1 -> 35 | C41: 10% Retention Quinartilan CIS (AL-REPCIS-003-24INF) JCM Construction & Supply Php 233,340.87 | D41: FINANCE | F41: MCGS | G41: For Signature
A42: =A41 -> 45666 | B42: =B41+1 -> 36 | C42: Wages(10/30-31/2024) AMD Balingasa & 2 | D42: FINANCE | F42: MCGS | G42: For Signature
A43: =A42 -> 45666 | B43: =B42+1 -> 37 | C43: To Region: List of Irrigated and Planted (LIPA) Wet Season 2024 CSJ, SQRIS,OSMCIA,MAZOIA,TAPSIA,Bahamas IA,ORISIA,HRISIA | D43: OMS | F43: MCGS | G43: For Signature
A44: =A43 -> 45666 | B44: =B43+1 -> 38 | C44: Hard Copies of NIS & CIS NWRB Statement of Account (SOA)
A45: =A44 -> 45666 | B45: =B44+1 -> 39 | C45: Submission of Status of Funds GAA2024 as of November 2024 LFP, GAA 2023, 2022, 2021 & 2020
A46: =A45 -> 45666 | B46: =B45+1 -> 40 | C46: Water Permit Application for Posting V-ALB-2024-11-008 Philippine Geothermal Production Comp. Inc
A47: =A46 -> 45666 | B47: =B46+1 -> 41 | C47: Re: Follow-up Signed Deeds of Usufruct and Permit-to-Enter for EGPIPSolar Projects
A48: ***NOTHING FOLLOWS***
A50: Received, Recorded, Tracked, Disseminated & Filed:
...

Sheet 0110
A1: INCOMING DOCUMENTS TO THE OFFICE OF THE IMO MANAGER
A2: 45667
A3: =TEXT(A2,"DDDD") -> Friday
A4: NOTE: | B4: MCGS on Official Business 3:30PM, OIC after: BPB
A5: NO. | C5: DOCUMENT | F5: TO | G5: REMARKS
C6: DOCUMENT | D6: SECTION | E6: TYPE
A7: =A2 -> 45667 | B7: 1 | C7: Travel Order: ENG-TO052 | D7: ENG'G | F7: MCGS | G7: For Signature
A8: =A7 -> 45667 | B8: =B7+1 -> 2 | C8: Travel Order: ENG-TO050 | D8: ENG'G | F8: MCGS | G8: For Signature
A9: =A8 -> 45667 | B9: =B8+1 -> 3 | C9: Personnel Locator Slip: 01/10/2025, 9:00AM, Official, A Lopez | D9: OMS | F9: MCGS | G9: For Signature
A10: =A9 -> 45667 | B10: =B9+1 -> 4 | C10: Travel Order: ENG-TO053 | D10: ENG'G | F10: MCGS | G10: For Signature
A11: =A10 -> 45667 | B11: =B10+1 -> 5 | C11: Gate Pass: 041-2025 | D11: OMS | F11: MCGS | G11: For Signature
A12: =A11 -> 45667 | B12: =B11+1 -> 6 | C12: Gate Pass: 042-2025 | D12: OMS | F12: MCGS | G12: For Signature (Void)
A13: =A12 -> 45667 | B13: =B12+1 -> 7 | C13: Travel Order: OMS-TO036 | D13: OMS | F13: MCGS | G13: For Signature
A14: =A13 -> 45667 | B14: =B13+1 -> 8 | C14: Authority to Render Overtime Services: JAR Sarion & 2 (01/08/2025) JAR Sarion (01/07/2025) | D14: ENG'G | F14: MCGS | G14: For Signature
A15: =A14 -> 45667 | B15: =B14+1 -> 9 | C15: Report of ETPs for October 2024 (501-CARP, 501-LFP) Report of ETPs for November 2024 (501-CARP) | D15: FINANCE | F15: MCGS | G15: For Signature
A16: =A15 -> 45667 | B16: =B15+1 -> 10 | C16: Check w/ Attachments: Glory's Diner - 16,167.36 Meal & Snacks for1 day Modernization NIS Coordination Meeting last 09/27/2024 | D16: FINANCE | F16: MCGS | G16: For Signature
A17: =A16 -> 45667 | B17: =B16+1 -> 11 | C17: Request for ICC: 1. Eunice M. Rellores | D17: ENG'G | F17: MCGS | G17: For Signature | J17: •
A18: =A17 -> 45667 | B18: =B17+1 -> 12 | C18: Approved Sand & Gravel Quarry Permit Applications: 1. Santos Padilla 2. Maggie B. Zafe | D18: ENG'G | F18: MCGS | G18: For Signature
A19: =A18 -> 45667 | B19: =B18+1 -> 13 | C19: Gate Pass : 043-2025 RIS : 021-2025 Daily Trip Ticket : 011,012,013,014,015,016,017,018,019, 020-2025 Travel Order : ENG-TO 054 | D19: ENG'G | F19: MCGS | G19: For signature
A20: =A19 -> 45667 | B20: =B19+1 -> 14 | C20: Equipment Program of Works | D20: OMS | F20: MCGS | G20: For signature
A21: =A20 -> 45667 | B21: =B20+1 -> 15 | C21: Authority to Render Overtime Services: NS REODIQUE & 3 (01/11/2025) TRAVEL ORDER: OMS-TO037 | D21: OMS | F21: MCGS | G21: For signature
A22: =A21 -> 45667 | B22: =B21+1 -> 16 | C22: Check w/ Attachments: Vilma M. Manlangit - 4,000.00 CA of Gratuity Pay of MC Alvarez | D22: FINANCE | F22: MCGS | G22: For signature
A23: =A22 -> 45667 | B23: =B22+1 -> 17 | C23: DCTV Payment for 12/30/2024-01/29/2025 of Albay Ligao Water District 11/06/2024-12/03/2024 GSIS Remittance for November 2024 (COB) GSIS Remittance for November 2024 (CARP to COB) TEV of DZ Manlangit 06/12/2024-06/15/2024 Virac Water District 11/29/2024-12/16/2024 Bureau of Treasure for Fidelity Bond of AV Marquez 2023-2024 | D23: FINANCE | F23: MCGS | G23: For signature
A24: =A23 -> 45667 | B24: =B23+1 -> 18 | C24: 10% Retention Pandan Bongalon CIS (AL-REPCIS-001-24INF) JCM Costruction & Supply, Inc. Php 281,493.98 | D24: FINANCE | F24: MCGS | G24: For signature
A25: =A24 -> 45667 | B25: =B24+1 -> 19 | C25: Gate Pass: 044-2025 | D25: OMS | F25: MCGS | G25: For signature
A26: =A25 -> 45667 | B26: =B25+1 -> 20 | C26: Travel Order : ENG-TO 055 Travel Order : FIN-TO 001 | D26: ENG'G | F26: MCGS | G26: For signature
A27: =A26 -> 45667 | B27: =B26+1 -> 21 | C27: 3rd & Final Progress Billing Gogon CIS (AL-REPCIS-002-24INF) 3RB Construction & Supply | D27: ENG'G | F27: MCGS | G27: For signature
A28: =A27 -> 45667 | B28: =B27+1 -> 22 | C28: Authority To Render Overtime Services: EMS Abila & 8 (12/30/2024) | D28: ADMIN | F28: MCGS | G28: For signature
A29: =A28 -> 45667 | B29: =B28+1 -> 23 | C29: INSPECTION REPORT: Response to Corrective Action Request Regarding Canal Construction and Flooding in Barangay Bariw, Malinao, Albay | D29: ENG'G | F29: MCGS | G29: For signature COMPLAINT
... A40: =A39 -> 45667 | B40: =B39+1 -> 34 | C40: ITINERARY: ENG-TO058 | D40: ENG'G | F40: BPB | G40: For signature
A41: ***NOTHING FOLLOWS***
A43: Received, Recorded, Tracked, Disseminated & Filed:
A46: COLEEN M. RASTRULLO | D46: ELLA N. RINGAD | G46: JESSICA V. PEÑAFLOR
A47: Engineering Assistant A | D47: Clerk Processor A | G47: Information Officer C

Sheet 0113
A1: INCOMING DOCUMENTS TO THE OFFICE OF THE IMO MANAGER
A2: 45670
A3: =TEXT(A2,"DDDD") -> Monday
A4: NOTE:
A5: NO. | C5: DOCUMENT | F5: TO | G5: REMARKS
C6: DOCUMENT | D6: SECTION | E6: TYPE
A7: =A2 -> 45670 | B7: 1 | C7: Personnel Locator Slip: 01/13/2024, 8:20, LTO, CL Lontac 01/13/2024, 8:20, LTO, JL Agripa | D7: OMS | F7: MCGS | G7: For Signature
A8: =A7 -> 45670 | B8: =B7+1 -> 2 | C8: Travel Order: OMS-TO040 | D8: OMS | F8: MCGS | G8: For Signature
A9: =A8 -> 45670 | B9: =B8+1 -> 3 | C9: Personnel Locator Slip: 01/13/2024, 8:35 am, LBP, JP Pante, Personal | D9: OMS | F9: MCGS | G9: For Signature
A10: =A9 -> 45670 | B10: =B9+1 -> 4 | C10: Itinerary: OMS-TO 045, 041, 043, 044,042 | D10: OMS | F10: MCGS | G10: For Signature
A11: =A10 -> 45670 | B11: =B10+1 -> 5 | C11: Gate Pass: 046,047,048,049,050,051-2025 RIS: 024,025,026-2025 Transpo Req: 033,034,030,036,037-2025 Trip Ticket: 025,024,023-2025 | D11: OMS | F11: MCGS | G11: For Signature
A12: =A11 -> 45670 | B12: =B11+1 -> 6 | C12: Personnel Locator Slip: 01/13/2024, 9:00, LTO, JA Amados | D12: OMS | F12: MCGS | G12: For Signature
A13: =A12 -> 45670 | B13: =B12+1 -> 7 | C13: Itinerary: ENG-TO059,060,061,062,063,064,065,066,079 | D13: ENG'G | F13: MCGS | G13: For Signature
A14: =A13 -> 45670 | B14: =B13+1 -> 8 | C14: Itinerary: OMS-TO047 | D14: OMS | F14: MCGS | G14: For Signature
A15: =A14 -> 45670 | B15: =B14+1 -> 9 | C15: To Catanduanes: Approved Copy of 2nd & Final Billing Buhi CIS (CAT-REPCIS-001-23) | D15: CATNES | F15: MCGS | G15: For Signature
A16: =A15 -> 45670 | B16: =B15+1 -> 10 | C16: 2nd & Final Billing Cawayan CIS (AL-REPCIS-003-23) Roca Blanca Construction | D16: ENG'G | F16: MCGS | G16: For Signature | I16: •
A17: =A16 -> 45670 | B17: =B16+1 -> 11 | C17: 15% Mobilization South Quinale RIS (AL-EGPIPSOL-014-24INF) Roca Blanca Construction | D17: ENG'G | F17: MCGS | G17: For Signature
A18: =A17 -> 45670 | B18: =B17+1 -> 12 | C18: Cheque & Attachments: Vilma Manlangit - Php 49,090.80 for CA of wages of A.Arao & 9 (11/16-30/2024) | D18: FINANCE | F18: MCGS | G18: For Signature
A19: =A18 -> 45670 | B19: =B18+1 -> 13 | C19: Cheque & Attachments: Vilma Manlangit - Php 49,090.80 for CA of wages of A.Arao & 9 (12/1-15/2024) | D19: FINANCE | F19: MCGS | G19: For Signature
A20: =A19 -> 45670 | B20: =B19+1 -> 14 | C20: Reimbursement of MCGS for Rizal Day Flower Stand last December 30, 2024 | D20: FINANCE | F20: MCGS | G20: For Signature
A21: =A20 -> 45670 | B21: =B20+1 -> 15 | C21: 1. Adjust understated Tax payment for May 2021 2. Adjust Understatement of Check #1014363 3. Record Funding Check for November 2024 4. Record Funding Check for October 2024 5. Socorro's Lakeside Restaurant & Grill due to overpayment for Check #1124038 dated 1/12/24 6. Fund Transfer of CARP settlement of PHIC Remittances for July-August 2024 7. Record Funding Check for October 2024 8. Fund Transfer of CARP & COB settlement of PHIC Remittances for May-June 2024 9. Fund Transfer of CARP & COB settlement of BIR Remittances for May 2024 10. Fund Transfer of CARP & COB settlement of BIR Remittances for June-July 2024 | D21: FINANCE | F21: MCGS | G21: For Signature
A22: =A21 -> 45670 | B22: =B21+1 -> 16 | C22: To Region: Operations and Maintenance Monthly Report of Albay-Catanduanes IMO for December 2024 | D22: OMS | F22: MCGS | G22: For Signature
A23: =A22 -> 45670 | B23: =B22+1 -> 17 | C23: Itinerary: OMS-TO049 | D23: OMS | F23: MCGS | G23: For Signature
A24: =A23 -> 45670 | B24: =B23+1 -> 18 | C24: Itinerary: OMS-TO048,046 | D24: OMS | F24: MCGS | G24: For Signature
A25: =A24 -> 45670 | B25: =B24+1 -> 19 | C25: Gate Pass: 052-2025 Travel Order: OMS-TO050 | D25: OMS | F25: MCGS | G25: For Signature
A26: =A25 -> 45670 | B26: =B25+1 -> 20 | C26: ITINERARY: ENG-TO080,081 | F26: MCGS | G26: For Signature
A27: =A26 -> 45670 | B27: =B26+1 -> 21 | C27: Letters to: 1. Hon. Wilfredo V. Maronilla 2. Linao Brgy. Captain re Final Pre-Con on January 17, 2025, 9:00AM at SQIA Office | F27: MCGS | G27: For Signature
A28: =A27 -> 45670 | B28: =B27+1 -> 22 | C28: PIC Weekly Accomplishment Report & Project Status South Quinale RIS as of 01/10/2025 South Quinale RIS as of 01/10/2025 | F28: MCGS | G28: For Signature
A29: =A28 -> 45670 | B29: =B28+1 -> 23 | C29: ITINERARY: ENG-TO082 | F29: MCGS | G29: For Signature
A30: =A29 -> 45670 | B30: =B29+1 -> 24 | C30: Personnel Locator Slip: 01/13/2025, 1:30PM, Official, J Amados | F30: MCGS | G30: For Signature
A31: =A30 -> 45670 | B31: =B30+1 -> 25 | C31: Letter to DPWH 1st District: Response to Complaint Regarding Flooding Allegedly Caused by our Irrigation Canals | F31: MCGS | G31: For Signature
A32: =A31 -> 45670 | B32: =B31+1 -> 26 | C32: Audit Compliance Progress Report (ACPR) of Operations Audit in NIA Region 5 | D32: ENG'G | F32: MCGS
A33: =A32 -> 45670 | B33: =B32+1 -> 27 | C33: Authority to Render Overtime Services: MD Orogo (01/12/2025) RP Bonapos (01/10/2025) CL Lontac & 3 (01/11/2025) KAL Almiñana & 1 (01/09/2025) DRP Pagal (01/07-08/2025) DMC Mayor & 3 (01/11-12/2025) | D33: ADMIN | F33: MCGS | G33: For Signature
A34: =A33 -> 45670 | B34: =B33+1 -> 28 | C34: Itinerary: OMS-TO051 | D34: OMS | F34: MCGS | G34: For Signature
A35: =A34 -> 45670 | B35: =B34+1 -> 29 | C35: Posting of Invitation to Apply for Vacant Positions: 1. Sr. IDO - Magarao, Camsur 2. Principal Enginer C - ROV Naga City 3. SWRFT - Magarao, Camsur | F35: MCGS
A36: =A35 -> 45670 | B36: =B35+1 -> 30 | C36: MC No. 133 s. 2024 Juman Resource Promotion and Selection Board (HRMPSB) Resolution No. 1-2024 | F36: MCGS
A37: =A36 -> 45670 | B37: =B36+1 -> 31 | C37: MC No. 01 s. 2025 NIA Board of Directors Performance Evaluation Guidelines | F37: MCGS
A38: =A37 -> 45670 | B38: =B37+1 -> 32 | C38: MC No. 02 s. 2025 NIA Ushering 2025 Activity | F38: MCGS
A39: =A38 -> 45670 | B39: =B38+1 -> 33 | C39: MC No. 132 s. 2024 Amendment to NIA MC No. 126 s.2023 "NIA Drug-Free Workplace Program Policy" | F39: MCGS
A40: =A39 -> 45670 | B40: =B39+1 -> 34 | C40: OM No. 007 s. 2025 Submission of Scheduling of Forced Leave (SFL) and Statement of Assets, Liabilities, and Net Worth (SALN) | F40: MCGS
...

Sheet 0114
A1: INCOMING DOCUMENTS TO THE OFFICE OF THE IMO MANAGER
A2: 45671
A3: =TEXT(A2,"DDDD") -> Tuesday
A4: NOTE:
A5: NO. | C5: DOCUMENT | F5: TO | G5: REMARKS
C6: DOCUMENT | D6: SECTION | E6: TYPE
A7: =A2 -> 45671 | B7: 1 | C7: GATE PASS: 058, 059, 060-2025 RIS: 027, 028-2024 | F7: MCGS | G7: For Signature
A8: =A7 -> 45671 | B8: =B7+1 -> 2 | C8: Travel Order: ENG-TO067,068 | F8: MCGS | G8: For Signature
A9: =A8 -> 45671 | B9: =B8+1 -> 3 | C9: ITINERARY OF TRAVEL: OMS-TO056 | F9: MCGS | G9: For Signature
A10: =A9 -> 45671 | B10: =B9+1 -> 4 | C10: ITINERARY OF TRAVEL: ENG-TO069, 070 | F10: MCGS | G10: For Signature
A11: =A10 -> 45671 | B11: =B10+1 -> 5 | C11: Gate Pass: January 11, 2025 Nover Springael, foreman of Sunwest Inc. : solar Module Panels 6 pallets thru Howo Boom Truck NFF-8761 Gate Pass: January 14, 2025 Arnel Bodlong, Foreman of Sunwest Inc. : submersible pump and 1 other thru Toyota Hilux ZNN 460 Nover Springael, foreman of Sunwest Inc. : SOLAR MOUNTING KITS and 2 others thru Howo Boom Truck NFF-8761 | F11: MCGS | G11: For Signature
A12: =A11 -> 45671 | B12: =B11+1 -> 6 | C12: ITINERARY OF TRAVEL: ENG-TO071, 072,073 | F12: MCGS | G12: For Signature
A13: =A12 -> 45671 | B13: =B12+1 -> 7 | C13: To Region: Turnover Documents 1. San Francisco RIS, CY 2022, 20M | F13: MCGS | G13: For Signature
A14: =A13 -> 45671 | B14: =B13+1 -> 8 | C14: To Catanduanes: Project Completion Reports 1. Soboc CIS CY 2018 2. Burgos San Jose CIS CY 2018 3. Alibuag CIS CY 2017 4. Manambrag CIS CY 2019 5. Siay CIP CY 2020 6. Tarba CIS CY 2016 7. Hicming CIP Cy 2020 8. Carangag CIS CY 2015 9. Sta. Isabel CIP CY 2019 10. Tinago CIS CY 2018 11. Sicmil CIS CY 2015 12. Panganiban CIS CY 2015 13. Oco CIS CY 2016 | F14: MCGS | G14: For Signature
A15: =A14 -> 45671 | B15: =B14+1 -> 9 | C15: Itinerary: OMS-TO056 | F15: MCGS | G15: For Signature
A16: =A15 -> 45671 | B16: =B15+1 -> 10 | C16: Follow-up Letter from St. Claire Trading re 10% Retention of Contract No. CO18-AL-002-19: Supply & Delivery of Construction Materials for the Improvement of NIA ACIMO Building | F16: MCGS | I16: •
A17: =A16 -> 45671 | B17: =B16+1 -> 11 | C17: Stronghold Insurance Company Inc. Certification from Insurance Commission for Advance Payment Bond for Libjo CIS (AL-EGPIPSOL-012-24INF) | F17: MCGS
A18: =A17 -> 45671 | B18: =B17+1 -> 12 | C18: Personnel Locator Slip: 01/14/2025, 1:00PM, Official, JA Amados 01/14/2025, 1:00PM, Official, Cl Lontac | F18: MCGS | G18: For Signature
A19: =A18 -> 45671 | B19: =B18+1 -> 13 | C19: To Regional Office: Condonation of Writing Off of Loans of Unpaid ISF Back Account Balance Per RA 10969 SQRIS - Anso Recato & 12 CSJRIS - Armando Llarena & 10 | F19: MCGS | G19: For Signature
A20: =A19 -> 45671 | B20: =B19+1 -> 14 | C20: Stronghold Insurance Company Inc. Statement of Accounts as of January 8, 2025 JCM Const./Hi-Tone Const./ CPR Const./ Kratos Devt./Sisbro Const./ Apex Builders | F20: MCGS
A21: =A20 -> 45671 | B21: =B20+1 -> 15 | C21: Transmittal to COA: JEV for FUND 501-LFP (October 1-15, 2024) JEV for FUND 501-LFP (September 16-30, 2024) | F21: MCGS | G21: For Signature
A22: =A21 -> 45671 | B22: =B21+1 -> 16 | C22: Claire's Resto & Catering Meals/Snacks for NIA Capability Building 10/01/2024 | F22: MCGS | G22: For Signature
A23: =A22 -> 45671 | B23: =B22+1 -> 17 | C23: Personnel Locator Slip: 01/14/2025, 3:15PM, Official, MD Orogo 01/14/2025, 3:15PM, Official, JV Peñaflor 01/14/2025, 3:15PM, Official, EN Ringad | F23: MCGS | G23: For Signature
A24: =A23 -> 45671 | B24: =B23+1 -> 18 | C24: Gate Pass: 061,062,063,064,065,066-2025 Transpo Req: 045,046,047,048,049-2025 | F24: MCGS | G24: For Signature
A25: =A24 -> 45671 | B25: =B24+1 -> 19 | C25: To CamSur IMO: Record of Leaves of Absence (Leave Card) of Albino, Arroyo & Cabiles | F25: MCGS | G25: For Signature
A26: =A25 -> 45671 | B26: =B25+1 -> 20 | C26: To Region: Record of Leaves of Absence (Leave Card) of Chazzie L. Rañola | F26: MCGS | G26: For Signature
A27: =A26 -> 45671 | B27: =B26+1 -> 21 | C27: To Region: Procurement Monitoring Report (PMR) Annexes A & B as of December 31, 2024 | F27: MCGS | G27: For Signature
A28: ***NOTHING FOLLOWS***
A30: Received, Recorded, Tracked, Disseminated & Filed:
A33: COLEEN M. RASTRULLO | D33: ELLA N. RINGAD | G33: JESSICA V. PEÑAFLOR
A34: Engineering Assistant A | D34: Clerk Processor A | G34: Information Officer C

Sheet 0115
A1: INCOMING DOCUMENTS TO THE OFFICE OF THE IMO MANAGER
A2: 45672
A3: =TEXT(A2,"DDDD") -> Wednesday
A4: NOTE:
A5: NO. | C5: DOCUMENTS | F5: TO | G5: REMARKS
C6: DOCUMENT | D6: SECTION | E6: TYPE
A7: =A2 -> 45672 | B7: 1 | C7: TRAVEL ORDER: ADM-TO002 | F7: MCGS | G7: FOR SIGNATURE
A8: =A7 -> 45672 | B8: =B7+1 -> 2 | C8: ITINERARY: ENG-TO078,077,076,075 TRAVEL ORDER: ENG-TO086 | F8: MCGS | G8: FOR SIGNATURE
A9: =A8 -> 45672 | B9: =B8+1 -> 3 | C9: MEMORANDUM OF AGREEMENT NIA & KINA BALANGIBANG CARISAC IA (KBCIA), INC. | F9: MCGS | G9: FOR SIGNATURE
A10: =A9 -> 45672 | B10: =B9+1 -> 4 | C10: ITINERARY: OMS-TO058 | F10: MCGS | G10: FOR SIGNATURE
A11: =A10 -> 45672 | B11: =B10+1 -> 5 | C11: Gate Pass: 067,068-2025 RIS: 029,030,031-2025 | F11: MCGS | G11: FOR SIGNATURE
A12: =A11 -> 45672 | B12: =B11+1 -> 6 | C12: Travel Order: ENG-TO092, OMS-TO059 | F12: MCGS | G12: FOR SIGNATURE
A13: =A12 -> 45672 | B13: =B12+1 -> 7 | C13: Gate Pass Matls: 001-2025 RIS: 032-2025 | F13: MCGS | G13: FOR SIGNATURE
A14: =A13 -> 45672 | B14: =B13+1 -> 8 | C14: Travel Order: OMS-TO060 | F14: MCGS | G14: FOR SIGNATURE
A15: =A14 -> 45672 | B15: =B14+1 -> 9 | C15: To Region: Response to Corrective Action Form No. 202501:001 Complair Re Flooding Allegedly Casued by Our Irrigation Canals in Barangay Bariw, Malinao, Albay | F15: MCGS | G15: FOR SIGNATURE
A16: =A15 -> 45672 | B16: =B15+1 -> 10 | C16: Typo Error on the Date of Letter for Post-Qualification 1. 3RB Const. & 5 others | F16: MCGS | I16: •
A17: =A16 -> 45672 | B17: =B16+1 -> 11 | C17: No verification form attachment in email received Re: Request for Accomplishment of Verification Form 1. 3RB Const & Supply | F17: MCGS
A18: =A17 -> 45672 | B18: =B17+1 -> 12 | C18: Approved Casual Appointment of NIA ACIMO | F18: MCGS
A19: =A18 -> 45672 | B19: =B18+1 -> 13 | C19: Cheque w/ Attachments: Jane Amy Sarion - 3,300.00 TEV November 2024 FICELCO - 6,356.09 Electric Consumption of NIA Cat. 11/23/2024-12/23/2024 | F19: MCGS | G19: FOR SIGNATURE
A20: =A19 -> 45672 | B20: =B19+1 -> 14 | C20: Cheque w/ Attachments: Vilma M. Manlangit - 68,318.03 CA for FAW payrolls of OGSONG & TAPSSIA | F20: MCGS | G20: FOR SIGNATURE
A21: =A20 -> 45672 | B21: =B20+1 -> 15 | C21: Project Completion Report Magsaysay-Begonia CIS (RREIS-CT-021-13) | F21: MCGS
A22: =A21 -> 45672 | B22: =B21+1 -> 16 | C22: Response Report on Follow-Up Rectification Works of Mabato-Siay CIP (CAT-SIP-2021-01-021INF & CAT-SIP-2021-04INF) | F22: MCGS
A23: =A22 -> 45672 | B23: =B22+1 -> 17 | C23: Resubmission of Variation Order of BUGAO & OBO-MOSBOS CIS CAT-RREIS-006-23INF | F23: MCGS
A24: =A23 -> 45672 | B24: =B23+1 -> 18 | C24: Resubmission of Variation Order of AGBAN CIS CAT-RREIS-010-23INF | F24: MCGS
A25: =A24 -> 45672 | B25: =B24+1 -> 19 | C25: Resubmission of Variation Order of PANGANIBAN CIS CAT-REPCIS-008-24INF | F25: MCGS
A26: =A25 -> 45672 | B26: =B25+1 -> 20 | C26: Original Copy of Final Inspection Report of Cabuyoan CIS CAT-RREIS-005-23INF | F26: MCGS
A27: =A26 -> 45672 | B27: =B26+1 -> 21 | C27: Salary Adjustment AV Marquez (10/1-31/2024) Balondo (Apr.- Aug 2024) | F27: MCGS | G27: FOR SIGNATURE
A28: =A27 -> 45672 | B28: =B27+1 -> 22 | C28: Payroll (12/16-31/2024) V. Manlangit | F28: MCGS | G28: FOR SIGNATURE
A29: =A28 -> 45672 | B29: =B28+1 -> 23 | C29: SRI Payroll H. Gorgonia & 48 Reyes & 1 | F29: MCGS | G29: FOR SIGNATURE
A30: =A29 -> 45672 | B30: =B29+1 -> 24 | C30: CAN CY 2024 Gorgonia & 50 | F30: MCGS | G30: FOR SIGNATURE
A31: =A30 -> 45672 | B31: =B30+1 -> 25 | C31: Payroll & attachments Almiñana (10/30-31/2024) Balingasa(10/30-31/2024) Alnas (11/16-30/2024) Llave (11/16-30/2024) Azutea (11/16-30/2024) Almiñana (11/1-15/2024) Warde (11/1-15/2024) | F31: MCGS | G31: FOR SIGNATURE
A32: =A31 -> 45672 | B32: =B31+1 -> 26 | C32: Cheque & attachments: Ligao City Water District - 5,546.88 Water Consumption 12/03/2024-01/06/2025 | F32: MCGS | G32: FOR SIGNATURE
A33: =A32 -> 45672 | B33: =B32+1 -> 27 | C33: Cheque & attachments: Claire's Resto & Catering - 32,300.00 NIA capability Building 10/01/2024 | F33: MCGS | G33: FOR SIGNATURE
A34: =A33 -> 45672 | B34: =B33+1 -> 28 | C34: Cheque & attachments: Kairo's Food & Allied Services Corporation - 46,406.25 1 Day Stakeholders Forum 12/13/2024 | F34: MCGS | G34: FOR SIGNATURE
A35: =A34 -> 45672 | B35: =B34+1 -> 29 | C35: To COA: Copy of emailed scanned copies of PR, NOA, PO and IAR dated January 15, 2025 | F35: MCGS | G35: FOR SIGNATURE
A36: =A35 -> 45672 | B36: =B35+1 -> 30 | C36: Office Memo: ADM006s.2025 : NIA Ushering 2025: Crafting Horizons | F36: MCGS | G36: FOR SIGNATURE
A37: =A36 -> 45672 | B37: =B36+1 -> 31 | C37: Authority to render Overtime Services: RO Clariño & 12 others (01/11-12/2025) DRP Pagal (01/13-14/2025) RP Bonapos & 1 (01/15/2025) | F37: MCGS | G37: FOR SIGNATURE
A38: =A37 -> 45672 | B38: =B37+1 -> 32 | C38: Travel Order: OMS-TO061 ENG-TO087,088 | F38: MCGS | G38: FOR SIGNATURE
... A41: =A40 -> 45672 | B41: =B40+1 -> 35 | C41: Travel Order: ENG-TO 089,090 OMS-TO062 | F41: MCGS | G41: FOR SIGNATURE
A42: =A41 -> 45672 | B42: =B41+1 -> 36 | C42: Submission of CY 2024 Harvest Report and Estimated Cost of Production | F42: MCGS
...

Sheet 0116
A1: INCOMING DOCUMENTS TO THE OFFICE OF THE IMO MANAGER
A2: 45673
A3: =TEXT(A2,"DDDD") -> Thursday
A4: NOTE:
A5: NO. | C5: DOCUMENTS | F5: TO | G5: REMARKS
C6: DOCUMENT | D6: SECTION | E6: TYPE
A7: =A2 -> 45673 | B7: 1 | C7: Travel Order : ENG-TO 094, 095 | F7: MCGS | G7: For signature
A8: =A7 -> 45673 | B8: =B7+1 -> 2 | C8: Gate Pass: January 16, 2025-003 Edcel Arao, 50 bags of cement thru Hino Dump Truck SCN-294 travel order: OMS-TO063 | F8: MCGS | G8: For signature
A9: =A8 -> 45673 | B9: =B8+1 -> 3 | C9: Personnel Locator Slip: JP. Papa, 01/16/25, 9:00 am, OFFICIAL | F9: MCGS | G9: For signature
A10: =A9 -> 45673 | B10: =B9+1 -> 4 | C10: Gate Pass: 075-2025 RIS: 035-2025 TRIP TICKET: 026-2025 | F10: MCGS | G10: For signature
A11: =A10 -> 45673 | B11: =B10+1 -> 5 | C11: Authority to Render Overtime Services: Jan. 11, 2025 RG. Aycardo & 1 Jan. 15, 2025 JA. Siguenza | F11: MCGS | G11: For signature
A12: =A11 -> 45673 | B12: =B11+1 -> 6 | C12: Travel Order: ENG-TO096,097 | F12: MCGS | G12: For signature
A13: =A12 -> 45673 | B13: =B12+1 -> 7 | C13: CORRECTIVE ACTION REQUEST FORM: 202501:003 Zhai Carillo-Pineda Purok 1, Sitio Taguntong, Mahaba Ligao City | F13: MCGS
A14: =A13 -> 45673 | B14: =B13+1 -> 8 | C14: Gate Pass Vcls: 076-2025 RIS: 036-2025 | F14: MCGS | G14: For signature
A15: =A14 -> 45673 | B15: =B14+1 -> 9 | C15: Cheque & Attachments : 15% Mobilization Tagoytoy CIS (AL-EGPIPSOL-009-24INF) Dalebo Construction & Gen. Merchandise (2,128,457.41) | F15: MCGS | G15: For signature
A16: =A15 -> 45673 | B16: =B15+1 -> 10 | C16: Notice of Meeting 01/20/2025, 9:00AM, NIA ACIMO Conference Room Finalization of Areas for Inventory of Irrigation System as of December 2024 | F16: MCGS | G16: For signature | I16: •
A17: =A16 -> 45673 | B17: =B16+1 -> 11 | C17: Memorandum of Agreement (MOA) Cabilogan San Juan RIS SPIP | F17: MCGS | G17: For signature
A18: =A17 -> 45673 | B18: =B17+1 -> 12 | C18: CSPC Letter Request to Conduct an Interview & Survey | F18: MCGS
A19: =A18 -> 45673 | B19: =B18+1 -> 13 | C19: To Region: Request for Trailer Truck on Jnauary 18, 2025 | F19: MCGS | G19: For signature
A20: =A19 -> 45673 | B20: =B19+1 -> 14 | C20: Travel Order: OMS-TO064 | F20: MCGS | G20: For signature
A21: =A20 -> 45673 | B21: =B20+1 -> 15 | C21: Letter to LGU Malinao: RESPONSE TO REQUEST FOR ADDITIONAL CANAL CONCRETING PROJECT AND VALIDATION AT BRGY BARIW, MALINAO | F21: MCGS | G21: For signature
A22: =A21 -> 45673 | B22: =B21+1 -> 16 | C22: Payroll (11/18/2024-12/31/2024) Caningag CIS FAW Romel R. Molina & 4 others | F22: MCGS | G22: For signature
A23: =A22 -> 45673 | B23: =B22+1 -> 17 | C23: Ligao Community College Request for permission of ten (10) students for OJT from 01/22/2025-04/03/2025 (400hrs) | F23: MCGS
A24: =A23 -> 45673 | B24: =B23+1 -> 18 | C24: Personnel Locator Slip: 01/16/25, 1:00PM, Official, JLM Agripa | F24: MCGS | G24: For signature
A25: =A24 -> 45673 | B25: =B24+1 -> 19 | C25: To Region: Request for Final Inspection Alobo-Gapo-Inarado CIP (SIP-AL-070-18) Mabalod-Tandarura CIP (SIP-AL-082-18) | F25: MCGS | G25: For signature
A26: =A25 -> 45673 | B26: =B25+1 -> 20 | C26: Personnel Locator Slip: 01/16/2025, 2:00PM, Official, AM Lopez | F26: MCGS | G26: For signature
A27: =A26 -> 45673 | B27: =B26+1 -> 21 | C27: (DRAFT) Revised 2nd APP-CSE CY 2024 for review | F27: MCGS
A28: =A27 -> 45673 | B28: =B27+1 -> 22 | C28: MC No. 145 s. 2022 PGU/LGU Resolution to regulate quarrying activitiers : requirrement prior the implementation of new irrigation projects & repair/rehab/restoration works for existing irrigation system | F28: MCGS
A29: =A28 -> 45673 | B29: =B28+1 -> 23 | C29: Magurang Ubaliw Basud Irrigators Association Resolution No. 2403 s.2024: A Resolution Requesting Me. Mark Cloyd G. So, Acting Division Manager, NIA, Ligao City, Albay for Appropriate Action for the Urgent Repair of Damaged Irrigation Line Canals of Dam 1 and Dam 2 | F29: MCGS
A30: =A29 -> 45673 | B30: =B29+1 -> 24 | C30: To COA: copy of emailed scanned copies of Inspection and Acceptance Report Dated January 16, 2025 | F30: MCGS | G30: For signature
A31: =A30 -> 45673 | B31: =B30+1 -> 25 | C31: Authority to Render Overtime Services: MD Orogo & 3 (01/08/2025) I Cullat (01/12/2025) | F31: MCGS | G31: For signature
A32: =A31 -> 45673 | B32: =B31+1 -> 26 | C32: Travel Order: OMS-TO065 | F32: MCGS | G32: For signature
A33: =A32 -> 45673 | B33: =B32+1 -> 27 | C33: Gate Pass Vcls: 077,078,079,080,081-2025 RIS: 037,038-2025 Transpo Req: 060,056,059,057,054-2025 | F33: MCGS | G33: For signature
A34: =A33 -> 45673 | B34: =B33+1 -> 28 | C34: Travel Order: ENG-TO098,099,100 | F34: MCGS | G34: For signature
A35: =A34 -> 45673 | B35: =B34+1 -> 29 | C35: Application For Leave: RO Clariño (12/23/2024) GS Arabaca (12/26/2024) DA Rebadajo (12/27-28/2024) RO Clariño (01/2-3/2025) AML Dela Cruz (01/02/2025) | F35: MCGS | G35: For signature
A36: ***NOTHING FOLLOWS***
A38: Received, Recorded, Tracked, Disseminated & Filed:
A41: COLEEN M. RASTRULLO | D41: ELLA N. RINGAD | G41: JESSICA V. PEÑAFLOR
A42: Engineering Assistant A | D42: Clerk Processor A | G42: Information Officer C

Sheet 0117
A1: INCOMING DOCUMENTS TO THE OFFICE OF THE IMO MANAGER
A2: 45674
A3: =TEXT(A2,"DDDD") -> Friday
A4: NOTE:
A5: NO. | C5: DOCUMENTS | F5: TO | G5: REMARKS
C6: DOCUMENT | D6: SECTION | E6: TYPE
A7: =A2 -> 45674 | B7: 1 | C7: Follow-up Inspection Report (Fallen Tree along MC of Cabilogan-San Juan RIS) | D7: OMS | F7: MCGS | G7: For Signature
A8: =A7 -> 45674 | B8: =B7+1 -> 2 | C8: Authority to Render Overtime Services: RG Aycardo & 3 (01/08/2025 | D8: ENG'G | F8: MCGS | G8: For Signature
A9: =A8 -> 45674 | B9: =B8+1 -> 3 | C9: Personnel Locator Slip: 01/17/2025, 8:20, Official, A Lopez | D9: ADMIN | F9: MCGS | G9: For Signature
A10: =A9 -> 45674 | B10: =B9+1 -> 4 | C10: GSIS Remittances September 2024 for NIA 501-COB Payroll: AJ Delgado (11/1-15/2024) AN Guarin & 2 (11/16-30/2024) AM Balingasa & 2 (11/1-15/2024) J Bombita & 3 (11/1-15/2024) JP Atanante & 1 (11/1-15/2024) | D10: FINANCE | F10: MCGS | G10: For Signature
A11: =A10 -> 45674 | B11: =B10+1 -> 5 | C11: TEV: JSM Peñafiel (04/02-25/2024) JSM Peñafiel (07/03-26/2024) JSM Peñafiel (08/01-27/2024) JSM Peñafiel (09/03-26/2024) JSM Peñafiel (03/1-18/2024) MDC Salire (August 2024) JSM Peñafiel (10/1-28/2024) CR Reyes (May 2024) | D11: FINANCE | F11: MCGS | G11: For Signature
A12: =A11 -> 45674 | B12: =B11+1 -> 6 | C12: Travel Order: OMS-TO066 | D12: OMS | F12: MCGS | G12: For Signature
A13: =A12 -> 45674 | B13: =B12+1 -> 7 | C13: Gate Pass Vcls: 082,083-2025 Gate Pass Mtls: 004-2025 | F13: MCGS | G13: For Signature
A14: =A13 -> 45674 | B14: =B13+1 -> 8 | C14: Follow-up Letter to Atty. Shella L. Abellano re Civil case No. 1944 Tracking No. 1220017 | F14: MCGS | G14: For Signature
A15: =A14 -> 45674 | B15: =B14+1 -> 9 | C15: Travel Order: OMS-TO067 | F15: MCGS | G15: For Signature
A16: =A15 -> 45674 | B16: =B15+1 -> 10 | C16: Inspection Report: Validation of the Area for Request for Comment on the Revival of Eminent Domain case Entitled "Republic of the Philippines Vs Mariano Garcia" | F16: MCGS | G16: For Signature | I16: •
A17: =A16 -> 45674 | B17: =B16+1 -> 11 | C17: Application for Leave &CTO : 1. Reyes, CR. Et. Al | F17: MCGS | G17: For Signature
A18: =A17 -> 45674 | B18: =B17+1 -> 12 | C18: Cheques & Attachments : Mobilization for Truck 1. Aphard Primecon Construction - PO-EQP-24-12-001 (45,937.50) | F18: MCGS | G18: For Signature
A19: =A18 -> 45674 | B19: =B18+1 -> 13 | C19: Cheque & Attachments : Final Billing Repair/Rehabilitation of Kamanitohan CIS (AL-REPCIS-006-24INF) Php 1,221,599.79 | F19: MCGS | G19: For Signature
A20: =A19 -> 45674 | B20: =B19+1 -> 14 | C20: NWRB-AL-2024-09-050 LGU of Malinao, Albay Ground Water : Brgy. Balading, 4512, Malinao, Albay | F20: MCGS | G20: For Signature
A21: =A20 -> 45674 | B21: =B20+1 -> 15 | C21: Personnel Locator Slip: 1/17/25, LTO Ligao, 10:30 am, JA Amados, OFFICIAL | F21: MCGS | G21: For Signature
A22: =A21 -> 45674 | B22: =B21+1 -> 16 | C22: Gate Pass Mtls: 005-2025 | F22: MCGS | G22: For Signature
A23: =A22 -> 45674 | B23: =B22+1 -> 17 | C23: Authority to Render Overtime Services: NB Oraye (01/11/2025) | F23: MCGS | G23: For Signature
A24: =A23 -> 45674 | B24: =B23+1 -> 18 | C24: DPWH Response re the Flooding Complaint from Brgy. Bariw, Malinao, Albay | F24: MCGS
A25: =A24 -> 45674 | B25: =B24+1 -> 19 | C25: Travel Order: OMS-TO071 | F25: MCGS | G25: For Signature
A26: =A25 -> 45674 | B26: =B25+1 -> 20 | C26: Travel Order: OMS-TO068,069,070 | F26: MCGS | G26: For Signature
A27: =A26 -> 45674 | B27: =B26+1 -> 21 | C27: To Region: IMT-Contract-Nagbarorong Baras IA Inc. | F27: MCGS | G27: For Signature
A28: =A27 -> 45674 | B28: =B27+1 -> 22 | C28: Gate Pass Vcls: 084,085-2025 RIS: 039-2025 Transpo Req: 027,028 | F28: MCGS | G28: For Signature
A29: =A28 -> 45674 | B29: =B28+1 -> 23 | C29: Personnel Locator Slip: 01/17/2025, 3:00PM, Official, DP Vibar | F29: MCGS | G29: For Signature
A30: =A29 -> 45674 | B30: =B29+1 -> 24 | C30: Authority to Render Overtime Services: NS Reodique & 1 (01/18/2025) NS Reodique & 1 (01/19/2025) | F30: MCGS | G30: For Signature
A31: =A30 -> 45674 | B31: =B30+1 -> 25 | C31: Travel Order: ENG-TO 101 | F31: MCGS | G31: For Signature
A32: =A31 -> 45674 | B32: =B31+1 -> 26 | C32: Payroll: ARS Madrideo & 5 (12/19-31/2024) | F32: MCGS | G32: For Signature
A33: =A32 -> 45674 | B33: =B32+1 -> 27 | C33: Payroll: DZ Manlangit & 7 (12/19-31/2024) ACS Guarin & 2 (12/19-31/2024) FB Arcilla & 6 (12/19-31/2024) | F33: MCGS | G33: For Signature
A34: =A33 -> 45674 | B34: =B33+1 -> 28 | C34: Gate Pass Vcls: 086-2025 RIS: 040-2025 Transpo Req: 061-2025 Trip Ticket: 029,030,031,032,033,034,035,036-2025 | F34: MCGS | G34: For Signature
A35: =A34 -> 45674 | B35: =B34+1 -> 29 | C35: FIVC & Final Inspection Report: Tagoytoy CIS (ALCARP-REPCIS-015-24INF) | F35: MCGS
A36: =A35 -> 45674 | B36: =B35+1 -> 30 | C36: Approved Revised CY 2024 POW MNOH MAHABA RIS (OSMCIA) P 50M | F36: MCGS
A37: =A36 -> 45674 | B37: =B36+1 -> 31 | C37: Approved CY 2025 POW MNOH MAHABA RIS (MAZOIA) P 12M | F37: MCGS
A38: =A37 -> 45674 | B38: =B37+1 -> 32 | C38: Payroll ACS Guarin & 2 (01/1-15/2025) | F38: MCGS | G38: For Signature
A39: =A38 -> 45674 | B39: =B38+1 -> 33 | C39: As-Take Plan of Mabini CIS CY 2024 EGPIP-SOLAR | F39: MCGS
A40: =A39 -> 45674 | B40: =B39+1 -> 34 | C40: Approved CY 2025 POW Lower Talisay CIS P 20M | F40: MCGS
...

Sheet 0120
A1: INCOMING DOCUMENTS TO THE OFFICE OF THE IMO MANAGER
A2: 45677
A3: =TEXT(A2,"DDDD") -> Monday
A4: NOTE: | B4: MCGS & BPB on Official Business until 10:45AM
A5: NO. | C5: DOCUMENTS | F5: TO | G5: REMARKS
C6: DOCUMENT | D6: SECTION | E6: TYPE
A7: =A2 -> 45677 | B7: 1 | C7: Travel Order: OMS-TO074,078 | D7: OMS | F7: LFCP | G7: For Signature
A8: =A7 -> 45677 | B8: =B7+1 -> 2 | C8: Itinerary: OMS-TO075,076 | D8: OMS | F8: LFCP | G8: For Signature
A9: =A8 -> 45677 | B9: =B8+1 -> 3 | C9: Personnel Locator Slip: 01/20/2025, 9:30, Official, AM Lopez | D9: ADMIN | F9: LFCP | G9: For Signature
A10: =A9 -> 45677 | B10: =B9+1 -> 4 | C10: Travel Order: OMS-TO079 | D10: OMS | F10: LFCP | G10: For Signature
A11: =A10 -> 45677 | B11: =B10+1 -> 5 | C11: TEV: FT Melgar( June 2024) SA Pontillas (May 2024) SA Pontillas (November 2024) VJA Peralta (October -December 2024) SA Pontillas (August 2024) SA Pontillas (October 2024) SA Pontillas (September 2024) MB Dacillo ( August 1-29, 2024) MB Dacillo (March 1-26, 2024) MB Dacillo (July 2-30, 2024) MB Dacillo ( February 1-23, 2024) MB Dacillo (January 24-July 19, 2024) | D11: FINANCE | F11: MCGS | G11: For Signature
A12: =A11 -> 45677 | B12: =B11+1 -> 6 | C12: Travel Order: ENG-TO125 | D12: ENG'G | F12: MCGS | G12: Backdated For Signature
A13: =A12 -> 45677 | B13: =B12+1 -> 7 | C13: Travel Order: OMS-TO077 Itinerary: OMS-TO080 | D13: OMS | F13: LFCP | G13: For Signature
A14: =A13 -> 45677 | B14: =B13+1 -> 8 | C14: Travel Order: ENG-TO126 | D14: ENG'G | F14: LFCP | G14: For Signature
A15: =A14 -> 45677 | B15: =B14+1 -> 9 | C15: Gate pass Vcls: 092,093,095,096,097,098,091,090-2025 RIS: 043,042,041-2025 Transpo Req: 069,063,066,064,065-2025 Trip Ticket: 040,039,038-2025 | D15: OMS | F15: LFCP | G15: For Signature
A16: =A15 -> 45677 | B16: =B15+1 -> 10 | C16: Itinerary: ENG-TO127 | D16: ENG'G | F16: LFCP | G16: For Signature | I16: •
A17: =A16 -> 45677 | B17: =B16+1 -> 11 | C17: Travel order: ENG-TO128 | D17: ENG'G | F17: LFCP | G17: For Signature
A18: =A17 -> 45677 | B18: =B17+1 -> 12 | C18: Itinerary: ENG-TO130 | D18: ENG'G | F18: LFCP | G18: For Signature
A19: =A18 -> 45677 | B19: =B18+1 -> 13 | C19: Angat Calambay Bulusan IA Inc Resolution No. 02 s. 2025 "A Resolution Requesting Assistance from the NIA ACIMO by Providing a Backhoe for the Desilting of Lined Canals Affected by Flooding due to Typhoons and Heavy Rainfall" | F19: MCGS
A20: =A19 -> 45677 | B20: =B19+1 -> 14 | C20: Gate Pass VCLS: 100-2025 RIS: 044-2025 Transpo Req: 067-2025 | F20: MCGS | G20: For Signature
A21: =A20 -> 45677 | B21: =B20+1 -> 15 | C21: Itinerary: OMS-TO083, 073 | F21: MCGS | G21: For Signature
A22: =A21 -> 45677 | B22: =B21+1 -> 16 | C22: Itinerary: ENG-TO103,104,105,106,107,108,109,110,111,112,113,114, 115, 116,117,118,119,120,121,122,123,124,129 | F22: LFCP | G22: For Signature
A23: =A22 -> 45677 | B23: =B22+1 -> 17 | C23: Itinerary: ENG-TO131 | F23: MCGS | G23: For Signature
A24: =A23 -> 45677 | B24: =B23+1 -> 18 | C24: Gate Pass Mtls: 006-2025 | F24: MCGS | G24: For Signature
