Workbook

Sheet CSJ-MNOH-SQ
A1: NIS IA PROFILE as of : (Month & Year)
A2: Region: V
A3: IMO:
A4: NIS:
A5: Name of IA | C5: Mailing Address | D5: Name of President | E5: Contact Number | F5: Date Organized | G5: Date of SEC Registration | H5: SEC Registration Number | I5: IA TIN | J5: Service Area (ha) | K5: FUSA | L5: Farmer - Beneficiaries (No.) | M5: Actual IA Members (No.) | N5: No. of TSAGs | O5: Existing O & M or IMT Contract (Specify) | P5: Latest Effectivity of Contract | Q5: Length of Canal Under Contract (km) | S5: Gender
P6: President | Q6: District | S6: M | T6: F
A7: Congressional District: I
B9: Sub-total NIS1 | J9: =SUM(J8:J8) -> 0 | K9: =SUM(K8:K8) -> 0 | L9: =SUM(L8:L8) -> 0 | M9: =SUM(M8:M8) -> 0 | N9: =SUM(N8:N8) -> 0 | O9: =COUNT(O8) -> 0 | Q9: =SUM(Q8:Q8) -> 0 | S9: =SUM(S8:S8) -> 0 | T9: =SUM(T8:T8) -> 0
I11: CY 2023 | J11: 3641.2867 | K11: 3636.435 | L11: 4441 | M11: 3976 | N11: 106
J12: =J9-J11 -> -3641.2867 | K12: =K9-K11 -> -3636.435 | L12: =L9-L11 -> -4441 | M12: =M9-M11 -> -3976 | N12: =N9-N11 -> -106

Sheet ALBAY
A1: CIS IA PROFILE as of : DECEMBER 31, 2024
A2: Region: V | G2: =900*12 -> 10800
A3: IMO 1: ALBAY/CATANDUANES
A4: PROVINCE 1: ALBAY
A5: Name of CIS | D5: Irrigators' Association Name | E5: Mailing Address | F5: Name of President | G5: Contact Number | H5: Date Organized | I5: TIN No. | J5: SEC REGISTRATION | L5: WATER PERMIT | N5: Service Area (ha) | O5: FUSA (ha) | P5: Farmer - Beneficiaries | Q5: Actual IA Members | R5: No. of Sectors | S5: Date of Original System Turnover | T5: Date of Latest System Turnover | U5: Amortizing Loan or Fully-paid | V5: Operational or Non-operational | W5: Length of Canal Under Contract (km) | Z5: (With IMT/ Without IMT) | AA5: REMARKS | AC5: Gender
J6: Date of SEC Registration | K6: SEC Registration Number | L6: Water Permit Number | M6: Date Approved | U6: President | W6: Lined | X6: Unlined | Y6: Total | AA6: District | AC6: M | AD6: F
A7: Congressional District: I
A8: 1 | B8: BALADING-AWANG CIS | C8: 1 | D8: BALADING-AWANG IRRIGATORS ASSOCIATION, INC. | E8: Balading, Malinao | F8: Joel C. Casitas | G8: 09485318709 | H8: 2000 | I8: 005-715-040 | J8: 00-00157 | K8: 36662 | L8: on process | M8: on process | N8: 74.7186 | O8: 74.7186 | P8: 105 | Q8: 45 | R8: 2 | S8: 36664 | T8: 40735 | U8: Non-Amortizing | V8: Operational | W8: 1.79 | Y8: =SUM(W8:X8) -> 1.79 | Z8: with IMT contract | AC8: 36 | AD8: 9
A9: =A8+1 -> 2 | B9: BARIW SAN CARLOS CIS | C9: =C8+1 -> 2 | D9: Samahan ng Magsasaka ng San Carlos sa Lupang Pangarap (SAMALUPA) Incorporated | E9: Bariw, Malinao | F9: Fernando B. Cordenete | G9: 09208829164 | H9: 2009 | I9: 762-720-718 | J9: CN202070004 | K9: 43837 | L9: 11727 | M9: 32714 | N9: 109.6278 | O9: 109.6278 | P9: 177 | Q9: 112 | R9: 2 | S9: 40992 | T9: 40992 | U9: Non-Amortizing | V9: Operational | Y9: =SUM(W9:X9) -> 0 | Z9: without IMT contract | AC9: 89 | AD9: 23
A10: =A9+1 -> 3 | B10: BASAGAN CIS | C10: =C9+1 -> 3 | D10: BASAGAN FABRICA FARMERS IRRIGATORS ASSOCIATION,INC | E10: Basagan, Tabaco City | F10: Elpedio G. Cao | G10: 09087259910 | H10: 42265 | I10: 438-010-429-000 | J10: CN201639202 | K10: 42516 | L10: on process | M10: on process | N10: 9.1286 | O10: 9.1286 | P10: 28 | Q10: 20 | R10: 2 | S10: 43139 | T10: 06/17/2022 | U10: Non-Amortizing | V10: Operational | W10: 0.453 | X10: 1.737 | Y10: =SUM(W10:X10) -> 2.19 | Z10: with IMT contract | AC10: 16 | AD10: 4
A11: =A10+1 -> 4 | B11: BAYANDONG CIS | C11: =C10+1 -> 4 | D11: HUNGO-BAYANDONG IRRIGATORS' ASSOCIATION, INC. | E11: Bayandong, Bacacay | F11: Justiniano B. Esplana, Jr. | G11: 09097220716 | H11: 2004 | I11: 005-436-169-000 | J11: 04-27163 | K11: 38104 | L11: on process | M11: on process | N11: 89.5112 | O11: 89.5112 | P11: 103 | Q11: 87 | R11: 3 | S11: 39017 | T11: 41312 | U11: Fully Paid | V11: Operational | W11: 4.61 | Y11: =SUM(W11:X11) -> 4.61 | Z11: with IMT contract | AC11: 54 | AD11: 33
A12: =A11+1 -> 5 | B12: BBMAGUI CIS | C12: =C11+1 -> 5 | D12: BARANGHAWON BOGŇABONG MARIROC GUINOBAT IRRIGATORS ASSOCIATION (BBMAGUI-IA), INC. | E12: Bongabong,Tabaco City | F12: Artemio B. Buenconsejo | G12: 09262677315 | H12: 2011 | I12: 497-201-735 | J12: CN201126239 | K12: 40577 | L12: on process | M12: on process | N12: 156.3617 | O12: 156.3617 | P12: 75 | Q12: 50 | R12: 4 | S12: 08/14/2020 | T12: 8/14/2020 | U12: Non-Amortizing | V12: Operational | W12: 4.3925 | X12: 2.842 | Y12: =SUM(W12:X12) -> 7.2345 | Z12: with IMT contract | AC12: 40 | AD12: 10
A13: =A12+1 -> 6 | B13: BONGA CIS | C13: =C12+1 -> 6 | D13: BONGA MIRISBIRIS IRRIGATORS ASSOCIATION (BMIA), INC. | E13: Bonga, Bacacay, Albay | F13: Eleno B. Nuñez | G13: 09319919491 | H13: 41326 | I13: 439-465-031 | J13: CN201330831 | K13: 41462 | L13: on process | M13: on process | N13: 99.3249 | O13: 99.0016 | P13: 69 | Q13: 15 | R13: 2 | S13: 2013 | T13: 2014 | U13: Non-Amortizing | V13: Operational | W13: 2.329 | X13: 0.807 | Y13: =SUM(W13:X13) -> 3.136 | Z13: with IMT contract | AC13: 10 | AD13: 5
A14: =A13+1 -> 7 | B14: BURABOD-JONOP CIS | C14: =C13+1 -> 7 | D14: BURABOD-JONOP STA. ELENA IRRIGATORS ASSOCIATION, INC. | E14: Burabod, Malinao | F14: JOEL C. CEPEREZ JR. | G14: 09772309263 | H14: 1991 | I14: NONE | J14: OO2153 | K14: 33781 | L14: 14098 | M14: 34299 | N14: 327.3648 | O14: 327.3648 | P14: 333 | Q14: 151 | R14: 5 | S14: 34205 | T14: 40471 | U14: Non-Amortizing | V14: Operational | Y14: =SUM(W14:X14) -> 0 | Z14: without IMT contract | AC14: 120 | AD14: 31
A15: =A14+1 -> 8 | B15: CABASAN CIS | C15: =C14+1 -> 8 | D15: CABASAN-SAN VICENTE IRRIGATORS ASSOCIATION, INC. | E15: Cabasan, Bacacay | F15: Ely A. Bellen | G15: 09515383158 | H15: 41380 | I15: NONE | J15: CN201330088 | K15: 41435 | L15: on process | M15: on process | N15: 16.5087 | O15: 16.5087 | P15: 20 | Q15: 20 | R15: 1 | S15: 42314 | T15: 42929 | U15: Non-Amortizing | V15: Operational | Y15: =SUM(W15:X15) -> 0 | Z15: without IMT contract | AC15: 20 | AD15: 5
A16: =A15+1 -> 9 | B16: CAGBULACAO CIS | C16: =C15+1 -> 9 | D16: CAGBULACAO FARMERS IRRIGATORS ASSOCIATION, INC. | E16: Cagbulacao, Bacacay | F16: EDWIN B. BISTA | G16: 09175178079 | H16: 41331 | I16: NONE | J16: CN201330826 | K16: 41460 | L16: on process | M16: on process | N16: 8.9716 | O16: 7.1457 | P16: 12 | Q16: 12 | R16: 1 | S16: 2015 | T16: 42934 | U16: Non-Amortizing | V16: Operational | Y16: =SUM(W16:X16) -> 0 | Z16: without IMT contract | AC16: 8 | AD16: 7
A17: =A16+1 -> 10 | B17: CAGRARAY CIS | C17: =C16+1 -> 10 | D17: CAGRARAY FARMERS IRRIGATORS ASSOCIATION, INC. | E17: Cagraray, Bacacay | F17: Nelson B. Belleza | G17: NONE | H17: 41338 | I17: NONE | J17: CN201330829 | K17: 41460 | L17: on process | M17: on process | N17: 14.9689 | O17: 14.9689 | P17: 20 | Q17: 20 | R17: 1 | S17: 10/15/2014 | T17: 04/16/2018 | U17: Non-Amortizing | V17: Operational | Y17: =SUM(W17:X17) -> 0 | Z17: without IMT contract | AC17: 15 | AD17: 5
A18: =A17+1 -> 11 | B18: CALE-NAGA CIS | C18: =C17+1 -> 11 | D18: CARARAYAN CALE NAGA LIBJO IRRIGATORS' ASSOCIATION (CACANALIIA), INC. | E18: Cararayan, Tiwi | F18: Miguel C. Clariño | G18: 09774006032 | H18: 1998 | I18: 264-025-603 | J18: 200827757 | K18: 39544 | L18: on process | M18: on process | N18: 127.7262 | O18: 127.7262 | P18: 200 | Q18: 184 | R18: 4 | S18: 36056 | T18: 40651 | U18: Non-Amortizing | V18: Operational | W18: 3.8 | Y18: =SUM(W18:X18) -> 3.8 | Z18: with IMT contract | AC18: 150 | AD18: 34
A19: =A18+1 -> 12 | B19: CANAWAY CIS | C19: =C18+1 -> 12 | D19: CANSICO IRRIGATORS ASSOCIATION, INC. | E19: Malilipot, Albay | F19: Marcial C. Camo | G19: 09952998896 | H19: 40349 | I19: 297-210-305-000 | J19: CN201029937 | K19: 40216 | L19: on process | M19: on process | N19: 74.5528 | O19: 74.5528 | P19: 115 | Q19: 104 | R19: 3 | S19: 40640 | T19: 41310 | U19: Fully Paid | V19: Operational | W19: 5.41 | Y19: =SUM(W19:X19) -> 5.41 | Z19: with IMT contract | AC19: 84 | AD19: 20
A20: =A19+1 -> 13 | B20: CASANRA CIS | C20: =C19+1 -> 13 | D20: CA-SAN-RA TABACO IRRIGATORS ASSOCIATION INC | E20: Purok 5, Cabangan, Tabaco City | F20: Efren B. Bombeta | G20: none | H20: 01-18-2020 | I20: 768-158-627 | J20: CN202070080 | K20: 03-02-2020 | L20: on process | M20: on process | N20: 11.9954 | O20: 11.9954 | P20: 17 | Q20: 17 | R20: 1 | S20: 11/19/2021 | T20: 11/19/2021 | U20: Non-Amortizing | V20: Operational | Y20: =SUM(W20:X20) -> 0 | Z20: without IMT contract | AC20: 8 | AD20: 2
A21: =A20+1 -> 14 | B21: COROCORO BELEN CIS | C21: =C20+1 -> 14 | D21: COBEGA FARMERS IRRIGATORS ASSOCIATION, INC. | E21: Corocoro, Tiwi, Albay | F21: Jose C. Arbo | G21: 09194826373 | H21: 42410 | I21: 485-420-506-000 | J21: CN201639196 | K21: 42514 | L21: on process | M21: on process | N21: 77.9005 | O21: 77.9005 | P21: 35 | Q21: 22 | R21: 1 | S21: 43137 | U21: Non-Amortizing | V21: Operational | W21: 2.393 | X21: 1.247 | Y21: =SUM(W21:X21) -> 3.64 | Z21: with IMT contract | AC21: 15 | AD21: 7
A22: =A21+1 -> 15 | B22: DIARO CIS | C22: =C21+1 -> 15 | D22: DIARO IRRIGATORS' ASSOCIATION, INC. | E22: Diaro, Malinao | F22: Julian C. Cascabel | G22: 09097417988 | H22: 31701 | I22: 004-981-065 | J22: 142714 | K22: 31980 | L22: 11247 | M22: 32379 | N22: 85.6152 | O22: 75.7889 | P22: 82 | Q22: 66 | R22: 3 | S22: 29589 | T22: 40837 | U22: Non-Amortizing | V22: Operational | W22: 2.49 | Y22: =SUM(W22:X22) -> 2.49 | Z22: with IMT contract | AC22: 53 | AD22: 13
A23: =A22+1 -> 16 | B23: Estancia-Labnig CIS | C23: =C22+1 -> 16 | D23: ESTANCIA LABNIG IRRIGATORS ASSN, INC. | E23: Estancia, Malinao | F23: Florante C. Bayonito | H23: 1991 | I23: 005-615-533 | J23: 192362 | K23: 33413 | L23: 14126 | M23: 34320 | N23: 153.8508 | O23: 153.8508 | P23: 130 | Q23: 80 | R23: 2 | S23: 34815 | T23: 40494 | U23: Non-Amortizing | V23: Operational | W23: 2.175 | X23: 1.244 | Y23: =SUM(W23:X23) -> 3.419 | Z23: with IMT contract | AC23: 64 | AD23: 16
C24: =C23+1 -> 17 | D24: LABNIG CIS IRRIGATORS' ASSOCIATION, INC | E24: Labnig, Malinao | F24: Pio B. Casi | G24: 09478793192 | H24: 2002 | I24: 296-930-972 | J24: CN200253494 | K24: 37505 | L24: 14125 | M24: 34320 | P24: 109 | Q24: 60 | R24: 2 | S24: 2008 | T24: 40494 | U24: Non-Amortizing | V24: Operational | W24: 4.753 | Y24: =SUM(W24:X24) -> 4.753 | Z24: with IMT contract | AC24: 48 | AD24: 12
A25: =A23+1 -> 17 | B25: FIDEL SURTIDA CIS | C25: =C24+1 -> 18 | D25: FISTOSAN IRRIGATORS ASSOCIATION, INC. | E25: Sto. Domingo, Albay | F25: Bernardo Cortuna | G25: 09308338312 | H25: 1998 | I25: 434-028-921 | J25: CN201228532 | K25: 40933 | L25: on process | M25: on process | N25: 100.0244 | O25: 100.0244 | P25: 117 | Q25: 97 | R25: 3 | S25: 30497 | T25: 2011 | U25: Fully Paid | V25: Operational | Y25: =SUM(W25:X25) -> 0 | Z25: without IMT contract | AC25: 99 | AD25: 24
A26: =A25+1 -> 18 | B26: GOGON CIS | C26: =C25+1 -> 19 | D26: VINICASAN IRRIGATORS' ASSOCIATION, INC. | E26: Vinisitahan, Bacacay | F26: Jose B. Bernarte Jr. | H26: 1980 | I26: 004-979-965 | J26: 156740 | K26: 32444 | L26: 11423 | M26: 32503 | N26: 152.7195 | O26: 152.7195 | P26: 150 | Q26: 143 | R26: 4 | S26: 29731 | T26: 41313 | U26: Non-Amortizing | V26: Operational | W26: 6.69 | X26: 0.8 | Y26: =SUM(W26:X26) -> 7.49 | Z26: with IMT contract | AC26: 118 | AD26: 30
A27: =A26+1 -> 19 | B27: GUBAT-HINDI CIS | C27: =C26+1 -> 20 | D27: HINDI- GUBAT IRAYA IRRIGATORS ASSOCIATION, INC. | E27: Bacacay, Albay | F27: Arnel B. Boholst | G27: 09637270904 | H27: 2000 | I27: 005-716-921 | J27: 97-001421 | K27: 35550 | L27: on process | M27: on process | N27: 43.8112 | O27: 43.8112 | P27: 99 | Q27: 93 | R27: 5 | S27: 37321 | T27: 41313 | U27: Non-Amortizing | V27: Operational | W27: 3.206 | X27: 0.894 | Y27: =SUM(W27:X27) -> 4.1 | Z27: with IMT contract | AC27: 85 | AD27: 8
A28: =A27+1 -> 20 | B28: GUINOBAT CIS | C28: =C27+1 -> 21 | D28: GUINOBAT IRRIGATORS ASSOCIATION, INC. | E28: Guinobat, Tabaco City | F28: Loreto B. Almonte | G28: 09162112170 | H28: 43116 | I28: 468-719-560 | J28: 201539189 | K28: 43233 | L28: on process | M28: on process | N28: 25.9485 | O28: 25.9485 | P28: 23 | Q28: 23 | R28: 2 | S28: 44418 | T28: 3/15/2024 | U28: Non-Amortizing | V28: non-operational | Y28: =SUM(W28:X28) -> 0 | Z28: without IMT contract | AC28: 18 | AD28: 5
A29: =A28+1 -> 21 | B29: HACIENDA DD | C29: =C28+1 -> 22 | D29: HACIENDA TABACO AGRARIAN FARMERS ASSOCIATION (HATAFA), INC. | E29: Hacienda, Tabaco | F29: Adelina L. Balingbing | G29: 09109284462 | H29: 36722 | I29: 461-351-581 | J29: 1200100167 | K29: 37069 | L29: on process | M29: on process | N29: 89.6423 | O29: 89.6423 | P29: 102 | Q29: 73 | R29: 2 | S29: 40317 | T29: 3/30/2015 | U29: Non-Amortizing | V29: Operational | W29: 2.769 | Y29: =SUM(W29:X29) -> 2.769 | Z29: with IMT contract | AC29: 72 | AD29: 8 | AL29: New entry/ new organized
A30: =A29+1 -> 22 | B30: LANGATON CIS | C30: =C29+1 -> 23 | D30: LANGATON SAN RAFAEL FARMERS IRRIGATORS ASSOCIATION, INC. | E30: Langaton, Bacacay | F30: BENITA P. APILLADA | G30: 09301347161 | H30: Feb, 2012 | I30: 475-777206-000 | J30: 201539473CN | K30: 42276 | L30: on process | M30: on process | N30: 17.9384 | O30: 17.9384 | P30: 35 | Q30: 12 | R30: 2 | S30: 41317 | T30: 41317 | U30: Non-Amortizing | V30: Operational | Y30: =SUM(W30:X30) -> 0 | Z30: without IMT contract | AC30: 24 | AD30: 6 | AL30: Not included in the inventory
A31: =A30+1 -> 23 | B31: LIBJO CIS | C31: =C30+1 -> 24 | D31: TIGBI BOLO LIBJO (TIBOLI) IRRIGATORS ASSOCIATION, INC, | E31: Libjo, Tiwi, Albay | F31: Gilberto C. Climacosa | G31: 09150078575 | H31: May 27,2012 | I31: 439-927-161-000 | J31: CN201232689 | K31: 41205 | L31: on process | M31: on process | N31: 69.9637 | O31: 69.9637 | P31: 100 | Q31: 34 | R31: 3 | S31: 41788 | T31: no more project implemented | U31: Non-Amortizing | V31: Operational | W31: 4.169 | X31: 0.143 | Y31: =SUM(W31:X31) -> 4.312 | Z31: with IMT contract | AC31: 29 | AD31: 5
A32: =A31+1 -> 24 | B32: MANAET CIS | C32: =C31+1 -> 25 | D32: MANAET SMALL FARMERS IRRIGATORS ASSOCIATION, INC. | E32: Manaet, Bacacay | F32: Efren B. Bongadillo | G32: 09103478424 | H32: 41343 | I32: 440-249-000 | J32: CN201329390 | K32: 41381 | L32: on process | M32: on process | N32: 8.5102 | O32: 7.814 | P32: 18 | Q32: 18 | R32: 1 | S32: 42130 | T32: 43201 | U32: Non-Amortizing | V32: Operational | Y32: =SUM(W32:X32) -> 0 | Z32: without IMT contract | AC32: 10 | AD32: 8
A33: =A32+1 -> 25 | B33: MARIROC CIS | C33: =C32+1 -> 26 | D33: TABACO IRRIGATORS' ASSOCIATION, INC. | E33: Matagbac, Tabaco | F33: Domingo B. Serrano | G33: 09306930864 | H33: 1980 | I33: 005-434-463 | J33: 158917 | K33: 32913 | L33: 11336 | M33: on process | N33: 189.3883 | O33: 177.1948 | P33: 222 | Q33: 117 | R33: 4 | S33: 30632 | T33: 41320 | U33: Non-Amortizing | V33: Operational | W33: 8.25 | Y33: =SUM(W33:X33) -> 8.25 | Z33: with IMT contract | AC33: 80 | AD33: 37
A34: =A33+1 -> 26 | B34: MATALIPNI CIS | C34: =C33+1 -> 27 | D34: MATALIPNI MALOLOS IRRIGATORS ASSOCIATION (MAMAIA), INC. | E34: Matalipni, Malinao, Albay | F34: Bernardo C. Canesa | G34: 09289579874 | H34: 42359 | I34: 486-007-444 | J34: CN201639195 | K34: 42514 | L34: on process | M34: on process | N34: 39.8862 | O34: 39.8862 | P34: 62 | Q34: 62 | R34: 2 | S34: 2/28/2017 | T34: 2/28/2017 | U34: Non-Amortizing | V34: Operational | W34: 0.993 | X34: 0.023 | Y34: =SUM(W34:X34) -> 1.016 | Z34: with IMT contract | AC34: 55 | AD34: 7
B35: ORAS - TABIGUIAN CIS | C35: =C34+1 -> 28 | D35: RAS-GUIAN TABACO IRRIGATORS ASSOCIATION Inc. | E35: Purok 5, Tabiguian, Tabaco City | F35: Clarito T. Bilardo | G35: none | H35: 01-16-2020 | I35: 767-273-189-000 | J35: CN202070067 | K35: 02-21-2020 | L35: on process | M35: on process | N35: 15 | O35: 15 | P35: 20 | Q35: 60 | R35: 1 | S35: 11/25/2021 | T35: 11/25/2021 | V35: non-operational | Y35: =SUM(W35:X35) -> 0 | Z35: without IMT contract | AC35: 24 | AD35: 6
A36: =A34+1 -> 27 | B36: SAGPAN KAN BANWA CIS | C36: =C35+1 -> 29 | D36: SAGPAN KAN BANWA IRRIGATORS ASSOCIATION INC. | E36: Awang, Malinao, Albay | F36: Henry B. Cervantes | G36: 09186572921 | H36: 43172 | I36: IRC0001130215 | J36: CN201809763 | K36: 43259 | L36: on process | M36: on process | N36: 146.0559 | O36: 146.0559 | P36: 91 | Q36: 52 | R36: 3 | S36: 44418 | T36: 44418 | U36: Non-Amortizing | V36: Operational | W36: 2.034 | X36: 4.202 | Y36: =SUM(W36:X36) -> 6.236 | Z36: with IMT contract | AC36: 42 | AD36: 10
A37: =A36+1 -> 28 | B37: SAN ANTONIO CIS | C37: =C36+1 -> 30 | D37: SAN ANTONIO TABACO IRRIGATORS' ASSOCIATION, INC. | E37: San Antonio, Tabaco City | F37: Guillermo Sardana | G37: 09204199352 | H37: 39975 | I37: 297-328-299 | J37: CN201029956 | K37: 40381 | L37: on process | M37: on process | N37: 39.2016 | O37: 39.2016 | P37: 148 | Q37: 48 | R37: 1 | S37: 40470 | T37: 40484 | U37: Fully Paid | V37: Operational | W37: 2.253 | Y37: =SUM(W37:X37) -> 2.253 | Z37: with IMT contract | AC37: 37 | AD37: 11
A38: =A37+1 -> 29 | B38: SAN FRANCISCO RIS | C38: =C37+1 -> 31 | D38: COLANOS TANGKALAO IA, INC. | E38: Tabaco/Malinao | F38: SALVADOR B. CASIN | G38: 09636521170 | H38: 40448 | I38: 406-583-897-000 | J38: CN201032353 | K38: 40519 | L38: on process | M38: on process | N38: 661.0387 | O38: 609.3483 | P38: 1461 | Q38: 1461 | R38: 4 | S38: 42591 | T38: 42591 | U38: Non-Amortizing | V38: Operational | W38: 2.423 | Y38: =SUM(W38:X38) -> 2.423 | Z38: with IMT contract | AC38: 1168 | AD38: 293
A39: =A38+1 -> 30 | B39: SOA CIS | C39: =C38+1 -> 32 | D39: SOA IRRIGATORS ASSOCIATION, INC. | E39: Soa, Malinao | F39: Crisanto Bon | G39: 09274145293 | H39: 1996 | I39: 005-714-898 | J39: 97-00141 | K39: 35550 | L39: on process | M39: on process | N39: 5.0395 | O39: 5.0395 | P39: 21 | Q39: 3 | R39: 1 | S39: 35699 | T39: 37379 | U39: Fully Paid | V39: Operational | Y39: =SUM(W39:X39) -> 0 | Z39: without IMT contract | AC39: 8 | AD39: 5
A40: =A39+1 -> 31 | B40: SSMISAN CIS | C40: =C39+1 -> 33 | D40: SAN FERNANDO STA. MISERICORDIA IRRIGATORS ASSOCIATION, INC. | E40: Misericordia, Sto. Domingo | F40: Nelson M. Balinquit | G40: 09097715309 | H40: 2009 | I40: 290-794-624 | J40: CN200931683 | K40: 40144 | L40: on process | M40: on process | N40: 28.5528 | O40: 28.5528 | P40: 85 | Q40: 85 | R40: 1 | S40: 2010 | T40: 2011 | U40: Fully Paid | V40: Operational | W40: 1.18 | Y40: =SUM(W40:X40) -> 1.18 | Z40: with IMT contract | AC40: 68 | AD40: 17
...
