Workbook

Sheet Summary
C4: Employment Status | D4: Number of Employees
C5: PERMANENT/CO-TERMINUS | D5: ='REGIONAL OFFICE'!D170+ACIMO!D153+CNIMO!D105+CSIMO!D265+SMIMO!D114 -> 126
C6: CASUAL (COB) | D6: ='REGIONAL OFFICE'!D171+ACIMO!D154+CNIMO!D106+CSIMO!D266+SMIMO!D115 -> 147
C7: CASUAL (Project-Charged) | D7: ='REGIONAL OFFICE'!D172+ACIMO!D155+CNIMO!D107+CSIMO!D267+SMIMO!D116 -> 46
C8: JOB ORDER | D8: ='REGIONAL OFFICE'!D173+ACIMO!D156+CNIMO!D108+CSIMO!D268+SMIMO!D117 -> 275
C9: CONTRACT OF SERVICE | D9: ='REGIONAL OFFICE'!D174+ACIMO!D157+CNIMO!D109+CSIMO!D269+SMIMO!D118 -> 93
C10: Total | D10: ='REGIONAL OFFICE'!D175+ACIMO!D158+CNIMO!D110+CSIMO!D270+SMIMO!D119 -> 687

Sheet REGIONAL OFFICE
A1: AS OF JULY 2026
A2: PERMANENT/CO-TERMINUS
A3: No. | B3: ID No. | C3: Name | D3: Designation / Position | E3: Sex | F3: Date of Birth | G3: Office
A4: =1 -> 1 | B4: 163547 | C4: Albia, Jiselle E. | D4: Chief, Finance Section/Chief Corporate Accountant B | E4: F | F4: 08/21/1988 | G4: Finance Section
A5: =A4+1 -> 2 | B5: 620930 | C5: Amisola, Jonnah Rose R. | D5: Engineering Assistant A | E5: F | F5: 33119 | G5: Construction Management Section
A6: =A5+1 -> 3 | B6: 549361 | C6: Antonio, Jesus P. | D6: Utility Worker A | E6: M | F6: 26708 | G6: Administrative Section
A7: =A6+1 -> 4 | B7: 706818 | C7: Aquino, Ailyn P. | D7: Senior Engineer A | E7: F | F7: 35176 | G7: Operations and Maintenance Section
A8: =A7+1 -> 5 | B8: 333623 | C8: Azurias, Angelita V. | D8: Data Encoder | E8: F | F8: 26959 | G8: Planning and Design Section
A9: =A8+1 -> 6 | B9: 582940 | C9: Azurias, Joie T. | D9: Heavy Equipment Operator | E9: M | F9: 29309 | G9: Equipment Section
A10: =A9+1 -> 7 | B10: 809774 | C10: Balane, Annette | D10: Chief, Construction Section/Senior Engineer A | E10: F | F10: 46216 | G10: Construction Management Section
A11: =A10+1 -> 8 | B11: 250317 | C11: Balondo, Eduardo A. | D11: Chief, Equipment Section /Principal Engineer C | E11: M | F11: 24569 | G11: Operations and Maintenance Section
A12: =A11+1 -> 9 | B12: 482392 | C12: Baraero, Ma. Cleofe B. | D12: Public Relations Officer A | E12: F | F12: 31673 | G12: Office of the Regional Manager
A13: =A12+1 -> 10 | B13: 301467 | C13: Bayrante, Job Jr. B. | D13: Administrative Officer IV (Accounting) | E13: M | F13: 34275 | G13: Finance Section
A14: =A13+1 -> 11 | B14: 813367 | C14: Briton, Kimberly A. | D14: Senior Accounting Processor B | E14: F | F14: 35012 | G14: Finance Section
A15: =A14+1 -> 12 | B15: 688176 | C15: Brusas, Abel P. | D15: Senior Supply Officer | E15: M | F15: 31782 | G15: Administrative Section
A16: =A15+1 -> 13 | B16: 826525 | C16: Buen, Virgilio S. | D16: Driver Mechanic B | E16: M | F16: 26914 | G16: Equipment Section
... A28: =A27+1 -> 25 | B28: 852114 | C28: Federis, Jerry Ivan R. | D28: Data Encoder | E28: M | F28: 35280 | G28: Administrative Section
A29: =A28+1 -> 26 | B29: 987833 | C29: Gozon, Russell D. | D29: Driver Mechanic B | E29: M | F29: 06/23/1984 | G29: Office of the Regional Manager
A30: =A29+1 -> 27 | B30: 797270 | C30: Joven, Carla Marthy T. | D30: Senior Irrigators Development Officer | E30: F | F30: 31188 | G30: Institutional Development Section
A31: =A30+1 -> 28 | B31: 388739 | C31: Madrid, Jane Mitchille Valerie A. | D31: Senior Computer Services Programmer | E31: F | F31: 32440 | G31: Office of the Regional Manager
A32: =A31+1 -> 29 | B32: 518967 | C32: Medrano, Mary Grace P. | D32: Irrigators Development Officer A | E32: F | F32: 32116 | G32: Institutional Development Section
A33: =A32+1 -> 30 | B33: 628726 | C33: Oatemar, Marilou O. | D33: Chief, Institutional Development Section / Supervising Irrigators Development Officer | E33: F | F33: 22800 | G33: Institutional Development Section
A34: =A33+1 -> 31 | B34: 136268 | C34: Otordos, Christine Mae M. | D34: Data Encoder | E34: F | F34: 37135 | G34: Finance Section
A35: =A34+1 -> 32 | B35: 620692 | C35: Panuelos, Romeo Jr. A. | D35: Industrial Security Guard A | E35: M | F35: 29010 | G35: Administrative Section
A36: =A35+1 -> 33 | B36: 149654 | C36: Posugac, Charliemagne Señar | D36: Storekeeper B | E36: M | F36: 03/04/1993 | G36: Administrative Section
A37: =A36+1 -> 34 | B37: 698289 | C37: Ramos, Mark Lo B. | D37: Supervising Engineer A | E37: M | F37: 34075 | G37: Operations and Maintenance Section
A38: =A37+1 -> 35 | B38: 395329 | C38: Rañola, Chazzie L. | D38: Senior Accounting Processor B | E38: F | F38: 36051 | G38: Finance Section
A39: =A38+1 -> 36 | B39: 454671 | C39: Rebadulla, Joseph A. | D39: Division Manager A | E39: M | F39: 29292 | G39: Office of the Division Manager, AFD
A40: =A39+1 -> 37 | B40: 907603 | C40: Renta, Roel R. | D40: Utility Worker A | E40: M | F40: 27493 | G40: Administrative Section
A41: =A40+1 -> 38 | B41: 481988 | C41: Requiro, Joseph Christopher A. | D41: Chief, Equipment Section/Supervising Engineer A (ME) | E41: M | F41: 35094 | G41: Equipment Section
A42: =A41+1 -> 39 | B42: 560714 | C42: Rubi, Nicole D. | D42: Senior Accounting Processor A | E42: F | F42: 35563 | G42: Finance Section
A43: =A42+1 -> 40 | B43: 839488 | C43: Santos, Anne A. | D43: Senior Irrigators Development Officer | E43: F | F43: 27240 | G43: Institutional Development Section
A44: =A43+1 -> 41 | B44: 432925 | C44: Sarmiento, Ma. Sarah E. | D44: Engineer A | E44: F | F44: 34716 | G44: Construction Management Section
A45: =A44+1 -> 42 | B45: 573674 | C45: Sentillas, Conrado R. | D45: Industrial Security Guard A | E45: M | F45: 23949 | G45: Administrative Section
A46: =A45+1 -> 43 | B46: 504243 | C46: Templonuevo, Andre F. | D46: Senior Draftsman | E46: M | F46: 23193 | G46: Planning and Design Section
A47: =A46+1 -> 44 | B47: 942094 | C47: Varde, George A. | D47: Industrial Security Guard A | E47: M | F47: 32377 | G47: Administrative Section
A48: ***NOTHING FOLLOWS***
A50: CASUAL (COB)
A51: No. | B51: ID No. | C51: Name | D51: Designation / Position | E51: Sex | F51: Date of Birth | G51: Office
A52: 1 | B52: 978735 | C52: Agaton, Collen Kate N. | D52: Engineer A | E52: F | F52: 35605 | G52: Operations and Maintenance Section
...

Sheet ACIMO
A1: AS OF JULY 20, 2026
A2: PERMANENT/CO-TERMINUS
A3: No. | B3: ID No. | C3: Name | D3: Designation / Position | E3: Sex | F3: Date of Birth | G3: Office
A4: 1 | B4: 596165 | C4: SO, Mark Cloyd G. | D4: Acting Division Manager/Supervising Engineer A | E4: M | F4: 31589 | G4: Albay Office
A5: =A4+1 -> 2 | B5: 587812 | C5: BERDIN, Ian Feliciano III P. | D5: Senior Water Resources Facilities Technician | E5: M | F5: 27113 | G5: Albay Office
A6: =A5+1 -> 3 | B6: 472890 | C6: BALONDO, Senen A. | D6: Industrial Security Guard A | E6: M | F6: 26029 | G6: Albay Office
A7: =A6+1 -> 4 | B7: 578550 | C7: PAJE, Jojo O. | D7: Industrial Security Guard A | E7: M | F7: 27980 | G7: Albay Office
A8: =A7+1 -> 5 | B8: 583972 | C8: DURAN, Maureen R. | D8: Corporate Accounts Analyst | E8: M | F8: 27829 | G8: Albay Office
A9: =A8+1 -> 6 | B9: 164959 | C9: PANTE, Lech Fidel C. | D9: Engineer A | E9: M | F9: 33116 | G9: Albay Office
A10: =A9+1 -> 7 | B10: 817959 | C10: NACARIO, John Bernard S. | D10: Water Resources Facilities Operator B | E10: M | F10: 31386 | G10: Albay Office
A11: =A10+1 -> 8 | B11: 722450 | C11: REODIQUE, Nestor S. | D11: Heavy Equipment Operator | E11: M | F11: 28163 | G11: Albay Office
A12: =A11+1 -> 9 | B12: 723219 | C12: MARQUEZ, Angelo V. | D12: Sr. Engineer A | E12: M | F12: 28446 | G12: Catanduanes Sub-Office
A13: =A12+1 -> 10 | B13: 929272 | C13: MANLANGIT, Vilma M. | D13: Sr. Accounting Processor B | E13: F | F13: 26671 | G13: Albay Office
A14: =A13+1 -> 11 | B14: 660100 | C14: DAYUPAY, Jennimel R. | D14: Engineer A | E14: M | F14: 33926 | G14: Albay Office
A15: =A14+1 -> 12 | B15: 740109 | C15: REYES, Conchita R. | D15: Irrigator's Development Officer A | E15: F | F15: 23643 | G15: Albay Office
A16: ***NOTHING FOLLOWS***
A18: CASUAL (COB)
A19: No. | B19: ID No. | C19: Name | D19: Designation / Position | E19: Sex | F19: Date of Birth | G19: Office
A20: 1 | B20: 990269 | C20: ABILA, Ela Mae S. | D20: Procurement Analyst B | E20: F | F20: 36085 | G20: Albay Office
A21: =A20+1 -> 2 | B21: 599880 | C21: ADELANTE, Isagani Jr. P. | D21: Industrial Security Guard A | E21: M | F21: 28809 | G21: Catanduanes Sub-Office
A22: =A21+1 -> 3 | B22: 545194 | C22: ALNAS, Mark Anjo T. | D22: Engineer A | E22: M | F22: 34051 | G22: Catanduanes Sub-Office
A23: =A22+1 -> 4 | B23: 135180 | C23: ARABACA, Gilbert S. | D23: Senior Engineer A | E23: M | F23: 33619 | G23: Albay Office
A24: =A23+1 -> 5 | B24: 983454 | C24: BALINGASA, Aliza May D. | D24: Irrigator's Development Officer A | E24: F | F24: 37022 | G24: Albay Office
A25: =A24+1 -> 6 | B25: 706109 | C25: BALITA, Marcos B. | D25: Industrial Security Guard A | E25: M | F25: 30611 | G25: Albay Office
A26: =A25+1 -> 7 | B26: 287556 | C26: BELGADO, Ma. Dolores S. | D26: Supervising Engineer A | E26: F | F26: 28556 | G26: Albay Office
A27: =A26+1 -> 8 | B27: 705491 | C27: CALPE, Amy B. | D27: Data Encoder | E27: F | F27: 30689 | G27: Albay Office
A28: =A27+1 -> 9 | B28: 505503 | C28: CLARIÑO, Roland O. | D28: Survey Aide A | E28: M | F28: 31163 | G28: Albay Office
A29: =A28+1 -> 10 | B29: 488433 | C29: COMPLETO, Jessica B. | D29: Senior Engineer A | E29: F | F29: 35057 | G29: Albay Office
A30: =A29+1 -> 11 | B30: 411215 | C30: DEDASE, Luisito O. | D30: Property Officer B | E30: M | F30: 29050 | G30: Albay Office
A31: =A30+1 -> 12 | B31: 905404 | C31: DELA CRUZ, Alexandra Mae L. | D31: Engineering Assistant A | E31: F | F31: 35616 | G31: Albay Office
A32: =A31+1 -> 13 | B32: 489240 | C32: DELGADO, Alexandra Joy M. | D32: Data Encoder | E32: F | F32: 35340 | G32: Albay Office
... A51: =A50+1 -> 32 | B51: 568533 | C51: SARION, Jane Amy R. | D51: Engineer A | E51: F | F51: 36760 | G51: Albay Office
A52: ***NOTHING FOLLOWS***
A54: CASUAL (Project-Charged)
A55: No. | B55: ID No. | C55: Name | D55: Designation / Position | E55: Sex | F55: Date of Birth | G55: Office
A56: 1 | B56: 970465 | C56: NACARIO, Richard S. | D56: Administrative Services Assistant B | E56: M | F56: 29566 | G56: Albay Office
A57: =A56+1 -> 2 | B57: 435914 | C57: ORAYE, Noel Jr. B. | D57: Foreman A | E57: M | F57: 35631 | G57: Albay Office
A58: =A57+1 -> 3 | B58: 669920 | C58: DETERA, Dale Derick L. | D58: Survey Aide A | E58: M | F58: 36089 | G58: Albay Office
A59: =A58+1 -> 4 | B59: 447264 | C59: DACILLO, Milany B. | D59: Senior Water Resources Facilities Technician | E59: F | F59: 28745 | G59: Albay Office
A60: =A59+1 -> 5 | B60: 478643 | C60: JACOB, Elizabeth J. | D60: Sr. Irrigator's Development Officer A | E60: F | F60: 23614 | G60: Albay Office
...

Sheet CNIMO
A1: AS OF JULY 2026
A2: PERMANENT/CO-TERMINUS
A3: No. | B3: ID No. | C3: Name | D3: Designation / Position | E3: Sex | F3: Date of Birth | G3: Office
A4: 1 | B4: 926247 | C4: Villaluz, Edmundo T. | D4: Principal Engineer A | E4: M | F4: 25064 | G4: IMO Manager
A5: 2 | B5: 772266 | C5: Abanto, Michael Louie Q. | D5: Industrial Security Guard A | E5: M | F5: 27641 | G5: Operations Section/ Equipment Unit
A6: 3 | B6: 715099 | C6: Abraham, Mario M. | D6: Utility Worker A | E6: M | F6: 25889 | G6: Administrative Section/ General Services
A7: 4 | B7: 191397 | C7: Avila, Archie B. | D7: Engineer A | E7: M | F7: 33678 | G7: Engineering Section
A8: 5 | B8: 207698 | C8: Capistrano, Ricky M. | D8: Water Resources Facilities Operator B | E8: M | F8: 27687 | G8: Operations Section/ O&M
A9: 6 | B9: 804461 | C9: Dela Cruz, Ernesto Jr. O. | D9: Driver Mechanic B | E9: M | F9: 25480 | G9: Operations Section/ Equipment Unit
A10: 7 | B10: 207635 | C10: Diaz, Joven R. | D10: Industrial Security Guard A | E10: M | F10: 30644 | G10: Administrative Section/ General Services
A11: 8 | B11: 641778 | C11: Eboña, Joan M. | D11: Sr. Accounting Processor A | E11: F | F11: 30126 | G11: Finance Section
A12: 9 | B12: 336696 | C12: Encinares, Emelie A. | D12: Data Encoder | E12: F | F12: 29447 | G12: Administrative Section/ Human Resource Unit
A13: 10 | B13: 522405 | C13: Espeso, Alejandro B. | D13: Sr. Water Resources Facilities Technician | E13: M | F13: 23588 | G13: Operations Section
A14: 11 | B14: 367836 | C14: King, Roger Allan B. | D14: Sr. Engineer A | E14: M | F14: 32246 | G14: Office of the IMO Manager
A15: 12 | B15: 193132 | C15: Magana, Jesus Y. | D15: Collection Representative A | E15: M | F15: 29184 | G15: Administrative Section
... A20: 17 | B20: 129682 | C20: Villamonte, Mariano R. | D20: Irrigator's Development Officer A | E20: M | F20: 25437 | G20: Operations Section/ Institutional Development Unit
A21: ***NOTHING FOLLOWS***
A23: CASUAL (COB)
A24: No. | B24: ID No. | C24: Name | D24: Designation / Position | E24: Sex | F24: Date of Birth | G24: Office
A25: 1 | B25: 659076 | C25: Abarca, Romy L. | D25: Engineering Assistan B | E25: M | F25: 36641 | G25: Operations Section/ O&M
A26: 2 | B26: 194698 | C26: Agot, Joy Ann Rachel P. | D26: Administrative Services Officer B | E26: F | F26: 34638 | G26: Administrative Section/ Human Resource Unit
A27: 3 | B27: 112454 | C27: Almonte, Kristine Joe P. | D27: Senior Engineer A | E27: F | F27: 36848 | G27: Engineering Section/ Planning
A28: 4 | B28: 413063 | C28: Argente, Joemel J. | D28: Supervising Engineer A | E28: M | F28: 34919 | G28: Engineering Section/ Design
A29: 5 | B29: 505837 | C29: Azagra, Ronellyn A. | D29: Survey Aide A | E29: F | F29: 33030 | G29: Administrative Section/ Property/ BAC Support
A30: 6 | B30: 889738 | C30: Baliwag, Arvin P. | D30: Irrigator's Development Officer A | E30: M | F30: 36679 | G30: Operations Section/ Institutional Development Unit
A31: 7 | B31: 135023 | C31: Dizon, Leslie Ravien P. | D31: Engineering Assistant A | E31: F | F31: 36414 | G31: Engineering Section/ Design
A32: 8 | B32: 551850 | C32: Eboña, Rene Dick A. | D32: Industrial Security Guard A | E32: M | F32: 29842 | G32: Administrative Section/ General Services
A33: 9 | B33: 499755 | C33: Factor, Romnel E. | D33: Engineering Assistant A | E33: M | F33: 35533 | G33: Engineering Section/ Construction
A34: 10 | B34: 671031 | C34: Ilagan, Ella Mae B. | D34: Senior Engineer A | E34: F | F34: 34252 | G34: Engineering Section/ Design
A35: 11 | B35: 563502 | C35: Lamadrid, John Rey F. | D35: Senior Irrigator's Development Officer | E35: M | F35: 35748 | G35: Operations Section/ Institutional Development Unit
A36: 12 | B36: 226523 | C36: Lopez, John Paul S. | D36: Industrial Security Guard A | E36: M | F36: 33826 | G36: Administrative Section/ General Services
... A52: 28 | B52: 533788 | C52: Zaleta, Ma. Carmi V. | D52: Survey Aide A | E52: F | F52: 31084 | G52: Finance Section/ Accounting
A53: ***NOTHING FOLLOWS***
A55: CASUAL (Project-Charged)
A56: No. | B56: ID No. | C56: Name | D56: Designation / Position | E56: Sex | F56: Date of Birth | G56: Office
A57: 1 | B57: 680795 | C57: Casuga, Shirley K. | D57: Research Assistant A | E57: F | F57: 28075 | G57: Operations Section/ Institutional Development Unit
A58: 2 | B58: 829433 | C58: Talento, Ismael S. | D58: Research Assistant B | E58: M | F58: 26576 | G58: Operations Section/ Institutional Development Unit
A59: ***NOTHING FOLLOWS***
A61: JOB ORDER
A62: No. | B62: ID No. | C62: Name | D62: Designation / Position | E62: Sex | F62: Date of Birth | G62: Office
...

Sheet CSIMO
A1: AS OF JULY 2026
A2: PERMANENT/CO-TERMINUS
A3: No. | B3: ID No. | C3: Name | D3: Designation / Position | E3: Sex | F3: Date of Birth | G3: Office
A4: 1 | B4: 600292 | C4: Rañola, Carol L. | D4: Division Manager A | E4: F | F4: 26363 | G4: Camarines Sur IMO - Head Office
A5: 2 | B5: 147234 | C5: Aguilar, Elthon S. | D5: Driver-Mechanic B | E5: M | F5: 27611 | G5: Camarines Sur IMO - Head Office
A6: 3 | B6: 328765 | C6: Aguilar, Joel S. Jr. | D6: Senior Engineer A | E6: M | F6: 32380 | G6: Camarines Sur IMO - Head Office
A7: 4 | B7: 454516 | C7: Beraquit, Raejane Mae A. | D7: Industrial Relations Management/Development Officer C | E7: F | F7: 33221 | G7: Camarines Sur IMO - Head Office
A8: 5 | B8: 163561 | C8: Cabiles, Andrew B. | D8: Senior Irrigators' Development Officer A | E8: M | F8: 35384 | G8: Camarines Sur IMO - Head Office
A9: 6 | B9: 269133 | C9: Floriano, Don Jose S. | D9: Industrial Security Guard A | E9: M | F9: 26317 | G9: Camarines Sur IMO - Head Office
A10: 7 | B10: 670799 | C10: Gaddi, Nori Nilo A. | D10: Driver-Mechanic B | E10: M | F10: 25252 | G10: Camarines Sur IMO - Head Office
A11: 8 | B11: 715888 | C11: Madrid, Albert Felix A. | D11: Data Encoder | E11: M | F11: 30102 | G11: Camarines Sur IMO - Head Office
A12: 9 | B12: 555528 | C12: Montes, Eleanor R. | D12: Senior Financial Planning Analyst | E12: F | F12: 26339 | G12: Camarines Sur IMO - Head Office
A13: 10 | B13: 576341 | C13: Ragodon, Dennis P. | D13: Engineer A | E13: M | F13: 25175 | G13: Camarines Sur IMO - Head Office
A14: 11 | B14: 325765 | C14: Reyes, Dave Randel Y. | D14: Industrial Security Guard A | E14: M | F14: 28814 | G14: Camarines Sur IMO - Head Office
A15: 12 | B15: 177316 | C15: Saboco, Anna Rose R. | D15: Engineering Assistant B | E15: F | F15: 34776 | G15: Camarines Sur IMO - Head Office
... A48: 45 | B48: 801762 | C48: Hermogeno, Ruth Maria Magdalena P. | D48: Irrigators Development Officer A | E48: F | F48: 22849 | G48: Camarines Sur IMO - Head Office
A49: ***NOTHING FOLLOWS***
A51: CASUAL (COB)
A52: No. | B52: ID No. | C52: Name | D52: Designation / Position | E52: Sex | F52: Date of Birth | G52: Office
A53: 1 | B53: 480488 | C53: Albaño, Mark Anthony D. | D53: Hydrologist | E53: M | F53: 36142 | G53: Camarines Sur IMO - Head Office
A54: 2 | B54: 643529 | C54: Anagao, Clarice S. | D54: Engineer A | E54: F | F54: 35766 | G54: Camarines Sur IMO - Head Office
A55: 3 | B55: 259062 | C55: Apa, Russel R. | D55: Senior Engineer A | E55: M | F55: 33277 | G55: Camarines Sur IMO - Head Office
A56: 4 | B56: 186295 | C56: Arroyo, Mariano Jr. E. | D56: Heavy Equipment Operator | E56: M | F56: 26640 | G56: Camarines Sur IMO - Head Office
A57: 5 | B57: 277263 | C57: Asares, Angelica Mae D. | D57: Records Officer D | E57: F | F57: 35654 | G57: Camarines Sur IMO - Head Office
A58: 6 | B58: 954708 | C58: Balondo, Ed Brian M. | D58: Administrative Aide III (Utility Worker A) | E58: M | F58: 36802 | G58: Camarines Sur IMO - Head Office
A59: 7 | B59: 522588 | C59: Buena, Ace B. | D59: Senior Engineer A | E59: M | F59: 33862 | G59: Camarines Sur IMO - Head Office
A60: 8 | B60: 241341 | C60: Bustilla, Gil P. | D60: Supervising Engineer A | E60: M | F60: 35296 | G60: Camarines Sur IMO - Head Office
A61: 9 | B61: 629251 | C61: Cabrera, Justine E. | D61: Welder A | E61: M | F61: 37758 | G61: Camarines Sur IMO - Head Office
A62: 10 | B62: 230274 | C62: Cañaveral, Jose Leo L. | D62: Engineer A | E62: M | F62: 33939 | G62: Camarines Sur IMO - Head Office
A63: 11 | B63: 684033 | C63: Cleofas, Jaspher C. | D63: Senior Engineer A | E63: M | F63: 33520 | G63: Camarines Sur IMO - Head Office
A64: 12 | B64: 118238 | C64: Dela Cruz, Marciano Jr. S. | D64: Foreman A | E64: M | F64: 33298 | G64: Camarines Sur IMO - Head Office
... A98: 46 | B98: 286498 | C98: Margaja, Geovanni C. | D98: Heavy Equipment Operator | E98: M | F98: 29921 | G98: Rinconada Integrated Irrigation System
A99: ***NOTHING FOLLOWS***
A101: CASUAL (Project-Charged)
A102: No. | B102: ID No. | C102: Name | D102: Designation / Position | E102: Sex | F102: Date of Birth | G102: Office
A103: 1 | B103: 657564 | C103: Luna, Krystal Mae E. | D103: Engineer A | E103: F | F103: 36675 | G103: Camarines Sur IMO - Head Office
A104: 2 | B104: 863059 | C104: Gavica, Edgardo Jr. C | D104: Engineering Assistant A | E104: M | F104: 33960 | G104: Camarines Sur IMO - Head Office
A105: 3 | B105: 654749 | C105: Palacay, Elsie F. | D105: Clerk Processor A | E105: F | F105: 34090 | G105: Libmanan-Cabusao Pump Irrigation System
A106: 4 | B106: 381946 | C106: Baluca, Paciano E. | D106: Driver-Mechanic B | E106: M | F106: 23315 | G106: Rinconada Integrated Irrigation System
A107: 5 | B107: 827681 | C107: Samson, Enrique D. | D107: Driver | E107: M | F107: 25449 | G107: Rinconada Integrated Irrigation System
...

Sheet SMIMO
A1: AS OF JULY 2026
A2: PERMANENT/CO-TERMINUS
A3: No. | B3: ID No. | C3: Name | D3: Designation / Position | E3: Sex | F3: Date of Birth | G3: Office
A4: =1 -> 1 | B4: 679718 | C4: Baynas, Jessie D. | D4: Principal Engineer A/Acting Division Manager | E4: M | F4: 29341 | G4: Sorsogon-Masbate Irrigation Management Office
A5: =A4+1 -> 2 | B5: 956072 | C5: Correa, Carl James M. | D5: Water Res.Fac. Operator B | E5: M | F5: 37108 | G5: Sorsogon-Masbate Irrigation Management Office
A6: =A5+1 -> 3 | B6: 214340 | C6: Domanico, Marichu E. | D6: Senior Water Resources Fac. Tech | E6: F | F6: 31391 | G6: Sorsogon-Masbate Irrigation Management Office
A7: =A6+1 -> 4 | B7: 432299 | C7: Marco, Ariel L. | D7: Senior IDO | E7: M | F7: 31387 | G7: Sorsogon-Masbate Irrigation Management Office
A8: =A7+1 -> 5 | B8: 946218 | C8: Nopre, Sherwin Rois R. | D8: Senior Engineer A | E8: M | F8: 33374 | G8: Sorsogon-Masbate Irrigation Management Office
A9: =A8+1 -> 6 | B9: 838420 | C9: Fauni, Annie R. | D9: Engineer A | E9: F | F9: 35087 | G9: Sorsogon-Masbate Irrigation Management Office
A10: =A9+1 -> 7 | B10: 116532 | C10: Federis, Jona E. | D10: Senior Accounting Processor B | E10: F | F10: 31508 | G10: Sorsogon-Masbate Irrigation Management Office
A11: =A10+1 -> 8 | B11: 679911 | C11: Valeriano, Maridol G. | D11: Irrigator's Development Officer A | E11: F | F11: 30612 | G11: Sorsogon-Masbate Irrigation Management Office
A12: ***NOTHING FOLLOWS***
A14: CASUAL (COB)
A15: No. | B15: ID No. | C15: Name | D15: Designation / Position | E15: Sex | F15: Date of Birth | G15: Office
A16: 1 | B16: 198016 | C16: Albino, Francisco Jr. P. | D16: Driver Mechanic A | E16: M | F16: 29402 | G16: Sorsogon-Masbate Irrigation Management Office
A17: 2 | B17: 184086 | C17: Aninipot, Cynthia E. | D17: Administration Services Assistant C | E17: F | F17: 29982 | G17: Sorsogon-Masbate Irrigation Management Office
A18: 3 | B18: 175539 | C18: Bolandro, Aleah Lalaine S. | D18: Engineer A | E18: F | F18: 36635 | G18: Sorsogon-Masbate Irrigation Management Office
A19: 4 | B19: 783099 | C19: Dometita, Jezra D. | D19: Engineer A | E19: M | F19: 35948 | G19: Sorsogon-Masbate Irrigation Management Office
A20: 5 | B20: 689545 | C20: Furigay, Neling M. | D20: Irrigators Dev't Officer A | E20: F | F20: 28913 | G20: Sorsogon-Masbate Irrigation Management Office
A21: 6 | B21: 177823 | C21: Granado, Jerry G. | D21: Administrative Aide lV(Watchman) | E21: M | F21: 28570 | G21: Sorsogon-Masbate Irrigation Management Office
A22: 7 | B22: 665387 | C22: Tamboong, Alfie G. | D22: Administrative Aide lll (UW-A) | E22: M | F22: 30897 | G22: Sorsogon-Masbate Irrigation Management Office
A23: 8 | B23: 298597 | C23: Ulmido, Julei Andrea L. | D23: Senior Engineer A | E23: F | F23: 35257 | G23: Sorsogon-Masbate Irrigation Management Office
A24: 9 | B24: 505744 | C24: Tenorio, Richille L. | D24: Engineer A | E24: M | F24: 35374 | G24: Sorsogon-Masbate Irrigation Management Office
A25: ***NOTHING FOLLOWS***
A27: CASUAL (Project-Charged)
A28: No. | B28: ID No. | C28: Name | D28: Designation / Position | E28: Sex | F28: Date of Birth | G28: Office
A29: =1 -> 1 | B29: 575385 | C29: Abas, Archie A. | D29: Driver | E29: M | F29: 29822 | G29: Sorsogon-Masbate Irrigation Management Office
A30: =A29+1 -> 2 | B30: 701306 | C30: Abejuela, Mark Anthony G. | D30: Administrative Aide l | E30: M | F30: 29803 | G30: Sorsogon-Masbate Irrigation Management Office
A31: =A30+1 -> 3 | B31: 453983 | C31: Albao, Joselito L. | D31: Engineering Assistant A | E31: M | F31: 27285 | G31: Sorsogon-Masbate Irrigation Management Office
A32: =A31+1 -> 4 | B32: 576927 | C32: Ariscon, Christine V. | D32: Engineering Assistant A | E32: F | F32: 30455 | G32: Sorsogon-Masbate Irrigation Management Office
A33: =A32+1 -> 5 | B33: 691972 | C33: Baleza, Mark Glenn S. | D33: Engineering Assistant A | E33: M | F33: 36426 | G33: Sorsogon-Masbate Irrigation Management Office
A34: =A33+1 -> 6 | B34: 635784 | C34: Barruga, Vicente D. | D34: Irrigator's Development Officer A | E34: M | F34: 33125 | G34: Sorsogon-Masbate Irrigation Management Office
A35: =A34+1 -> 7 | B35: 181281 | C35: Borilla, Ruben E. | D35: Senior Mason | E35: M | F35: 23345 | G35: Sorsogon-Masbate Irrigation Management Office
A36: =A35+1 -> 8 | B36: 856465 | C36: Carpon, Janielle Chloe G. | D36: Accounting Processor A | E36: F | F36: 36770 | G36: Sorsogon-Masbate Irrigation Management Office
A37: =A36+1 -> 9 | B37: 571407 | C37: Carpon, Genaro Jr. G. | D37: Driver Mechanic A | E37: M | F37: 27083 | G37: Sorsogon-Masbate Irrigation Management Office
A38: =A37+1 -> 10 | B38: 981786 | C38: Casilao, Jonathan G. | D38: Engineering Assistant A | E38: M | F38: 30837 | G38: Sorsogon-Masbate Irrigation Management Office
A39: =A38+1 -> 11 | B39: 177281 | C39: Dometita, Arnold D. | D39: Survey Aide A | E39: M | F39: 26146 | G39: Sorsogon-Masbate Irrigation Management Office
A40: =A39+1 -> 12 | B40: 446295 | C40: Haya, Cammille B. | D40: Senior Irrigator's Development Officer | E40: F | F40: 34141 | G40: Sorsogon-Masbate Irrigation Management Office
A41: =A40+1 -> 13 | B41: 187811 | C41: Masip, Sheree Ann L. | D41: Engineering Assistant A | E41: F | F41: 31482 | G41: Sorsogon-Masbate Irrigation Management Office
... A43: =A42+1 -> 15 | B43: 516319 | C43: Serrano, Rica | D43: Research Assistant A | E43: F | F43: 36496 | G43: Sorsogon-Masbate Irrigation Management Office
...
