Workbook

Sheet JULY 16-31, 2026
B1: REPUBLIC OF THE PHILIPPINES
B2: OFFICE OF THE PRESIDENT
B3: National Irrigation Administration
B4: ALBAY-CATANDUANES IRRIGATION MANAGEMENT OFFICE
B5: Virac, Catanduanes
A7: T I M E B O O K
AD8: AFD - JOB ORDER
B10: For Labor on | C10: LFP | AC10: For the period: | AD10: July 16-31, 2026
C11: (State Project which was performed)
AG12: NO. OF MINUTES
B13: N A M E | C13: DESIGNATION | D13: T I M E R O L L | T13: No. of days worked | U13: No. of Compressed days worked | V13: Rate per Day | W13: GROSS AMOUNT | X13: OVERTIME | Y13: TOTAL | Z13: TOTAL EARNINGS FOR THE PERIOD OF JUNE 1-15 | AA13: BIR | AB13: HDMF | AC13: TOTAL DEDUCTIONS | AD13: NET | AE13: LBP | AG13: OVERTIME
D14: 16 | E14: 17 | F14: 18 | G14: 19 | H14: 20 | I14: 21 | J14: 22 | K14: 23 | L14: 24 | M14: 25 | N14: 26 | O14: 27 | P14: 28 | Q14: 29 | R14: 30 | Y14: EARNINGS FOR | AA14: SSS | AB14: HDMF-MPL | AD14: AMOUNT | AE14: ATM NUMBER
X15: UNDERTIME | Y15: THE PERIOD | AA15: NIAMPCO-ML | AD15: DUE | AG15: UNDERTIME
A16: 1 | B16: ARCILLA, MA. ELAINE E. | C16: Clerk Processor A | D16: X | E16: X | F16: S | G16: S | H16: X | I16: X | J16: X | K16: X | L16: X | M16: S | N16: S | O16: X | P16: X | Q16: X | R16: X | S16: X | T16: =COUNTIF(C16:S16,"X")*1+(COUNTIF(C16:R16,"/")/2)+COUNTIF(C16:R16,"OB")+COUNTIF(C16:R16,"SPH") -> 12 | U16: =COUNTIF(D16:R16,"CW")*1.25+(COUNTIF(D16:R16,"0.5")*1.25/2)+COUNTIF(D16:R16,"OB")+COUNTIF(D16:R16,"SPH") -> 0 | V16: 814.41 | W16: =ROUND(SUM(T16+U16)*V16,2) -> 9772.92 | Y16: =ROUND(SUM(W16+X16-X17),2) -> 9772.92 | Z16: 6515.28 | AA16: =ROUND(SUM(Y16+Z16)*(0.03),2) -> 488.65 | AB16: 200 | AC16: =ROUND(SUM(AA16+AA17+AA18+AB16+AB17+AB18),2) -> 688.65 | AD16: =ROUND(SUM(Y16-AC16),2) -> 9084.27 | AE16: 2767072972
X17: =V16/8/60*AG17 -> 0 | AG17: 0
AA18: =ROUND(SUM(Y18*0.03),2) -> 0 | AB18: 0
A19: 2 | B19: BEO, EDILBERTO JR. R. | C19: Irrigator's Development Officer A | D19: X | E19: / | F19: S | G19: S | H19: A | I19: / | J19: X | K19: X | L19: X | M19: S | N19: S | O19: X | P19: X | Q19: X | R19: X | S19: X | T19: =COUNTIF(C19:S19,"X")*1+(COUNTIF(C19:R19,"/")/2)+COUNTIF(C19:R19,"OB")+COUNTIF(C19:R19,"SPH") -> 10 | U19: =COUNTIF(D19:R19,"CW")*1.25+(COUNTIF(D19:R19,"0.5")*1.25/2)+COUNTIF(D19:R19,"OB")+COUNTIF(D19:R19,"SPH") -> 0 | V19: 1087.63 | W19: =ROUND(SUM(T19+U19)*V19,2) -> 10876.3 | Y19: =ROUND(SUM(W19+X19-X20),2) -> 10876.3 | Z19: 11950.33 | AA19: =ROUND(SUM(Y19+Z19)*(0.03),2) -> 684.8 | AB19: 200 | AC19: =ROUND(SUM(AA19+AA20+AA21+AB19+AB20+AB21),2) -> 884.8 | AD19: =ROUND(SUM(Y19-AC19),2) -> 9991.5 | AE19: 0897091518
X20: =V19/8/60*AG20 -> 0 | AG20: 0
AA21: =ROUND(SUM(Y21*0.03),2) -> 0
A22: 3 | B22: BRIOSO, JOHN LEARRY A. | C22: Watchman II | D22: X | E22: X | F22: OT | G22: S | H22: X | I22: X | J22: X | K22: X | L22: X | M22: OT | N22: S | O22: X | P22: X | Q22: X | R22: X | S22: X | T22: =COUNTIF(C22:S22,"X")*1+(COUNTIF(C22:R22,"/")/2)+COUNTIF(C22:R22,"OB")+COUNTIF(C22:R22,"SPH") -> 12 | U22: =COUNTIF(D22:R22,"CW")*1.25+(COUNTIF(D22:R22,"0.5")*1.25/2)+COUNTIF(D22:R22,"OB")+COUNTIF(D22:R22,"SPH") -> 0 | V22: 609.86 | W22: =ROUND(SUM(T22+U22)*V22,2) -> 7318.32 | X22: =V22*1.5*2 -> 1829.58 | Y22: =ROUND(SUM(W22+X22-X23),2) -> 9147.9 | Z22: 8538.04 | AA22: =ROUND(SUM(Y22+Z22)*(0.03),2) -> 530.58 | AB22: 200 | AC22: =ROUND(SUM(AA22+AA23+AA24+AB22+AB23+AB24),2) -> 730.58 | AD22: =ROUND(SUM(Y22-AC22),2) -> 8417.32 | AE22: 0897059835
AG23: 0
AA24: =ROUND(SUM(Y24*0.03),2) -> 0
A25: 4 | B25: LUMBAO, JOSHUA A. | C25: Engineer B | D25: X | E25: X | F25: S | G25: S | H25: X | I25: X | J25: X | K25: X | L25: X | M25: S | N25: S | O25: X | P25: X | Q25: X | R25: X | S25: X | T25: =COUNTIF(C25:S25,"X")*1+(COUNTIF(C25:R25,"/")/2)+COUNTIF(C25:R25,"OB")+COUNTIF(C25:R25,"SPH") -> 12 | U25: =COUNTIF(D25:R25,"CW")*1.25+(COUNTIF(D25:R25,"0.5")*1.25/2)+COUNTIF(D25:R25,"OB")+COUNTIF(D25:R25,"SPH") -> 0 | V25: 1087.63 | W25: =ROUND(SUM(T25+U25)*V25,2) -> 13051.56 | Y25: =ROUND(SUM(W25+X25-X26),2) -> 13040.23 | Z25: 11932.21 | AA25: =ROUND(SUM(Y25+Z25)*(0.03),2) -> 749.17 | AB25: 200 | AC25: =ROUND(SUM(AA25+AA26+AA27+AB25+AB26+AB27),2) -> 949.17 | AD25: =ROUND(SUM(Y25-AC25),2) -> 12091.06 | AE25: 0897084236
X26: =V25/8/60*AG26 -> 11.329479 | AG26: 5
A28: 5 | B28: MANLANGIT, DINDO Z. | C28: Irrigator's Development Officer A | D28: / | E28: X | F28: S | G28: S | H28: A | I28: A | J28: A | K28: A | L28: A | M28: S | N28: S | O28: X | P28: X | Q28: X | R28: X | S28: X | T28: =COUNTIF(C28:S28,"X")*1+(COUNTIF(C28:R28,"/")/2)+COUNTIF(C28:R28,"OB")+COUNTIF(C28:R28,"SPH") -> 6.5 | U28: =COUNTIF(D28:R28,"CW")*1.25+(COUNTIF(D28:R28,"0.5")*1.25/2)+COUNTIF(D28:R28,"OB")+COUNTIF(D28:R28,"SPH") -> 0 | V28: 1087.63 | W28: =ROUND(SUM(T28+U28)*V28,2) -> 7069.6 | Y28: =ROUND(SUM(W28+X28-X29),2) -> 6620.95 | Z28: 11689.76 | AA28: =ROUND(SUM(Y28+Z28)*(0.03),2) -> 549.32 | AB28: 200 | AC28: =ROUND(SUM(AA28+AA29+AA30+AB28+AB29+AB30),2) -> 749.32 | AD28: =ROUND(SUM(Y28-AC28),2) -> 5871.63
X29: =V28/8/60*AG29 -> 448.64738 | AA29: =ROUND(SUM(Y29+Z29)*(0.03),2) -> 0 | AG29: 198
AA30: =ROUND(SUM(Y30*0.03),2) -> 0
A31: 6 | B31: MELGAR, FREDERICK T. | C31: Sr Irrigator's Development Officer A | D31: X | E31: X | F31: S | G31: S | H31: X | I31: X | J31: X | K31: X | L31: X | M31: S | N31: S | O31: X | P31: X | Q31: X | R31: X | S31: X | T31: =COUNTIF(C31:S31,"X")*1+(COUNTIF(C31:R31,"/")/2)+COUNTIF(C31:R31,"OB")+COUNTIF(C31:R31,"SPH") -> 12 | U31: =COUNTIF(D31:R31,"CW")*1.25+(COUNTIF(D31:R31,"AM")*0.5625)+COUNTIF(D31:R31,"OB")+COUNTIF(D31:R31,"SPH") -> 0 | V31: 1357.46 | W31: =ROUND(SUM(T31+U31)*(V31),2) -> 16289.52 | Y31: =ROUND(SUM(W31+X31-X32),2) -> 16066.1 | Z31: 14827.42 | AA31: =ROUND(SUM(Y31+Z31)*(0.03),2) -> 926.81 | AB31: 200 | AC31: =ROUND(SUM(AA31+AA32+AA33+AB31+AB32+AB33),2) -> 1126.81 | AD31: =ROUND(SUM(Y31-AC31),2) -> 14939.29 | AE31: 0897067080
X32: =V31/8/60*AG32 -> 223.41529 | AG32: 79
AA33: =ROUND(SUM(Y33*0.03),2) -> 0
A34: 7 | B34: TAPIA, KAYCEELYN M. | C34: Engineer B | D34: X | E34: X | F34: S | G34: S | H34: X | I34: X | J34: X | K34: X | L34: X | M34: S | N34: S | O34: X | P34: X | Q34: X | R34: X | S34: X | T34: =COUNTIF(C34:S34,"X")*1+(COUNTIF(C34:R34,"/")/2)+COUNTIF(C34:R34,"OB")+COUNTIF(C34:R34,"SPH") -> 12 | U34: =COUNTIF(D34:R34,"CW")*1.25+(COUNTIF(D34:R34,"0.5")*1.25/2)+COUNTIF(D34:R34,"OB")+COUNTIF(D34:R34,"SPH") -> 0 | V34: 1087.63 | W34: =ROUND(SUM(T34+U34)*V34,2) -> 13051.56 | Y34: =ROUND(SUM(W34+X34-X35),2) -> 13047.03 | Z34: 11420.12 | AA34: =ROUND(SUM(Y34+Z34)*(0.03),2) -> 734.01 | AB34: 200 | AC34: =ROUND(SUM(AA34+AA35+AA36+AB34+AB35+AB36),2) -> 934.01 | AD34: =ROUND(SUM(Y34-AC34),2) -> 12113.02 | AE34: 0897084228
X35: =V34/8/60*AG35 -> 4.5317917 | AG35: 2
AA36: =ROUND(SUM(Y36*0.03),2) -> 0
A37: 8 | B37: TORIO, JOMEL M. | C37: Administrative Services Assistant B | D37: X | E37: X | F37: S | G37: S | H37: X | I37: X | J37: X | K37: X | L37: X | M37: S | N37: S | O37: X | P37: X | Q37: X | R37: X | S37: X | T37: =COUNTIF(C37:S37,"X")*1+(COUNTIF(C37:R37,"/")/2)+COUNTIF(C37:R37,"OB")+COUNTIF(C37:R37,"SPH") -> 12 | U37: =COUNTIF(D37:R37,"CW")*1.25+(COUNTIF(D37:R37,"0.5")*1.25/2)+COUNTIF(D37:R37,"OB")+COUNTIF(D37:R37,"SPH") -> 0 | V37: 941.17 | W37: =ROUND(SUM(T37+U37)*V37,2) -> 11294.04 | Y37: =ROUND(SUM(W37+X37-X38),2) -> 11294.04 | Z37: 10352.87 | AA37: =ROUND(SUM(Y37+Z37)*(0.03),2) -> 649.41 | AB37: 200 | AC37: =ROUND(SUM(AA37+AA38+AA39+AB37+AB38+AB39),2) -> 849.41 | AD37: =ROUND(SUM(Y37-AC37),2) -> 10444.63 | AE37: 0897060523
X38: =V37/8/60*AG38 -> 0 | AG38: 0
AA39: =ROUND(SUM(Y39*0.03),2) -> 0
B40: Item 1 - To be utilized in the clerical works in Catanduanes Sub-Office; To perform other tasks as required; Item 2 -To be utilized in various institutional works in Catanduanes; Item 3- To be utilized in the janitorial and other office maintenance works; and as Watchman; To assist in the monitoring and inspection of projects under FAW/LMC works (Catanduanes Sub-Office); Item 4- To be utilized in the survey works, monitoring, supervision and preparation of related reports of CY 2026 projects of Alinawan CIS, Tinago-Villa Aurora CIS, and San Jose CIS; To be utilized in monitoring, supervision, and preparation of related reports/documents of CY 2025 carry over SPIP for Aroyao SPIP; To be utilized in preparation of POW and Plans of additional CY 2026 projects of Hicming CIS and Mambang CIS; To perform other related tasks required to be accomplished; Item 5- To monitor the ongoing implementation of the institutional development activities of all SRI projects;To check and assist in the program of work for institutional development activities; Assist in the conduct of geo-resistivity survey of proposed solar projects; To check and review the monthly activities and accomplishments of institutional development activities; To conduct periodic site inspection to ensure proper implementation of institutional development activities; To assist in the validation of Potential Irrigable Area for development and preparation of reports; To perform other related tasks required to be accomplished; Item 6- To assist in the continuous implementation and monitoring of institutional development; To assist in the preparation of budget, evaluation of POWs and reports; To consolidate IA performance; To provide provisions on technical assistance and support to the validation of IA awardees;To perform other related tasks required to be accomplished. Item 7- To be utilized in the survey works, monitoring, supervision and preparation of related reports of CY 2026 projects of San Roque CIS and SIAY proposed SPIP;To be utilized in monitoring, supervision, and preparation of related reports/documents of CY 2025 carry over SPIP for Pajo San Isidro SPIP;To be utilized in preparation of POW and Plans of additional CY 2026 projects of Tinago Villa Aurora CIS & San Roque CIS; To perform other related tasks required to be accomplished; Item 8- Utilized in clerical and admin-related works in Catandunaes Sub-Office and other tasks as required.
X41: =X16+X19+X22+X25+X28+X31+X34+X37 -> 1829.58 | AA41: =ROUND(SUM(AA16:AA39),2) -> 5312.75 | AB41: =ROUND(SUM(AB16:AB39),2) -> 1600
AA42: =AA17+AA20+AA23+AA26+AA32+AA35+AA38 -> 0
X43: =-(687.93) -> -687.93
...

Sheet SUMMARY (1-15)-D&6 (2)
A1: S U M M A R Y O F P A Y R O L L
A3: Name | C3: MA. ELAINE E. ARCILLA
A4: Bureau/Province/Municipal | C4: CATANDUANES/SAN ANDRES
A5: For the Period | C5: JULY 1-15, 2025
A6: P R O J E C T
A8: S h e e t | B8: N u m b e r | C8: A m o u n t | D8: Amount Paid | E8: T r a n s f e r r e d T o
A9: N o . | B9: o f R o l l s | C9: o f R o l l s | D9: o f R o l l s
A10: 1 | C10: =#REF! -> #REF! | D10: =#REF! -> #REF! | E10: ='[1]TIMEBOOK (1-15)-D&6'!Y13 -> BIR | F10: =#REF! -> #REF!
E11: ='[1]TIMEBOOK (1-15)-D&6'!Z13 -> HDMF | F11: =#REF! -> #REF!
E12: ='[1]TIMEBOOK (1-15)-D&6'!Y14 -> SSS | F12: ='[1]TIMEBOOK (1-15)-D&6'!Y39 -> 0
E13: ='[1]TIMEBOOK (1-15)-D&6'!Z14 -> HDMF-MPL | F13: ='[1]TIMEBOOK (1-15)-D&6'!Z39 -> 0
E14: ='[1]TIMEBOOK (1-15)-D&6'!Y15 -> NIAMPCO-ML | F14: ='[1]TIMEBOOK (1-15)-D&6'!Y40 -> 0
E15: ='[1]TIMEBOOK (1-15)-D&6'!Z15 -> 0 | F15: ='[1]TIMEBOOK (1-15)-D&6'!Z40 -> 0
C21: =C10 -> #REF! | D21: =SUM(D10:D20) -> #REF! | F21: =SUM(F10:F20) -> #REF!
A23: 1) I HEREBY CERTIFY that the attached | E23: 3) I HEREBY CERTIFY on my official
A24: payroll/s and summary of which appears here- | E24: oath that the payroll/s and summary of
A25: on is/are correct and just and that the ser- | E25: which appears hereon, are the best of my
A26: vices were rendered under my direction and | E26: knowledge and belief proper and correct
A27: I approved payment thereof this ___ day of | E27: the same being chargeable to the appro-
A28: ______________________________________. | E28: priation set aside. THEREOF, I FURTHER
E29: CERTIFY that the payment thereon have
E30: been made in the amount of | F30: =D21 -> #REF!
E31: =PROPER(CHOOSE(LEFT(TEXT(D21,"000000000.00"))+1,,"One","Two","Three","Four","Five","Six","Seven","Eight","Nine")&IF(--LEFT(TEXT(D21,"000000000.00"))=0,,IF(AND(--MID(TEXT(D21,"000000000.00"),2,1)=0,--MID(TEXT(D21,"000000000.00"),3,1)=0)," Hundred"," Hundred "))&CHOOSE(MID(TEXT(D21,"000000000.00"),2,1)+1,,,"Twenty ","Thirty ","Forty ","Fifty ","Sixty ","Seventy ","Eighty ","Ninety ")&IF(--MID(TEXT(D21,"000000000.00"),2,1)<>1,CHOOSE(MID(TEXT(D21,"000000000.00"),3,1)+1,,"One","Two","Three","Four","Five","Six","Seven","Eight","Nine"),CHOOSE(MID(TEXT(D21,"000000000.00"),3,1)+1,"Ten","Eleven","Twelve","Thirteen","Fourteen","Fifteen","Sixteen","Seventeen","Eighteen","Nineteen"))&IF((--LEFT(TEXT(D21,"000000000.00"))+MID(TEXT(D21,"000000000.00"),2,1)+MID(TEXT(D21,"000000000.00"),3,1))=0,,IF(AND((--MID(TEXT(D21,"000000000.00"),4,1)+MID(TEXT(D21,"000000000.00"),5,1)+MID(TEXT(D21,"000000000.00"),6,1)+MID(TEXT(D21,"000000000.00"),7,1))=0,(--MID(TEXT(D21,"000000000.00"),8,1)+RIGHT(TEXT(D21,"000000000.00")))>0)," Million"," Million "))&CHOOSE(MID(TEXT(D21,"000000000.00"),4,1)+1,,"One","Two","Three","Four","Five","Six","Seven","Eight","Nine")&IF(--MID(TEXT(D21,"000000000.00"),4,1)=0,,IF(AND(--MID(TEXT(D21,"000000000.00"),5,1)=0,--MID(TEXT(D21,"000000000.00"),6,1)=0)," Hundred"," Hundred "))&CHOOSE(MID(TEXT(D21,"000000000.00"),5,1)+1,,," Twenty"," Thirty"," Forty"," Fifty"," Sixty"," Seventy"," Eighty"," Ninety")&IF(--MID(TEXT(D21,"000000000.00"),5,1)<>1,CHOOSE(MID(TEXT(D21,"000000000.00"),6,1)+1,," One"," Two"," Three"," Four"," Five"," Six"," Seven"," Eight"," Nine"),CHOOSE(MID(TEXT(D21,"000000000.00"),6,1)+1," Ten"," Eleven"," Twelve"," Thirteen"," Fourteen"," Fifteen"," Sixteen"," Seventeen"," Eighteen"," Nineteen"))&IF((--MID(TEXT(D21,"000000000.00"),4,1)+MID(TEXT(D21,"000000000.00"),5,1)+MID(TEXT(D21,"000000000.00"),6,1))=0,,IF(OR((--MID(TEXT(D21,"000000000.00"),7,1)+MID(TEXT(D21,"000000000.00"),8,1)+MID(TEXT(D21,"000000000.00"),9,1))=0,--MID(TEXT(D21,"000000000.00"),7,1)<>0)," Thousand "," Thousand "))&CHOOSE(MID(TEXT(D21,"000000000.00"),7,1)+1,,"One","Two","Three","Four","Five","Six","Seven","Eight","Nine")&IF(--MID(TEXT(D21,"000000000.00"),7,1)=0,,IF(AND(--MID(TEXT(D21,"000000000.00"),8,1)=0,--MID(TEXT(D21,"000000000.00"),9,1)=0)," Hundred "," Hundred "))&CHOOSE(MID(TEXT(D21,"000000000.00"),8,1)+1,,,"Twenty ","Thirty ","Forty ","Fifty ","Sixty ","Seventy ","Eighty ","Ninety ")&IF(--MID(TEXT(D21,"000000000.00"),8,1)<>1,CHOOSE(MID(TEXT(D21,"000000000.00"),9,1)+1,,"One","Two","Three","Four","Five","Six","Seven","Eight","Nine"),CHOOSE(MID(TEXT(D21,"000000000.00"),9,1)+1,"Ten","Eleven","Twelve","Thirteen","Fourteen","Fifteen","Sixteen","Seventeen","Eighteen","Nineteen"))&" Pesos & "&RIGHT(TEXT(D21,"000000000.00"),2)&"/100 only") -> #REF!
A33: APPROVED:
A37: Engr. MARK CLOYD G. SO | E37: ='[1]TIMEBOOK (1-15)-D&6'!X49 -> VILMA M. MANLANGIT
A38: Acting Manager, Albay-Cat IMO | E38: ='[1]TIMEBOOK (1-15)-D&6'!X50 -> SCDO
A41: 2) I HEREBY CERTIFY that this Voucher | E41: 4) To be accomplished when payment
A42: has been pre-audited and this same may be | E42: of labor payrolls was made without pre-
A43: paid in the amount of | E43: audit. Passed in post audit in the amount of
A44: =PROPER(CHOOSE(LEFT(TEXT(D21,"000000000.00"))+1,,"One","Two","Three","Four","Five","Six","Seven","Eight","Nine")&IF(--LEFT(TEXT(D21,"000000000.00"))=0,,IF(AND(--MID(TEXT(D21,"000000000.00"),2,1)=0,--MID(TEXT(D21,"000000000.00"),3,1)=0)," Hundred"," Hundred "))&CHOOSE(MID(TEXT(D21,"000000000.00"),2,1)+1,,,"Twenty ","Thirty ","Forty ","Fifty ","Sixty ","Seventy ","Eighty ","Ninety ")&IF(--MID(TEXT(D21,"000000000.00"),2,1)<>1,CHOOSE(MID(TEXT(D21,"000000000.00"),3,1)+1,,"One","Two","Three","Four","Five","Six","Seven","Eight","Nine"),CHOOSE(MID(TEXT(D21,"000000000.00"),3,1)+1,"Ten","Eleven","Twelve","Thirteen","Fourteen","Fifteen","Sixteen","Seventeen","Eighteen","Nineteen"))&IF((--LEFT(TEXT(D21,"000000000.00"))+MID(TEXT(D21,"000000000.00"),2,1)+MID(TEXT(D21,"000000000.00"),3,1))=0,,IF(AND((--MID(TEXT(D21,"000000000.00"),4,1)+MID(TEXT(D21,"000000000.00"),5,1)+MID(TEXT(D21,"000000000.00"),6,1)+MID(TEXT(D21,"000000000.00"),7,1))=0,(--MID(TEXT(D21,"000000000.00"),8,1)+RIGHT(TEXT(D21,"000000000.00")))>0)," Million"," Million "))&CHOOSE(MID(TEXT(D21,"000000000.00"),4,1)+1,,"One","Two","Three","Four","Five","Six","Seven","Eight","Nine")&IF(--MID(TEXT(D21,"000000000.00"),4,1)=0,,IF(AND(--MID(TEXT(D21,"000000000.00"),5,1)=0,--MID(TEXT(D21,"000000000.00"),6,1)=0)," Hundred"," Hundred "))&CHOOSE(MID(TEXT(D21,"000000000.00"),5,1)+1,,," Twenty"," Thirty"," Forty"," Fifty"," Sixty"," Seventy"," Eighty"," Ninety")&IF(--MID(TEXT(D21,"000000000.00"),5,1)<>1,CHOOSE(MID(TEXT(D21,"000000000.00"),6,1)+1,," One"," Two"," Three"," Four"," Five"," Six"," Seven"," Eight"," Nine"),CHOOSE(MID(TEXT(D21,"000000000.00"),6,1)+1," Ten"," Eleven"," Twelve"," Thirteen"," Fourteen"," Fifteen"," Sixteen"," Seventeen"," Eighteen"," Nineteen"))&IF((--MID(TEXT(D21,"000000000.00"),4,1)+MID(TEXT(D21,"000000000.00"),5,1)+MID(TEXT(D21,"000000000.00"),6,1))=0,,IF(OR((--MID(TEXT(D21,"000000000.00"),7,1)+MID(TEXT(D21,"000000000.00"),8,1)+MID(TEXT(D21,"000000000.00"),9,1))=0,--MID(TEXT(D21,"000000000.00"),7,1)<>0)," Thousand "," Thousand "))&CHOOSE(MID(TEXT(D21,"000000000.00"),7,1)+1,,"One","Two","Three","Four","Five","Six","Seven","Eight","Nine")&IF(--MID(TEXT(D21,"000000000.00"),7,1)=0,,IF(AND(--MID(TEXT(D21,"000000000.00"),8,1)=0,--MID(TEXT(D21,"000000000.00"),9,1)=0)," Hundred "," Hundred "))&CHOOSE(MID(TEXT(D21,"000000000.00"),8,1)+1,,,"Twenty ","Thirty ","Forty ","Fifty ","Sixty ","Seventy ","Eighty ","Ninety ")&IF(--MID(TEXT(D21,"000000000.00"),8,1)<>1,CHOOSE(MID(TEXT(D21,"000000000.00"),9,1)+1,,"One","Two","Three","Four","Five","Six","Seven","Eight","Nine"),CHOOSE(MID(TEXT(D21,"000000000.00"),9,1)+1,"Ten","Eleven","Twelve","Thirteen","Fourteen","Fifteen","Sixteen","Seventeen","Eighteen","Nineteen"))&" Pesos & "&RIGHT(TEXT(D21,"000000000.00"),2)&"/100 only") -> #REF! | E44: ________________________________.
E45: Entry was made in cash book for this
E46: amount.
A49: VIDA E. PITALLANO, CPA
A50: Sr. Accounting Processor A

Sheet BURS (2)
K2: Serial No. ____________________
K3: Date : ________________________
K4: Fund : _______________________
A5: BUDGET UTILIZATION REQUEST AND STATUS
A7: Payee | D7: MA. ELAINE E. ARCILLA
A9: Office
A11: Address | D11: Virac, Catanduanes
A13: Responsibility Center | D13: Particulars | I13: Project | K13: Account Code/ Expenditures | L13: Amount
D15: Wages for the period July 1-15, 2025. | L15: =#REF! -> #REF!
D24: Total | L24: =L15 -> #REF!
A25: A. | I25: B.
B26: Certified: | D26: Charges to appropriation/budget necessary, | J26: Certified: Budget available and utilized for
B27: lawful and under my direct supervision; and supporting | J27: the purpose/adjustment necessary as
B28: documents valid, proper and legal | J28: indicated above
A32: Signature : | C32: ____________________________________ | I32: Signature : | K32: ______________________________
A34: Printed Name: | C34: ____ENGR. ANGELO V. MARQUEZ______ | I34: Printed Name: | K34: ____VIDA E. PITALLANO, CPA_____
A36: Position : | C36: ___Acting Head, NIA Catanduanes Sub-Office_____ | I36: Position : | K36: ____Corporate Accounts Analyst_____
C37: Head, Requesting Office/Authorized Representative | K37: Head, Budget Division/Unit/Authorized Representative
A38: Date : | C38: _______________________________ | I38: Date : | K38: ____________________________
A41: C. | B41: STATUS OF UTILIZATION
A42: Reference | H42: Amount
A43: Date | B43: Particulars | E43: BURS/JEV/RCI No. | H43: Utilization | I43: Payable | K43: Payment | L43: Balance
L44: Utilization | M44: Payable
H45: (a) | I45: (b) | K45: (c) | L45: (a-b) | M45: (b-c)
B46: =D15 -> Wages for the period July 1-15, 2025. | H46: =L15 -> #REF!
A53: NIA-ACIMO-FIN-INT-Form06 Rev07

Sheet DISBURSEMENT VOUCHER (2)
A5: DISBURSEMENT VOUCHER | AB5: Fund :
AB6: Date :
AB7: DV No. :
A8: Mode of Payment
H9: MDS Check | M9: LCCA | T9: ADA | X9: Others (Please specify)
AA10: _________________
A11: Payee | E11: MA. ELAINE E. ARCILLA | S11: TIN/Employee No.: | AB11: ORS/BURS No.:
A13: Address | E13: Virac, Catanduanes
A15: Particulars | R15: Responsibility Center | W15: MFO/PAP | AB15: Amount
A16: To Cash Advance for the wages for the period July 1-15, 2025. | AB16: =Q22 -> 4585.39
Q18: AMOUNT
C19: 1 | E19: MA. ELAINE E. ARCILLA | Q19: 4933.39
H20: BIR 3% | N20: 148
H21: HDMF | N21: 200 | Q21: =SUM(N20:P21) -> 348
J22: TOTAL | Q22: =Q19-Q21 -> 4585.39
A24: Amount Due | AB24: =+AB16 -> 4585.39
A25: A. | B25: Certified: Expenses/Cash Advance necessary, lawful and incurred under my direct supervision.
B27: ____ENGR. ANGELO V. MARQUEZ_____
B28: Acting Head, NIA Catanduanes Sub-Office
A31: B. | B31: Accounting Entry:
A32: Account Title | S32: UACS Code | X32: Debit | AC32: Credit
A46: C. | B46: Certified: | S46: D. Approved for Payment | T46: Approved for Payment
C47: Cash available | S47: =UPPER(CHOOSE(LEFT(TEXT(AB24,"000000000.00"))+1,,"One","Two","Three","Four","Five","Six","Seven","Eight","Nine")&IF(--LEFT(TEXT(AB24,"000000000.00"))=0,,IF(AND(--MID(TEXT(AB24,"000000000.00"),2,1)=0,--MID(TEXT(AB24,"000000000.00"),3,1)=0)," Hundred"," Hundred "))&CHOOSE(MID(TEXT(AB24,"000000000.00"),2,1)+1,,,"Twenty ","Thirty ","Forty ","Fifty ","Sixty ","Seventy ","Eighty ","Ninety ")&IF(--MID(TEXT(AB24,"000000000.00"),2,1)<>1,CHOOSE(MID(TEXT(AB24,"000000000.00"),3,1)+1,,"One","Two","Three","Four","Five","Six","Seven","Eight","Nine"),CHOOSE(MID(TEXT(AB24,"000000000.00"),3,1)+1,"Ten","Eleven","Twelve","Thirteen","Fourteen","Fifteen","Sixteen","Seventeen","Eighteen","Nineteen"))&IF((--LEFT(TEXT(AB24,"000000000.00"))+MID(TEXT(AB24,"000000000.00"),2,1)+MID(TEXT(AB24,"000000000.00"),3,1))=0,,IF(AND((--MID(TEXT(AB24,"000000000.00"),4,1)+MID(TEXT(AB24,"000000000.00"),5,1)+MID(TEXT(AB24,"000000000.00"),6,1)+MID(TEXT(AB24,"000000000.00"),7,1))=0,(--MID(TEXT(AB24,"000000000.00"),8,1)+RIGHT(TEXT(AB24,"000000000.00")))>0)," Million"," Million "))&CHOOSE(MID(TEXT(AB24,"000000000.00"),4,1)+1,,"One","Two","Three","Four","Five","Six","Seven","Eight","Nine")&IF(--MID(TEXT(AB24,"000000000.00"),4,1)=0,,IF(AND(--MID(TEXT(AB24,"000000000.00"),5,1)=0,--MID(TEXT(AB24,"000000000.00"),6,1)=0)," Hundred"," Hundred "))&CHOOSE(MID(TEXT(AB24,"000000000.00"),5,1)+1,,," Twenty"," Thirty"," Forty"," Fifty"," Sixty"," Seventy"," Eighty"," Ninety")&IF(--MID(TEXT(AB24,"000000000.00"),5,1)<>1,CHOOSE(MID(TEXT(AB24,"000000000.00"),6,1)+1,," One"," Two"," Three"," Four"," Five"," Six"," Seven"," Eight"," Nine"),CHOOSE(MID(TEXT(AB24,"000000000.00"),6,1)+1," Ten"," Eleven"," Twelve"," Thirteen"," Fourteen"," Fifteen"," Sixteen"," Seventeen"," Eighteen"," Nineteen"))&IF((--MID(TEXT(AB24,"000000000.00"),4,1)+MID(TEXT(AB24,"000000000.00"),5,1)+MID(TEXT(AB24,"000000000.00"),6,1))=0,,IF(OR((--MID(TEXT(AB24,"000000000.00"),7,1)+MID(TEXT(AB24,"000000000.00"),8,1)+MID(TEXT(AB24,"000000000.00"),9,1))=0,--MID(TEXT(AB24,"000000000.00"),7,1)<>0)," Thousand "," Thousand "))&CHOOSE(MID(TEXT(AB24,"000000000.00"),7,1)+1,,"One","Two","Three","Four","Five","Six","Seven","Eight","Nine")&IF(--MID(TEXT(AB24,"000000000.00"),7,1)=0,,IF(AND(--MID(TEXT(AB24,"000000000.00"),8,1)=0,--MID(TEXT(AB24,"000000000.00"),9,1)=0)," Hundred "," Hundred "))&CHOOSE(MID(TEXT(AB24,"000000000.00"),8,1)+1,,,"Twenty ","Thirty ","Forty ","Fifty ","Sixty ","Seventy ","Eighty ","Ninety ")&IF(--MID(TEXT(AB24,"000000000.00"),8,1)<>1,CHOOSE(MID(TEXT(AB24,"000000000.00"),9,1)+1,,"One","Two","Three","Four","Five","Six","Seven","Eight","Nine"),CHOOSE(MID(TEXT(AB24,"000000000.00"),9,1)+1,"Ten","Eleven","Twelve","Thirteen","Fourteen","Fifteen","Sixteen","Seventeen","Eighteen","Nineteen"))&" Pesos & "&RIGHT(TEXT(AB24,"000000000.00"),2)&"/100 only") -> FOUR THOUSAND FIVE HUNDRED EIGHTY FIVE PESOS & 39/100 ONLY
C49: Subject to Authority to Debit Account (when applicable)
C51: Supporting documents complete and amount claimed | D51: Supporting documents complete and amount claimed
C52: proper
A54: Signature | S54: Signature
A56: Printed Name | E56: VIDA E. PITALLANO, CPA | S56: Printed Name | W56: ENGR. MARK CLOYD G. SO
A58: Position | E58: Corporate Accounts Analyst | S58: Position | W58: Acting Division Manager
E59: Head, Accounting Unit/Authorized Representative | W59: Agency Head/Authorized Representative
A60: Date | S60: Date
A62: E. | B62: Receipt of Payment | AB62: JEV No.
A63: Check/ ADA No. : | N63: Date : | S63: Bank Name & Account Number:
A65: Signature : | N65: Date : | S65: Printed Name: | AB65: Date
S66: =E11 -> MA. ELAINE E. ARCILLA
A67: Official Receipt No. & Date/Other Documents
A68: NIA-ACIMO-FIN-INT-Form13 Rev07

Sheet BUR - Gross-D&6
B3: NATIONAL IRRIGATION ADMINISTRATION | K3: Serial No. : ___________________
A4: ALBAY-CATANDUANES IMO, LIGAO CITY | K4: Date : _______________________
B5: BUDGET UTILIZATION REQUEST AND STATUS | K5: Fund : _______________________
A7: Payee | D7: ='SUMMARY (1-15)-D&6'!C3 -> D.Z. MANLANGIT & 6
A9: Office | D9: Albay-Catanduanes Irrigation Management Office
A11: Address | D11: Virac, Catanduanes
A13: Responsibility Center | D13: Particulars | I13: Project | K13: Account Code/ Expenditures | L13: Amount
L16: ='SUMMARY (1-15)-D&6'!C21 -> #REF!
D17: WAGES - | F17: ='SUMMARY (1-15)-D&6'!C5 -> #REF!
D24: TOTAL | L24: =L16 -> #REF!
A25: A. | I25: B.
B26: Certified: | D26: Charges to appropriation/budget necessary, | J26: Certified: Budget available and utilized for the
B27: lawful and under my direct supervision; and supporting | J27: purpose/adjustment necessary as indicated above
B28: documents valid, proper and legal
A32: Signature: | I32: Signature:
A33: Printed Name: | C33: =#REF! -> #REF! | I33: Printed Name: | K33: VIDA E. PITALLANO, CPA
A34: Position: | C34: =#REF! -> #REF! | I34: Position: | K34: Sr. Accounting Processor A
C35: Head, Requesting Office/Authorized Representative | K35: Head, Budget Division/Unit/Authorized Representative
A36: Date: | I36: Date:
A38: C. | B38: STATUS OF UTILIZATION
A39: Reference | H39: Amount
A40: Date | B40: Particulars | E40: BURS/ JEV/RCI No. | H40: Utilization | I40: Payable | K40: Payment | L40: Balance
L41: Utilization | M41: Payable
H42: (a) | I42: (b) | K42: (c) | L42: (a-b) | M42: (b-c)
B43: =D17 -> WAGES - | H43: =L24 -> #REF!
B44: =F17 -> #REF!

Sheet DV - BIR-D&6
A2: NATIONAL IRRIGATION ADMINISTRATION | AC2: Fund :
A3: ALBAY-CATANDUANES IMO, LIGAO CITY
A4: DISBURSEMENT VOUCHER | AC4: Date :
AC5: DV No. :
A7: Mode of Payment
H8: MDS Check | N8: LCCA | U8: ADA | Y8: Others (Please specify)
AB9: _________________
A10: Payee | E10: BIR | T10: TIN/Employee No.: | AC10: ORS/BURS No.:
A12: Address
A14: Particulars | S14: Responsibility Center | X14: MFO/PAP | AC14: Amount
A17: REMITTANCE OF WITHHOLDING TAX FOR THE MONTH OF JULY 2024 IN THE AMOUNT OF.. | AC17: =K28 -> #REF!
K20: Amount
C21: 1 | D21: =#REF! -> #REF! | K21: =#REF! -> #REF!
C22: 2 | D22: =#REF! -> #REF! | K22: =#REF! -> #REF!
C23: 3 | D23: =#REF! -> #REF! | K23: =#REF! -> #REF!
C24: 4 | D24: =#REF! -> #REF! | K24: =#REF! -> #REF!
C25: 5 | D25: =#REF! -> #REF! | K25: =#REF! -> #REF!
C26: 6 | D26: =#REF! -> #REF! | K26: =#REF! -> #REF!
C27: 7 | D27: =#REF! -> #REF! | K27: =#REF! -> #REF!
C28: T O T A L | K28: =#REF! -> #REF!
A31: Amount Due | AC31: =AC17 -> #REF!
A32: A. | C32: Certified: Expenses/Cash Advance necessary, lawful and incurred under my direct supervision.
C35: ='BUR - Gross-D&6'!C33:H33 -> #REF!
C36: ='BUR - Gross-D&6'!C34:H34 -> #REF!
C37: Printed Name, Designation and Signature of Supervisor
A39: B. | C39: Accounting Entry:
A40: Account Title | T40: UACS Code | Y40: Debit | AD40: Credit
A52: C. | C52: Certified: | T52: D. | U52: Approved for Payment
D53: Cash available | T53: =UPPER(CHOOSE(LEFT(TEXT(AC31,"000000000.00"))+1,,"One","Two","Three","Four","Five","Six","Seven","Eight","Nine")&IF(--LEFT(TEXT(AC31,"000000000.00"))=0,,IF(AND(--MID(TEXT(AC31,"000000000.00"),2,1)=0,--MID(TEXT(AC31,"000000000.00"),3,1)=0)," Hundred"," Hundred "))&CHOOSE(MID(TEXT(AC31,"000000000.00"),2,1)+1,,,"Twenty ","Thirty ","Forty ","Fifty ","Sixty ","Seventy ","Eighty ","Ninety ")&IF(--MID(TEXT(AC31,"000000000.00"),2,1)<>1,CHOOSE(MID(TEXT(AC31,"000000000.00"),3,1)+1,,"One","Two","Three","Four","Five","Six","Seven","Eight","Nine"),CHOOSE(MID(TEXT(AC31,"000000000.00"),3,1)+1,"Ten","Eleven","Twelve","Thirteen","Fourteen","Fifteen","Sixteen","Seventeen","Eighteen","Nineteen"))&IF((--LEFT(TEXT(AC31,"000000000.00"))+MID(TEXT(AC31,"000000000.00"),2,1)+MID(TEXT(AC31,"000000000.00"),3,1))=0,,IF(AND((--MID(TEXT(AC31,"000000000.00"),4,1)+MID(TEXT(AC31,"000000000.00"),5,1)+MID(TEXT(AC31,"000000000.00"),6,1)+MID(TEXT(AC31,"000000000.00"),7,1))=0,(--MID(TEXT(AC31,"000000000.00"),8,1)+RIGHT(TEXT(AC31,"000000000.00")))>0)," Million"," Million "))&CHOOSE(MID(TEXT(AC31,"000000000.00"),4,1)+1,,"One","Two","Three","Four","Five","Six","Seven","Eight","Nine")&IF(--MID(TEXT(AC31,"000000000.00"),4,1)=0,,IF(AND(--MID(TEXT(AC31,"000000000.00"),5,1)=0,--MID(TEXT(AC31,"000000000.00"),6,1)=0)," Hundred"," Hundred "))&CHOOSE(MID(TEXT(AC31,"000000000.00"),5,1)+1,,," Twenty"," Thirty"," Forty"," Fifty"," Sixty"," Seventy"," Eighty"," Ninety")&IF(--MID(TEXT(AC31,"000000000.00"),5,1)<>1,CHOOSE(MID(TEXT(AC31,"000000000.00"),6,1)+1,," One"," Two"," Three"," Four"," Five"," Six"," Seven"," Eight"," Nine"),CHOOSE(MID(TEXT(AC31,"000000000.00"),6,1)+1," Ten"," Eleven"," Twelve"," Thirteen"," Fourteen"," Fifteen"," Sixteen"," Seventeen"," Eighteen"," Nineteen"))&IF((--MID(TEXT(AC31,"000000000.00"),4,1)+MID(TEXT(AC31,"000000000.00"),5,1)+MID(TEXT(AC31,"000000000.00"),6,1))=0,,IF(OR((--MID(TEXT(AC31,"000000000.00"),7,1)+MID(TEXT(AC31,"000000000.00"),8,1)+MID(TEXT(AC31,"000000000.00"),9,1))=0,--MID(TEXT(AC31,"000000000.00"),7,1)<>0)," Thousand "," Thousand "))&CHOOSE(MID(TEXT(AC31,"000000000.00"),7,1)+1,,"One","Two","Three","Four","Five","Six","Seven","Eight","Nine")&IF(--MID(TEXT(AC31,"000000000.00"),7,1)=0,,IF(AND(--MID(TEXT(AC31,"000000000.00"),8,1)=0,--MID(TEXT(AC31,"000000000.00"),9,1)=0)," Hundred "," Hundred "))&CHOOSE(MID(TEXT(AC31,"000000000.00"),8,1)+1,,,"Twenty ","Thirty ","Forty ","Fifty ","Sixty ","Seventy ","Eighty ","Ninety ")&IF(--MID(TEXT(AC31,"000000000.00"),8,1)<>1,CHOOSE(MID(TEXT(AC31,"000000000.00"),9,1)+1,,"One","Two","Three","Four","Five","Six","Seven","Eight","Nine"),CHOOSE(MID(TEXT(AC31,"000000000.00"),9,1)+1,"Ten","Eleven","Twelve","Thirteen","Fourteen","Fifteen","Sixteen","Seventeen","Eighteen","Nineteen"))&" Pesos & "&RIGHT(TEXT(AC31,"000000000.00"),2)&"/100 only") -> #REF!
D55: Subject to Authority to Debit Account (when applicable)
D57: Supporting documents complete and amount claimed
D58: proper
A60: Signature | T60: Signature
A62: Printed Name | E62: ='BUR - Gross-D&6'!K33:K33 -> VIDA E. PITALLANO, CPA | T62: Printed Name | X62: ='SUMMARY (1-15)-D&6'!A37 -> Engr. MARK CLOYD G. SO
A64: Position | E64: ='BUR - Gross-D&6'!K34:K34 -> Sr. Accounting Processor A | T64: Position | X64: ='SUMMARY (1-15)-D&6'!A38 -> Acting Manager, Albay-Cat IMO
E65: Head, Accounting Unit/Authorized Representative | X65: Agency Head/Authorized Representative
A66: Date | T66: Date
A68: E. | C68: Receipt of Payment | AC68: JEV No.
A69: Check/ ADA No. : | L69: Date : | T69: Bank Name & Account Number:
A71: Signature : | L71: Date : | T71: Printed Name: | AC71: Date
...

Sheet  Jan 16-31, 2025 (jlb-dzm)
B1: REPUBLIC OF THE PHILIPPINES
B2: OFFICE OF THE PRESIDENT
B3: National Irrigation Administration
B4: ALBAY-CATANDUANES IRRIGATION MANAGEMENT OFFICE
B5: Virac, Catanduanes
A7: T I M E B O O K
AB8: AFD - JOB ORDER
B10: For Labor on | C10: LFP | AA10: For the period: | AB10: JANUARY 1-15, 2025
C11: (State Project which was performed)
AE12: NO. OF MINUTES
B13: N A M E | C13: DESIGNATION | D13: T I M E R O L L | T13: No. of days worked | U13: Rate per Day | V13: GROSS AMOUNT | W13: OVERTIME | X13: TOTAL | Y13: BIR | Z13: HDMF | AA13: TOTAL DEDUCTIONS | AB13: NET | AC13: LBP | AE13: OVERTIME
D14: 16 | E14: 17 | F14: 18 | G14: 19 | H14: 20 | I14: 21 | J14: 22 | K14: 23 | L14: 24 | M14: 25 | N14: 26 | O14: 27 | P14: 28 | Q14: 29 | R14: 30 | S14: 31 | X14: EARNINGS FOR | Y14: SSS | Z14: HDMF-MPL | AB14: AMOUNT | AC14: ATM NUMBER
W15: UNDERTIME | X15: THE PERIOD | Y15: NIAMPCO-ML | AB15: DUE | AE15: UNDERTIME
A16: 1 | B16: MANLANGIT, DINDO Z. | C16: Irrigator's Development Officer A | D16: X | E16: X | F16: S | G16: S | H16: X | I16: X | J16: X | K16: X | L16: X | M16: S | N16: S | O16: X | P16: X | Q16: H | R16: X | S16: X | T16: =COUNTIF(D16:S16,"X")+(COUNTIF(D16:S16,"/")/2)+COUNTIF(D16:S16,"OB")+COUNTIF(D16:S16,"SPH") -> 11 | U16: 1087.63 | V16: =T16*U16 -> 11963.93 | W16: =ROUND((ROUND((U16/8/60),2)*AE16),2) -> 0 | X16: =V16+W16-W18 -> 11961.664 | Y16: =X16*0.03 -> 358.84992 | AA16: =Y16+Y17+Y18+Z16+Z17+Z18 -> 358.84992 | AB16: 8200.44 | AE16: 0
W18: =U16/8/60*AE18 -> 2.2658958 | Y18: 0 | Z18: 0 | AE18: 1
A19: 2 | B19: MELGAR, FREDERICK T. | C19: Irrigator's Development Officer A | D19: X | E19: X | F19: S | G19: S | H19: X | I19: A | J19: A | K19: A | L19: X | M19: S | N19: S | O19: X | P19: X | Q19: H | R19: X | S19: X | T19: =COUNTIF(D19:S19,"X")+(COUNTIF(D19:S19,"/")/2)+COUNTIF(D19:S19,"OB")+COUNTIF(D19:S19,"SPH") -> 8 | U19: 1087.63 | V19: =T19*U19 -> 8701.04 | W19: 0 | X19: =V19+W19-W21 -> 8551.4909 | Y19: =X19*0.03 -> 256.54473 | AA19: =Y19+Y20+Y21+Z19+Z20+Z21 -> 826.54473 | AB19: 6257.48 | AC19: 0897067080 | AE19: 0
Y20: 570
W21: =U19/8/60*AE21 -> 149.54913 | AE21: 66
A22: 3 | B22: BEO, EDILBERTO R. | C22: Research Assistant B | D22: X | E22: X | F22: S | G22: S | H22: X | I22: X | J22: X | K22: X | L22: X | M22: S | N22: S | O22: X | P22: X | Q22: H | R22: X | S22: X | T22: =COUNTIF(D22:S22,"X")+(COUNTIF(D22:S22,"/")/2)+COUNTIF(D22:S22,"OB")+COUNTIF(D22:S22,"SPH") -> 11 | U22: 814.41 | V22: =T22*U22 -> 8958.51 | W22: 0 | X22: =V22+W22-W24 -> 8926.2729 | Y22: =X22*0.03 -> 267.78819 | AA22: =Y22+Y23+Y24+Z22+Z23+Z24 -> 267.78819 | AB22: =X22-AA22 -> 8658.4847 | AC22: 0897091518
W24: =U22/8/60*AE24 -> 32.237063 | Y24: 0 | Z24: 0 | AE24: 19
A25: 4 | B25: BEO. JOMER L. | C25: Engineering Assistant B | D25: X | E25: X | F25: S | G25: S | H25: X | I25: X | J25: X | K25: X | L25: X | M25: S | N25: S | O25: X | P25: X | Q25: H | R25: X | S25: X | T25: =COUNTIF(D25:S25,"X")+(COUNTIF(D25:S25,"/")/2)+COUNTIF(D25:S25,"OB")+COUNTIF(D25:S25,"SPH") -> 11 | U25: 814.41 | V25: =T25*U25 -> 8958.51 | W25: 0 | X25: =V25+W25-W27 -> 8902.5193 | Y25: =X25*0.03 -> 267.07558 | AA25: =Y25+Y26+Y27+Z25+Z26+Z27 -> 837.07558 | AB25: =X25-AA25 -> 8065.4437 | AC25: 2767052807
Y26: 570
W27: =U25/8/60*AE27 -> 55.990687 | Z27: 0 | AE27: 33
A28: 5 | B28: LUMBAO, JOSHUA A. | C28: Engineering Assistant B | D28: X | E28: X | F28: S | G28: S | H28: X | I28: X | J28: X | K28: X | L28: X | M28: S | N28: S | O28: X | P28: X | Q28: H | R28: X | S28: X | T28: =COUNTIF(D28:S28,"X")+(COUNTIF(D28:S28,"/")/2)+COUNTIF(D28:S28,"OB")+COUNTIF(D28:S28,"SPH") -> 11 | U28: 814.41 | V28: =T28*U28 -> 8958.51 | W28: 0 | X28: =V28+W28-W30 -> 8927.9696 | Y28: =X28*0.03 -> 267.83909 | AA28: =Y28+Y29+Y30+Z28+Z29+Z30 -> 267.83909 | AB28: =X28-AA28 -> 8660.1305 | AC28: 0897084236 | AE28: 0
W30: =U28/8/60*AE30 -> 30.540375 | Z30: 0 | AE30: 18
A31: 6 | B31: TAPIA, KAYCEELYN M. | C31: Engineering Assistant B | D31: X | E31: X | F31: S | G31: S | H31: X | I31: X | J31: X | K31: X | L31: X | M31: S | N31: S | O31: X | P31: X | Q31: H | R31: X | S31: X | T31: =COUNTIF(D31:S31,"X")+(COUNTIF(D31:S31,"/")/2)+COUNTIF(D31:S31,"OB")+COUNTIF(D31:S31,"SPH") -> 11 | U31: 814.41 | V31: =T31*U31 -> 8958.51 | W31: 0 | X31: =V31+W31-W33 -> 8958.51 | Y31: =X31*0.03 -> 268.7553 | AA31: =Y31+Y32+Y33+Z31+Z32+Z33 -> 268.7553 | AB31: =X31-AA31 -> 8689.7547 | AC31: 0897084228 | AE31: 0
W33: =U31/8/60*AE33 -> 0 | Y33: 0 | Z33: 0
A34: 7 | B34: TORIO, JOMEL M. | C34: Administrative Services Assistant B | D34: X | E34: X | F34: S | G34: S | H34: X | I34: X | J34: X | K34: X | L34: X | M34: X | N34: S | O34: X | P34: X | Q34: H | R34: X | S34: X | T34: =COUNTIF(D34:S34,"X")+(COUNTIF(D34:S34,"/")/2)+COUNTIF(D34:S34,"OB")+COUNTIF(D34:S34,"SPH") -> 12 | U34: 941.17 | V34: =T34*U34 -> 11294.04 | W34: 0 | X34: =V34+W34-W36 -> 11294.04 | Y34: =X34*0.03 -> 338.8212 | AA34: =Y34+Y35+Y36+Z34+Z35+Z36 -> 908.8212 | AB34: =X34-AA34 -> 10385.219 | AC34: 0897060523 | AE34: 0
Y35: 570
W36: =U34/8/60*AE36 -> 0 | Y36: 0 | Z36: 0 | AE36: 0
A37: 8 | B37: BRIOSO, JOHN LEARRY A. | C37: Utility Worker A | D37: X | E37: X | F37: X | G37: S | H37: X | I37: X | J37: X | K37: X | L37: X | M37: X | N37: X | O37: X | P37: X | Q37: X | R37: X | S37: X | T37: =COUNTIF(D37:S37,"X")+(COUNTIF(D37:S37,"/")/2)+COUNTIF(D37:S37,"OB")+COUNTIF(D37:S37,"SPH") -> 15 | U37: 567.32 | V37: =T37*U37 -> 8509.8 | W37: 0 | X37: =V37+W37-W39 -> 8509.8 | Y37: =X37*0.03 -> 255.294 | AA37: =Y37+Y38+Y39+Z37+Z38+Z39 -> 255.294 | AB37: 4752.7 | AC37: 0897059835
W39: =U37/8/60*AE39 -> 0 | Y39: 0 | Z39: 0
B40: Item 1 - Utilized in various institutional works in Catanduanes; Item 2-Utilized in various institutional works in Catanduanes; Item 3 - Utilized in various institutional works in Catanduanes - Item 4 Utilized in gathering date and other survey related reports in Albay and Catandunaes projects; Item 5- Utilized in the monitoring, supervision, of LMC Works/FAW and preparation of related works; Item 6- Utilized in the survey works, monitoring, supervision, of LMC/FAW Works; Item 7 -Utilized in clerical and admin-related works in Catandunaes Sub-Office; Item 8 - Utilize in the janitorial and other office maintenance works and as a watchman/To assist in the monitoring and inspection of projects under FAW/LMC works.
Y41: =Y16+Y19+Y22+Y25+Y28+Y31+Y34+Y37 -> 2280.968 | Z41: =Z16+Z19+Z22+Z25+Z28+Z31+Z34+Z37 -> 0
W43: =W18+W21+W24+W27+W30+W33+W39 -> 270.58315
A45: T O T A L S | V45: 54876.83 | W45: =ROUND(SUM(W41:W43),2) -> 270.58 | X45: 52639.49 | Y45: 1579.19 | Z45: =Z41 -> 0 | AA45: =ROUND((Y45+Z45),2) -> 1579.19 | AB45: 49460.3
B48: 1) I HEREBY CERTIFY that each person whose name appears on this roll rendered services as indicated and for the time stated. | J48: 2) I CERTIFY that this roll is correct, every person whose name appears hereon rendered services for the time and at the rates stated under my general supervision, and I approved payment of this roll. | X48: 3) I CERTIFY on my official that I have this ____ day of _____________, 2024 paid in cash to each person whose name appears having presented him self established his/her identity and affix his/her signature or thumbmark on the space provided.
B52: MARK ANJO T. ALNAS | J52: ANGELO V. MARQUEZ | X52: VILMA M. MANLANGIT
B53: Engineering A | J53: Acting Head, NIA Catanduanes Sub-Office | X53: SCDO

Sheet SUMMARY (1-15)-D&6
A1: S U M M A R Y O F P A Y R O L L
C3: D.Z. MANLANGIT & 6
A4: Bureau/Province/Municipal | C4: NIA, ALBAY-CATANDUANES IMO,
A5: For the Period | C5: =#REF! -> #REF!
A6: P R O J E C T
A8: S h e e t | B8: N u m b e r | C8: A m o u n t | D8: Amount Paid | E8: T r a n s f e r r e d T o
A9: N o . | B9: o f R o l l s | C9: o f R o l l s | D9: o f R o l l s
A10: 1 | C10: =#REF! -> #REF! | D10: =#REF! -> #REF! | E10: =#REF! -> #REF! | F10: =#REF! -> #REF!
E11: =#REF! -> #REF! | F11: =#REF! -> #REF!
E12: =#REF! -> #REF! | F12: =#REF! -> #REF!
E13: =#REF! -> #REF! | F13: =#REF! -> #REF!
E14: =#REF! -> #REF! | F14: =#REF! -> #REF!
E15: =#REF! -> #REF! | F15: =#REF! -> #REF!
C21: =C10 -> #REF! | D21: =SUM(D10:D20) -> #REF! | F21: =SUM(F10:F20) -> #REF!
A23: 1) I HEREBY CERTIFY that the attached | E23: 3) I HEREBY CERTIFY on my official
A24: payroll/s and summary of which appears here- | E24: oath that the payroll/s and summary of
A25: on is/are correct and just and that the ser- | E25: which appears hereon, are the best of my
A26: vices were rendered under my direction and | E26: knowledge and belief proper and correct
A27: I approved payment thereof this ___ day of | E27: the same being chargeable to the appro-
A28: ______________________________________. | E28: priation set aside. THEREOF, I FURTHER
E29: CERTIFY that the payment thereon have
E30: been made in the amount of | F30: =D21 -> #REF!
E31: =PROPER(CHOOSE(LEFT(TEXT(D21,"000000000.00"))+1,,"One","Two","Three","Four","Five","Six","Seven","Eight","Nine")&IF(--LEFT(TEXT(D21,"000000000.00"))=0,,IF(AND(--MID(TEXT(D21,"000000000.00"),2,1)=0,--MID(TEXT(D21,"000000000.00"),3,1)=0)," Hundred"," Hundred "))&CHOOSE(MID(TEXT(D21,"000000000.00"),2,1)+1,,,"Twenty ","Thirty ","Forty ","Fifty ","Sixty ","Seventy ","Eighty ","Ninety ")&IF(--MID(TEXT(D21,"000000000.00"),2,1)<>1,CHOOSE(MID(TEXT(D21,"000000000.00"),3,1)+1,,"One","Two","Three","Four","Five","Six","Seven","Eight","Nine"),CHOOSE(MID(TEXT(D21,"000000000.00"),3,1)+1,"Ten","Eleven","Twelve","Thirteen","Fourteen","Fifteen","Sixteen","Seventeen","Eighteen","Nineteen"))&IF((--LEFT(TEXT(D21,"000000000.00"))+MID(TEXT(D21,"000000000.00"),2,1)+MID(TEXT(D21,"000000000.00"),3,1))=0,,IF(AND((--MID(TEXT(D21,"000000000.00"),4,1)+MID(TEXT(D21,"000000000.00"),5,1)+MID(TEXT(D21,"000000000.00"),6,1)+MID(TEXT(D21,"000000000.00"),7,1))=0,(--MID(TEXT(D21,"000000000.00"),8,1)+RIGHT(TEXT(D21,"000000000.00")))>0)," Million"," Million "))&CHOOSE(MID(TEXT(D21,"000000000.00"),4,1)+1,,"One","Two","Three","Four","Five","Six","Seven","Eight","Nine")&IF(--MID(TEXT(D21,"000000000.00"),4,1)=0,,IF(AND(--MID(TEXT(D21,"000000000.00"),5,1)=0,--MID(TEXT(D21,"000000000.00"),6,1)=0)," Hundred"," Hundred "))&CHOOSE(MID(TEXT(D21,"000000000.00"),5,1)+1,,," Twenty"," Thirty"," Forty"," Fifty"," Sixty"," Seventy"," Eighty"," Ninety")&IF(--MID(TEXT(D21,"000000000.00"),5,1)<>1,CHOOSE(MID(TEXT(D21,"000000000.00"),6,1)+1,," One"," Two"," Three"," Four"," Five"," Six"," Seven"," Eight"," Nine"),CHOOSE(MID(TEXT(D21,"000000000.00"),6,1)+1," Ten"," Eleven"," Twelve"," Thirteen"," Fourteen"," Fifteen"," Sixteen"," Seventeen"," Eighteen"," Nineteen"))&IF((--MID(TEXT(D21,"000000000.00"),4,1)+MID(TEXT(D21,"000000000.00"),5,1)+MID(TEXT(D21,"000000000.00"),6,1))=0,,IF(OR((--MID(TEXT(D21,"000000000.00"),7,1)+MID(TEXT(D21,"000000000.00"),8,1)+MID(TEXT(D21,"000000000.00"),9,1))=0,--MID(TEXT(D21,"000000000.00"),7,1)<>0)," Thousand "," Thousand "))&CHOOSE(MID(TEXT(D21,"000000000.00"),7,1)+1,,"One","Two","Three","Four","Five","Six","Seven","Eight","Nine")&IF(--MID(TEXT(D21,"000000000.00"),7,1)=0,,IF(AND(--MID(TEXT(D21,"000000000.00"),8,1)=0,--MID(TEXT(D21,"000000000.00"),9,1)=0)," Hundred "," Hundred "))&CHOOSE(MID(TEXT(D21,"000000000.00"),8,1)+1,,,"Twenty ","Thirty ","Forty ","Fifty ","Sixty ","Seventy ","Eighty ","Ninety ")&IF(--MID(TEXT(D21,"000000000.00"),8,1)<>1,CHOOSE(MID(TEXT(D21,"000000000.00"),9,1)+1,,"One","Two","Three","Four","Five","Six","Seven","Eight","Nine"),CHOOSE(MID(TEXT(D21,"000000000.00"),9,1)+1,"Ten","Eleven","Twelve","Thirteen","Fourteen","Fifteen","Sixteen","Seventeen","Eighteen","Nineteen"))&" Pesos & "&RIGHT(TEXT(D21,"000000000.00"),2)&"/100 only") -> #REF!
A33: APPROVED:
A37: Engr. MARK CLOYD G. SO | E37: =#REF! -> #REF!
A38: Acting Manager, Albay-Cat IMO | E38: =#REF! -> #REF!
A41: 2) I HEREBY CERTIFY that this Voucher | E41: 4) To be accomplished when payment
A42: has been pre-audited and this same may be | E42: of labor payrolls was made without pre-
A43: paid in the amount of | E43: audit. Passed in post audit in the amount of
A44: =PROPER(CHOOSE(LEFT(TEXT(D21,"000000000.00"))+1,,"One","Two","Three","Four","Five","Six","Seven","Eight","Nine")&IF(--LEFT(TEXT(D21,"000000000.00"))=0,,IF(AND(--MID(TEXT(D21,"000000000.00"),2,1)=0,--MID(TEXT(D21,"000000000.00"),3,1)=0)," Hundred"," Hundred "))&CHOOSE(MID(TEXT(D21,"000000000.00"),2,1)+1,,,"Twenty ","Thirty ","Forty ","Fifty ","Sixty ","Seventy ","Eighty ","Ninety ")&IF(--MID(TEXT(D21,"000000000.00"),2,1)<>1,CHOOSE(MID(TEXT(D21,"000000000.00"),3,1)+1,,"One","Two","Three","Four","Five","Six","Seven","Eight","Nine"),CHOOSE(MID(TEXT(D21,"000000000.00"),3,1)+1,"Ten","Eleven","Twelve","Thirteen","Fourteen","Fifteen","Sixteen","Seventeen","Eighteen","Nineteen"))&IF((--LEFT(TEXT(D21,"000000000.00"))+MID(TEXT(D21,"000000000.00"),2,1)+MID(TEXT(D21,"000000000.00"),3,1))=0,,IF(AND((--MID(TEXT(D21,"000000000.00"),4,1)+MID(TEXT(D21,"000000000.00"),5,1)+MID(TEXT(D21,"000000000.00"),6,1)+MID(TEXT(D21,"000000000.00"),7,1))=0,(--MID(TEXT(D21,"000000000.00"),8,1)+RIGHT(TEXT(D21,"000000000.00")))>0)," Million"," Million "))&CHOOSE(MID(TEXT(D21,"000000000.00"),4,1)+1,,"One","Two","Three","Four","Five","Six","Seven","Eight","Nine")&IF(--MID(TEXT(D21,"000000000.00"),4,1)=0,,IF(AND(--MID(TEXT(D21,"000000000.00"),5,1)=0,--MID(TEXT(D21,"000000000.00"),6,1)=0)," Hundred"," Hundred "))&CHOOSE(MID(TEXT(D21,"000000000.00"),5,1)+1,,," Twenty"," Thirty"," Forty"," Fifty"," Sixty"," Seventy"," Eighty"," Ninety")&IF(--MID(TEXT(D21,"000000000.00"),5,1)<>1,CHOOSE(MID(TEXT(D21,"000000000.00"),6,1)+1,," One"," Two"," Three"," Four"," Five"," Six"," Seven"," Eight"," Nine"),CHOOSE(MID(TEXT(D21,"000000000.00"),6,1)+1," Ten"," Eleven"," Twelve"," Thirteen"," Fourteen"," Fifteen"," Sixteen"," Seventeen"," Eighteen"," Nineteen"))&IF((--MID(TEXT(D21,"000000000.00"),4,1)+MID(TEXT(D21,"000000000.00"),5,1)+MID(TEXT(D21,"000000000.00"),6,1))=0,,IF(OR((--MID(TEXT(D21,"000000000.00"),7,1)+MID(TEXT(D21,"000000000.00"),8,1)+MID(TEXT(D21,"000000000.00"),9,1))=0,--MID(TEXT(D21,"000000000.00"),7,1)<>0)," Thousand "," Thousand "))&CHOOSE(MID(TEXT(D21,"000000000.00"),7,1)+1,,"One","Two","Three","Four","Five","Six","Seven","Eight","Nine")&IF(--MID(TEXT(D21,"000000000.00"),7,1)=0,,IF(AND(--MID(TEXT(D21,"000000000.00"),8,1)=0,--MID(TEXT(D21,"000000000.00"),9,1)=0)," Hundred "," Hundred "))&CHOOSE(MID(TEXT(D21,"000000000.00"),8,1)+1,,,"Twenty ","Thirty ","Forty ","Fifty ","Sixty ","Seventy ","Eighty ","Ninety ")&IF(--MID(TEXT(D21,"000000000.00"),8,1)<>1,CHOOSE(MID(TEXT(D21,"000000000.00"),9,1)+1,,"One","Two","Three","Four","Five","Six","Seven","Eight","Nine"),CHOOSE(MID(TEXT(D21,"000000000.00"),9,1)+1,"Ten","Eleven","Twelve","Thirteen","Fourteen","Fifteen","Sixteen","Seventeen","Eighteen","Nineteen"))&" Pesos & "&RIGHT(TEXT(D21,"000000000.00"),2)&"/100 only") -> #REF! | E44: ________________________________.
E45: Entry was made in cash book for this
E46: amount.
A49: VIDA E. PITALLANO, CPA
A50: Sr. Accounting Processor A
E51: MARIA PIA O. AGUILAR
E52: State Auditor III/Audit Team Leader

Sheet DV - SSS-D&6
A2: NATIONAL IRRIGATION ADMINISTRATION | AC2: Fund :
A3: ALBAY-CATANDUANES IMO, LIGAO CITY
A4: DISBURSEMENT VOUCHER | AC4: Date :
AC5: DV No. :
A7: Mode of Payment
H8: MDS Check | N8: LCCA | U8: ADA | Y8: Others (Please specify)
AB9: _________________
A10: Payee | E10: SSS | T10: TIN/Employee No.: | AC10: ORS/BURS No.:
A12: Address
A14: Particulars | S14: Responsibility Center | X14: MFO/PAP | AC14: Amount
A17: REMITTANCE OF WITHHOLDING TAX FOR THE MONTH OF JULY 2024 IN THE AMOUNT OF.. | AC17: =K24 -> #REF!
K20: Amount
C21: 1 | D21: =#REF! -> #REF! | K21: =#REF! -> #REF!
C22: 2 | D22: =#REF! -> #REF! | K22: =#REF! -> #REF!
C23: 3 | D23: =#REF! -> #REF! | K23: =#REF! -> #REF!
C24: T O T A L | K24: =#REF! -> #REF!
A31: Amount Due | AC31: =AC17 -> #REF!
A32: A. | C32: Certified: Expenses/Cash Advance necessary, lawful and incurred under my direct supervision.
C35: ='BUR - Gross-D&6'!C33:H33 -> #REF!
C36: ='BUR - Gross-D&6'!C34:H34 -> #REF!
C37: Printed Name, Designation and Signature of Supervisor
A39: B. | C39: Accounting Entry:
A40: Account Title | T40: UACS Code | Y40: Debit | AD40: Credit
A52: C. | C52: Certified: | T52: D. | U52: Approved for Payment
D53: Cash available | T53: =UPPER(CHOOSE(LEFT(TEXT(AC31,"000000000.00"))+1,,"One","Two","Three","Four","Five","Six","Seven","Eight","Nine")&IF(--LEFT(TEXT(AC31,"000000000.00"))=0,,IF(AND(--MID(TEXT(AC31,"000000000.00"),2,1)=0,--MID(TEXT(AC31,"000000000.00"),3,1)=0)," Hundred"," Hundred "))&CHOOSE(MID(TEXT(AC31,"000000000.00"),2,1)+1,,,"Twenty ","Thirty ","Forty ","Fifty ","Sixty ","Seventy ","Eighty ","Ninety ")&IF(--MID(TEXT(AC31,"000000000.00"),2,1)<>1,CHOOSE(MID(TEXT(AC31,"000000000.00"),3,1)+1,,"One","Two","Three","Four","Five","Six","Seven","Eight","Nine"),CHOOSE(MID(TEXT(AC31,"000000000.00"),3,1)+1,"Ten","Eleven","Twelve","Thirteen","Fourteen","Fifteen","Sixteen","Seventeen","Eighteen","Nineteen"))&IF((--LEFT(TEXT(AC31,"000000000.00"))+MID(TEXT(AC31,"000000000.00"),2,1)+MID(TEXT(AC31,"000000000.00"),3,1))=0,,IF(AND((--MID(TEXT(AC31,"000000000.00"),4,1)+MID(TEXT(AC31,"000000000.00"),5,1)+MID(TEXT(AC31,"000000000.00"),6,1)+MID(TEXT(AC31,"000000000.00"),7,1))=0,(--MID(TEXT(AC31,"000000000.00"),8,1)+RIGHT(TEXT(AC31,"000000000.00")))>0)," Million"," Million "))&CHOOSE(MID(TEXT(AC31,"000000000.00"),4,1)+1,,"One","Two","Three","Four","Five","Six","Seven","Eight","Nine")&IF(--MID(TEXT(AC31,"000000000.00"),4,1)=0,,IF(AND(--MID(TEXT(AC31,"000000000.00"),5,1)=0,--MID(TEXT(AC31,"000000000.00"),6,1)=0)," Hundred"," Hundred "))&CHOOSE(MID(TEXT(AC31,"000000000.00"),5,1)+1,,," Twenty"," Thirty"," Forty"," Fifty"," Sixty"," Seventy"," Eighty"," Ninety")&IF(--MID(TEXT(AC31,"000000000.00"),5,1)<>1,CHOOSE(MID(TEXT(AC31,"000000000.00"),6,1)+1,," One"," Two"," Three"," Four"," Five"," Six"," Seven"," Eight"," Nine"),CHOOSE(MID(TEXT(AC31,"000000000.00"),6,1)+1," Ten"," Eleven"," Twelve"," Thirteen"," Fourteen"," Fifteen"," Sixteen"," Seventeen"," Eighteen"," Nineteen"))&IF((--MID(TEXT(AC31,"000000000.00"),4,1)+MID(TEXT(AC31,"000000000.00"),5,1)+MID(TEXT(AC31,"000000000.00"),6,1))=0,,IF(OR((--MID(TEXT(AC31,"000000000.00"),7,1)+MID(TEXT(AC31,"000000000.00"),8,1)+MID(TEXT(AC31,"000000000.00"),9,1))=0,--MID(TEXT(AC31,"000000000.00"),7,1)<>0)," Thousand "," Thousand "))&CHOOSE(MID(TEXT(AC31,"000000000.00"),7,1)+1,,"One","Two","Three","Four","Five","Six","Seven","Eight","Nine")&IF(--MID(TEXT(AC31,"000000000.00"),7,1)=0,,IF(AND(--MID(TEXT(AC31,"000000000.00"),8,1)=0,--MID(TEXT(AC31,"000000000.00"),9,1)=0)," Hundred "," Hundred "))&CHOOSE(MID(TEXT(AC31,"000000000.00"),8,1)+1,,,"Twenty ","Thirty ","Forty ","Fifty ","Sixty ","Seventy ","Eighty ","Ninety ")&IF(--MID(TEXT(AC31,"000000000.00"),8,1)<>1,CHOOSE(MID(TEXT(AC31,"000000000.00"),9,1)+1,,"One","Two","Three","Four","Five","Six","Seven","Eight","Nine"),CHOOSE(MID(TEXT(AC31,"000000000.00"),9,1)+1,"Ten","Eleven","Twelve","Thirteen","Fourteen","Fifteen","Sixteen","Seventeen","Eighteen","Nineteen"))&" Pesos & "&RIGHT(TEXT(AC31,"000000000.00"),2)&"/100 only") -> #REF!
D55: Subject to Authority to Debit Account (when applicable)
D57: Supporting documents complete and amount claimed
D58: proper
A60: Signature | T60: Signature
A62: Printed Name | E62: ='BUR - Gross-D&6'!K33:K33 -> VIDA E. PITALLANO, CPA | T62: Printed Name | X62: ='SUMMARY (1-15)-D&6'!A37 -> Engr. MARK CLOYD G. SO
A64: Position | E64: ='BUR - Gross-D&6'!K34:K34 -> Sr. Accounting Processor A | T64: Position | X64: ='SUMMARY (1-15)-D&6'!A38 -> Acting Manager, Albay-Cat IMO
E65: Head, Accounting Unit/Authorized Representative | X65: Agency Head/Authorized Representative
A66: Date | T66: Date
A68: E. | C68: Receipt of Payment | AC68: JEV No.
A69: Check/ ADA No. : | L69: Date : | T69: Bank Name & Account Number:
A71: Signature : | L71: Date : | T71: Printed Name: | AC71: Date
T72: =E10 -> SSS
A73: Official Receipt No. & Date/Other Documents

Sheet TIMEBOOK (1-15)-E
B2: REPUBLIC OF THE PHILIPPINES
B3: National Irrigation Administration
B4: ALBAY-CATANDUANES IRRIGATION MANAGEMENT OFFICE
B5: Virac, Catanduanes
A7: T I M E B O O K
AB8: AFD - JOB ORDER
B10: For Labor on | C10: LFP | AB10: SEPTEMBER 16-30, 2024
C11: (State Project which was performed)
AE12: NO. OF MINUTES
B13: N A M E | C13: DESIGNATION | D13: T I M E R O L L | T13: No. of days worked | U13: Rate per Day | V13: GROSS AMOUNT | W13: OVERTIME | X13: TOTAL | Y13: BIR | Z13: HDMF | AA13: TOTAL DEDUCTIONS | AB13: NET | AC13: LBP | AE13: OVERTIME
X14: EARNINGS FOR | Y14: SSS | Z14: HDMF-MPL | AB14: AMOUNT | AC14: ATM NUMBER
D15: 16 | E15: 17 | F15: 18 | G15: 19 | H15: 20 | I15: 21 | J15: 22 | K15: 23 | L15: 24 | M15: 25 | N15: 26 | O15: 27 | P15: 28 | Q15: 29 | R15: 30 | S15: 31 | W15: UNDERTIME | X15: THE PERIOD | Y15: NIAMPCO-ML | AB15: DUE | AE15: UNDERTIME
A16: 1 | B16: BEO, EDILBERTO R. | C16: Clerk Processor B | D16: X | E16: X | F16: X | G16: X | H16: X | I16: S | J16: S | K16: X | L16: X | M16: X | N16: X | O16: X | P16: S | Q16: S | R16: X | T16: =COUNTIF(D16:S16,"X")+(COUNTIF(D16:S16,"/")/2)+COUNTIF(D16:S16,"OB")+COUNTIF(D16:S16,"SPH") -> 11 | U16: 704.77 | V16: =U16*T16 -> 7752.47 | W16: =ROUND((ROUND((U16/8/60),2)*AE16),2) -> 0 | X16: =V16+W16-W18 -> 7551.3169 | Y16: =ROUND((X16*0.03),2) -> 226.54 | Z16: 0 | AA16: =Y16+Y17+Y18+Z16+Z17+Z18 -> 226.54 | AB16: =X16-AA16 -> 7324.7769 | AC16: 0897091518 | AE16: 0
W18: =U16/8/60*AE18 -> 201.1531 | Y18: 0 | Z18: 0 | AE18: 137
B20: Item 1-Utilized in various institutional works in Catanduanes | W20: =ROUND((W16),2) -> 0 | Y20: =Y16 -> 226.54 | Z20: =ROUND((Z16),2) -> 0
W21: =ROUND((W17),2) -> 0 | Y21: =ROUND((Y17),2) -> 0
W22: =W18 -> 201.1531 | Y22: =ROUND((Y18),2) -> 0 | Z22: =ROUND((Z18),2) -> 0
A24: T O T A L S | V24: =ROUND(SUM(V16:V18),2) -> 7752.47 | W24: =ROUND(SUM(W20:W22),2) -> 201.15 | X24: =ROUND(SUM(X16:X18),2) -> 7551.32 | Y24: =ROUND(SUM(Y20:Y22),2) -> 226.54 | Z24: =ROUND(SUM(Z20:Z22),2) -> 0 | AA24: =ROUND((Y24+Z24),2) -> 226.54 | AB24: =ROUND(SUM(AB16:AB18),2) -> 7324.78
B27: 1) I HEREBY CERTIFY that each person whose name appears on this roll rendered services as indicated and for the time stated. | J27: 2) I CERTIFY that this roll is correct, every person whose name appears hereon rendered services for the time and at the rates stated under my general supervision, and I approved payment of this roll. | X27: 3) I CERTIFY on my official that I have this ____ day of _____________, 20____ paid in cash to each person whose name appears having presented him self established his/her identity and affix his/her signature or thumbmark on the space provided.
B31: MARK ANJO T. ALNAS | J31: ANGELO V. MARQUEZ | X31: VILMA M. MANLANGIT
B32: Engineering A | J32: Acting Head, NIA Catanduanes Sub-Office | X32: SCDO

Sheet SUMMARY (1-15)-E
A1: S U M M A R Y O F P A Y R O L L
C3: E.R. BEO
A4: Bureau/Province/Municipal | C4: NIA, ALBAY-CATANDUANES IMO,
A5: For the Period | C5: =#REF! -> #REF!
A6: P R O J E C T
A8: S h e e t | B8: N u m b e r | C8: A m o u n t | D8: Amount Paid | E8: T r a n s f e r r e d T o
A9: N o . | B9: o f R o l l s | C9: o f R o l l s | D9: o f R o l l s
A10: 1 | C10: ='TIMEBOOK (1-15)-E'!X24 -> 7551.32 | D10: ='TIMEBOOK (1-15)-E'!AB24 -> 7324.78 | E10: =#REF! -> #REF! | F10: ='TIMEBOOK (1-15)-E'!Y16 -> 226.54
E11: =#REF! -> #REF! | F11: ='TIMEBOOK (1-15)-E'!Z16 -> 0
E12: =#REF! -> #REF! | F12: ='TIMEBOOK (1-15)-E'!Y17 -> 0
E13: =#REF! -> #REF! | F13: ='TIMEBOOK (1-15)-E'!Z18 -> 0
E14: =#REF! -> #REF! | F14: ='TIMEBOOK (1-15)-E'!Y18 -> 0
E15: =#REF! -> #REF! | F15: =#REF! -> #REF!
C21: =C10 -> 7551.32 | D21: =SUM(D10:D20) -> 7324.78 | F21: =SUM(F10:F20) -> #REF!
A23: 1) I HEREBY CERTIFY that the attached | E23: 3) I HEREBY CERTIFY on my official
A24: payroll/s and summary of which appears here- | E24: oath that the payroll/s and summary of
A25: on is/are correct and just and that the ser- | E25: which appears hereon, are the best of my
A26: vices were rendered under my direction and | E26: knowledge and belief proper and correct
A27: I approved payment thereof this ___ day of | E27: the same being chargeable to the appro-
A28: ______________________________________. | E28: priation set aside. THEREOF, I FURTHER
E29: CERTIFY that the payment thereon have
E30: been made in the amount of | F30: =D21 -> 7324.78
E31: =PROPER(CHOOSE(LEFT(TEXT(D21,"000000000.00"))+1,,"One","Two","Three","Four","Five","Six","Seven","Eight","Nine")&IF(--LEFT(TEXT(D21,"000000000.00"))=0,,IF(AND(--MID(TEXT(D21,"000000000.00"),2,1)=0,--MID(TEXT(D21,"000000000.00"),3,1)=0)," Hundred"," Hundred "))&CHOOSE(MID(TEXT(D21,"000000000.00"),2,1)+1,,,"Twenty ","Thirty ","Forty ","Fifty ","Sixty ","Seventy ","Eighty ","Ninety ")&IF(--MID(TEXT(D21,"000000000.00"),2,1)<>1,CHOOSE(MID(TEXT(D21,"000000000.00"),3,1)+1,,"One","Two","Three","Four","Five","Six","Seven","Eight","Nine"),CHOOSE(MID(TEXT(D21,"000000000.00"),3,1)+1,"Ten","Eleven","Twelve","Thirteen","Fourteen","Fifteen","Sixteen","Seventeen","Eighteen","Nineteen"))&IF((--LEFT(TEXT(D21,"000000000.00"))+MID(TEXT(D21,"000000000.00"),2,1)+MID(TEXT(D21,"000000000.00"),3,1))=0,,IF(AND((--MID(TEXT(D21,"000000000.00"),4,1)+MID(TEXT(D21,"000000000.00"),5,1)+MID(TEXT(D21,"000000000.00"),6,1)+MID(TEXT(D21,"000000000.00"),7,1))=0,(--MID(TEXT(D21,"000000000.00"),8,1)+RIGHT(TEXT(D21,"000000000.00")))>0)," Million"," Million "))&CHOOSE(MID(TEXT(D21,"000000000.00"),4,1)+1,,"One","Two","Three","Four","Five","Six","Seven","Eight","Nine")&IF(--MID(TEXT(D21,"000000000.00"),4,1)=0,,IF(AND(--MID(TEXT(D21,"000000000.00"),5,1)=0,--MID(TEXT(D21,"000000000.00"),6,1)=0)," Hundred"," Hundred "))&CHOOSE(MID(TEXT(D21,"000000000.00"),5,1)+1,,," Twenty"," Thirty"," Forty"," Fifty"," Sixty"," Seventy"," Eighty"," Ninety")&IF(--MID(TEXT(D21,"000000000.00"),5,1)<>1,CHOOSE(MID(TEXT(D21,"000000000.00"),6,1)+1,," One"," Two"," Three"," Four"," Five"," Six"," Seven"," Eight"," Nine"),CHOOSE(MID(TEXT(D21,"000000000.00"),6,1)+1," Ten"," Eleven"," Twelve"," Thirteen"," Fourteen"," Fifteen"," Sixteen"," Seventeen"," Eighteen"," Nineteen"))&IF((--MID(TEXT(D21,"000000000.00"),4,1)+MID(TEXT(D21,"000000000.00"),5,1)+MID(TEXT(D21,"000000000.00"),6,1))=0,,IF(OR((--MID(TEXT(D21,"000000000.00"),7,1)+MID(TEXT(D21,"000000000.00"),8,1)+MID(TEXT(D21,"000000000.00"),9,1))=0,--MID(TEXT(D21,"000000000.00"),7,1)<>0)," Thousand "," Thousand "))&CHOOSE(MID(TEXT(D21,"000000000.00"),7,1)+1,,"One","Two","Three","Four","Five","Six","Seven","Eight","Nine")&IF(--MID(TEXT(D21,"000000000.00"),7,1)=0,,IF(AND(--MID(TEXT(D21,"000000000.00"),8,1)=0,--MID(TEXT(D21,"000000000.00"),9,1)=0)," Hundred "," Hundred "))&CHOOSE(MID(TEXT(D21,"000000000.00"),8,1)+1,,,"Twenty ","Thirty ","Forty ","Fifty ","Sixty ","Seventy ","Eighty ","Ninety ")&IF(--MID(TEXT(D21,"000000000.00"),8,1)<>1,CHOOSE(MID(TEXT(D21,"000000000.00"),9,1)+1,,"One","Two","Three","Four","Five","Six","Seven","Eight","Nine"),CHOOSE(MID(TEXT(D21,"000000000.00"),9,1)+1,"Ten","Eleven","Twelve","Thirteen","Fourteen","Fifteen","Sixteen","Seventeen","Eighteen","Nineteen"))&" Pesos & "&RIGHT(TEXT(D21,"000000000.00"),2)&"/100 only") -> Seven Thousand Three Hundred Twenty Four Pesos & 78/100 Only
A33: APPROVED:
A37: Engr. MARK CLOYD G. SO | E37: =#REF! -> #REF!
A38: Acting Manager, Albay-Cat IMO | E38: =#REF! -> #REF!
A41: 2) I HEREBY CERTIFY that this Voucher | E41: 4) To be accomplished when payment
A42: has been pre-audited and this same may be | E42: of labor payrolls was made without pre-
A43: paid in the amount of | E43: audit. Passed in post audit in the amount of
